<?xml version='1.0'?>
<sdf version='1.7'>
  <model name='cessna_3'>
    <link name='cessna_3/base_link'>
      <inertial>
        <pose>-0.004 0 0.09271 0 -0 0</pose>
        <mass>4</mass>
        <inertia>
          <ixx>0.128531</ixx>
          <ixy>0</ixy>
          <ixz>0</ixz>
          <iyy>0.182593</iyy>
          <iyz>0</iyz>
          <izz>0.266689</izz>
        </inertia>
      </inertial>
      <self_collide>0</self_collide>
      <enable_wind>0</enable_wind>
      <kinematic>0</kinematic>
      <pose>0 0 0 0 -0 0</pose>
      <visual name='cessna_3/base_link_visual'>
        <pose>0 0 0 0 -0 0</pose>
        <geometry>
          <mesh>
            <scale>0.1 0.1 0.1</scale>
            <uri>model://cessna/meshes/body.dae</uri>
          </mesh>
        </geometry>
        <material>
          <script>
            <name>Gazebo</name>
            <uri>file://media/materials/scripts/gazebo.material</uri>
          </script>
          <shader type='pixel'/>
        </material>
        <transparency>0</transparency>
        <cast_shadows>0</cast_shadows>
      </visual>
      <collision name='cessna_3/base_link_collision'>
        <laser_retro>0</laser_retro>
        <max_contacts>10</max_contacts>
        <pose>0 0 0 0 -0 0</pose>
        <geometry>
          <box>
            <size>1 0.5 0.05</size>
          </box>
        </geometry>
        <surface>
          <friction>
            <ode>
              <mu>0.1</mu>
              <mu2>0.1</mu2>
              <fdir1>0 0 0</fdir1>
              <slip1>0</slip1>
              <slip2>0</slip2>
            </ode>
            <torsional>
              <coefficient>1</coefficient>
              <patch_radius>0</patch_radius>
              <surface_radius>0</surface_radius>
              <use_patch_radius>1</use_patch_radius>
              <ode>
                <slip>0</slip>
              </ode>
            </torsional>
          </friction>
          <bounce>
            <restitution_coefficient>0</restitution_coefficient>
            <threshold>1e+06</threshold>
          </bounce>
          <contact>
            <collide_without_contact>0</collide_without_contact>
            <collide_without_contact_bitmask>1</collide_without_contact_bitmask>
            <collide_bitmask>1</collide_bitmask>
            <ode>
              <soft_cfm>0</soft_cfm>
              <soft_erp>0.2</soft_erp>
              <kp>1e+13</kp>
              <kd>1</kd>
              <max_vel>100</max_vel>
              <min_depth>0.001</min_depth>
            </ode>
            <bullet>
              <split_impulse>1</split_impulse>
              <split_impulse_penetration_threshold>-0.01</split_impulse_penetration_threshold>
              <soft_cfm>0</soft_cfm>
              <soft_erp>0.2</soft_erp>
              <kp>1e+13</kp>
              <kd>1</kd>
            </bullet>
          </contact>
        </surface>
      </collision>
    </link>
    <link name='cessna_3/elevators'>
      <pose>-0.555 -0 0.057 0 -0 0</pose>
      <inertial>
        <pose>0 0 0 0 -0 0</pose>
        <mass>0.0001</mass>
        <inertia>
          <ixx>0.0038166</ixx>
          <ixy>0</ixy>
          <ixz>0</ixz>
          <iyy>0.0036</iyy>
          <iyz>0</iyz>
          <izz>0.003816</izz>
        </inertia>
      </inertial>
      <self_collide>0</self_collide>
      <enable_wind>0</enable_wind>
      <kinematic>0</kinematic>
      <visual name='cessna_3/elevators_visual'>
        <pose>0.555 0 -0.057 0 -0 0</pose>
        <geometry>
          <mesh>
            <scale>0.1 0.1 0.1</scale>
            <uri>model://cessna/meshes/elevators.dae</uri>
          </mesh>
        </geometry>
        <material>
          <shader type='pixel'/>
        </material>
        <transparency>0</transparency>
        <cast_shadows>0</cast_shadows>
      </visual>
    </link>
    <link name='cessna_3/imu_link'>
      <pose>0 0 0 0 -0 0</pose>
      <inertial>
        <pose>0 0 0 0 -0 0</pose>
        <mass>0.15</mass>
        <inertia>
          <ixx>1e-05</ixx>
          <ixy>0</ixy>
          <ixz>0</ixz>
          <iyy>2e-05</iyy>
          <iyz>0</iyz>
          <izz>3e-05</izz>
        </inertia>
      </inertial>
      <sensor name='imu_sensor' type='imu'>
        <pose>0 0 0 -3.14159 -0 0</pose>
        <always_on>1</always_on>
        <update_rate>1000</update_rate>
        <imu/>
      </sensor>
      <self_collide>0</self_collide>
      <enable_wind>0</enable_wind>
      <kinematic>0</kinematic>
    </link>
    <link name='cessna_3/left_aileron'>
      <pose>-0.145 0.37 0.15 0.05 -0 -0.12</pose>
      <inertial>
        <pose>0 0 0 0 -0 0</pose>
        <mass>0.0001</mass>
        <inertia>
          <ixx>0.0038166</ixx>
          <ixy>0</ixy>
          <ixz>0</ixz>
          <iyy>0.0036</iyy>
          <iyz>0</iyz>
          <izz>0.003816</izz>
        </inertia>
      </inertial>
      <self_collide>0</self_collide>
      <enable_wind>0</enable_wind>
      <kinematic>0</kinematic>
      <visual name='cessna_3/left_aileron_visual'>
        <pose>0.195 -0.36 -0.12 -0.05 -0 0.12</pose>
        <geometry>
          <mesh>
            <scale>0.1 0.1 0.1</scale>
            <uri>model://cessna/meshes/left_aileron.dae</uri>
          </mesh>
        </geometry>
        <material>
          <shader type='pixel'/>
        </material>
        <transparency>0</transparency>
        <cast_shadows>0</cast_shadows>
      </visual>
    </link>
    <link name='cessna_3/propeller'>
      <pose>0.179 0 0.0855 0 -0 0</pose>
      <inertial>
        <pose>0 0 0 0 -0 0</pose>
        <mass>0.025</mass>
        <inertia>
          <ixx>7.5067e-05</ixx>
          <ixy>0</ixy>
          <ixz>0</ixz>
          <iyy>7.515e-05</iyy>
          <iyz>0</iyz>
          <izz>6.8275e-07</izz>
        </inertia>
      </inertial>
      <self_collide>0</self_collide>
      <enable_wind>0</enable_wind>
      <kinematic>0</kinematic>
      <visual name='cessna_3/propeller_visual'>
        <pose>0 0 0 0 -0 0</pose>
        <geometry>
          <mesh>
            <scale>0.1 0.1 0.1</scale>
            <uri>model://cessna/meshes/cessna_prop.dae</uri>
          </mesh>
        </geometry>
        <material>
          <script>
            <name>Gazebo/Blue</name>
            <uri>file://media/materials/scripts/gazebo.material</uri>
          </script>
          <shader type='pixel'/>
        </material>
        <transparency>0</transparency>
        <cast_shadows>0</cast_shadows>
      </visual>
    </link>
    <link name='cessna_3/right_aileron'>
      <pose>-0.145 -0.37 0.15 -0.05 -0 0.12</pose>
      <inertial>
        <pose>0 0 0 0 -0 0</pose>
        <mass>0.0001</mass>
        <inertia>
          <ixx>0.0038166</ixx>
          <ixy>0</ixy>
          <ixz>0</ixz>
          <iyy>0.0036</iyy>
          <iyz>0</iyz>
          <izz>0.003816</izz>
        </inertia>
      </inertial>
      <self_collide>0</self_collide>
      <enable_wind>0</enable_wind>
      <kinematic>0</kinematic>
      <visual name='cessna_3/right_aileron_visual'>
        <pose>0.195 0.36 -0.12 0.05 -0 -0.12</pose>
        <geometry>
          <mesh>
            <scale>0.1 0.1 0.1</scale>
            <uri>model://cessna/meshes/right_aileron.dae</uri>
          </mesh>
        </geometry>
        <material>
          <shader type='pixel'/>
        </material>
        <transparency>0</transparency>
        <cast_shadows>0</cast_shadows>
      </visual>
    </link>
    <link name='cessna_3/rudder'>
      <pose>-0.51 -0 0.325 0 -0.35 0</pose>
      <inertial>
        <pose>0 0 0 0 -0 0</pose>
        <mass>0.0001</mass>
        <inertia>
          <ixx>0.0038166</ixx>
          <ixy>0</ixy>
          <ixz>0</ixz>
          <iyy>0.0036</iyy>
          <iyz>0</iyz>
          <izz>0.003816</izz>
        </inertia>
      </inertial>
      <self_collide>0</self_collide>
      <enable_wind>0</enable_wind>
      <kinematic>0</kinematic>
      <visual name='cessna_3/rudder_visual'>
        <pose>0.36 0 -0.475 0 0.35 0</pose>
        <geometry>
          <mesh>
            <scale>0.1 0.1 0.1</scale>
            <uri>model://cessna/meshes/rudder.dae</uri>
          </mesh>
        </geometry>
        <material>
          <shader type='pixel'/>
        </material>
        <transparency>0</transparency>
        <cast_shadows>0</cast_shadows>
      </visual>
    </link>
    <joint name='cessna_3/elevators_joint' type='revolute'>
      <parent>cessna_3/base_link</parent>
      <child>cessna_3/elevators</child>
      <pose>0 0 0 0 -0 0</pose>
      <axis>
        <xyz>0 1 0</xyz>
        <limit>
          <lower>-0.78</lower>
          <upper>0.78</upper>
          <effort>-1</effort>
          <velocity>-1</velocity>
        </limit>
        <dynamics>
          <spring_reference>0</spring_reference>
          <spring_stiffness>0</spring_stiffness>
          <damping>0</damping>
          <friction>0</friction>
        </dynamics>
      </axis>
      <physics>
        <ode>
          <limit>
            <cfm>0</cfm>
            <erp>0.2</erp>
          </limit>
          <suspension>
            <cfm>0</cfm>
            <erp>0.2</erp>
          </suspension>
        </ode>
      </physics>
    </joint>
    <joint name='cessna_3/imu_joint' type='revolute'>
      <parent>cessna_3/base_link</parent>
      <child>cessna_3/imu_link</child>
      <pose>0 0 0 0 -0 0</pose>
      <axis>
        <xyz>1 0 0</xyz>
        <limit>
          <lower>0</lower>
          <upper>0</upper>
          <effort>0</effort>
          <velocity>0</velocity>
        </limit>
        <dynamics>
          <spring_reference>0</spring_reference>
          <spring_stiffness>0</spring_stiffness>
          <damping>1</damping>
          <friction>0</friction>
        </dynamics>
      </axis>
      <physics>
        <ode>
          <limit>
            <cfm>0</cfm>
            <erp>0.2</erp>
          </limit>
          <suspension>
            <cfm>0</cfm>
            <erp>0.2</erp>
          </suspension>
        </ode>
      </physics>
    </joint>
    <joint name='cessna_3/left_aileron_joint' type='revolute'>
      <parent>cessna_3/base_link</parent>
      <child>cessna_3/left_aileron</child>
      <pose>0 0 -0 0 -0 0</pose>
      <axis>
        <xyz>0 1 0</xyz>
        <limit>
          <lower>-0.78</lower>
          <upper>0.78</upper>
          <effort>-1</effort>
          <velocity>-1</velocity>
        </limit>
        <dynamics>
          <spring_reference>0</spring_reference>
          <spring_stiffness>0</spring_stiffness>
          <damping>0</damping>
          <friction>0</friction>
        </dynamics>
      </axis>
      <physics>
        <ode>
          <limit>
            <cfm>0</cfm>
            <erp>0.2</erp>
          </limit>
          <suspension>
            <cfm>0</cfm>
            <erp>0.2</erp>
          </suspension>
        </ode>
      </physics>
    </joint>
    <joint name='cessna_3/propeller_joint' type='revolute'>
      <parent>cessna_3/base_link</parent>
      <child>cessna_3/propeller</child>
      <pose>0 0 0 0 -0 0</pose>
      <axis>
        <xyz>1 0 0</xyz>
        <limit>
          <lower>-1e+16</lower>
          <upper>1e+16</upper>
          <effort>-1</effort>
          <velocity>-1</velocity>
        </limit>
        <dynamics>
          <spring_reference>0</spring_reference>
          <spring_stiffness>0</spring_stiffness>
          <damping>0.001</damping>
          <friction>0</friction>
        </dynamics>
      </axis>
      <physics>
        <ode>
          <limit>
            <cfm>0</cfm>
            <erp>0.2</erp>
          </limit>
          <suspension>
            <cfm>0</cfm>
            <erp>0.2</erp>
          </suspension>
        </ode>
      </physics>
    </joint>
    <joint name='cessna_3/right_aileron_joint' type='revolute'>
      <parent>cessna_3/base_link</parent>
      <child>cessna_3/right_aileron</child>
      <pose>0 -0 -0 0 -0 0</pose>
      <axis>
        <xyz>0 1 0</xyz>
        <limit>
          <lower>-0.78</lower>
          <upper>0.78</upper>
          <effort>-1</effort>
          <velocity>-1</velocity>
        </limit>
        <dynamics>
          <spring_reference>0</spring_reference>
          <spring_stiffness>0</spring_stiffness>
          <damping>0</damping>
          <friction>0</friction>
        </dynamics>
      </axis>
      <physics>
        <ode>
          <limit>
            <cfm>0</cfm>
            <erp>0.2</erp>
          </limit>
          <suspension>
            <cfm>0</cfm>
            <erp>0.2</erp>
          </suspension>
        </ode>
      </physics>
    </joint>
    <joint name='cessna_3/rudder_joint' type='revolute'>
      <parent>cessna_3/base_link</parent>
      <child>cessna_3/rudder</child>
      <pose>-0 0 0 0 -0 0</pose>
      <axis>
        <xyz>0 0 1</xyz>
        <limit>
          <lower>-0.78</lower>
          <upper>0.78</upper>
          <effort>-1</effort>
          <velocity>-1</velocity>
        </limit>
        <dynamics>
          <spring_reference>0</spring_reference>
          <spring_stiffness>0</spring_stiffness>
          <damping>0</damping>
          <friction>0</friction>
        </dynamics>
      </axis>
      <physics>
        <ode>
          <limit>
            <cfm>0</cfm>
            <erp>0.2</erp>
          </limit>
          <suspension>
            <cfm>0</cfm>
            <erp>0.2</erp>
          </suspension>
        </ode>
      </physics>
    </joint>
    <static>0</static>
    <allow_auto_disable>1</allow_auto_disable>
    <plugin name='cessna_3_arduplane_plugin' filename='libArduPilotPlugin.so'>
      <fdm_addr>127.0.0.1</fdm_addr>
      <fdm_port_in>9042</fdm_port_in>
      <fdm_port_out>9043</fdm_port_out>
      <modelXYZToAirplaneXForwardZDown>0 0 0 0 0 0</modelXYZToAirplaneXForwardZDown>
      <gazeboXYZToNED>0 0 0 3.141593 0 0</gazeboXYZToNED>
      <imuName>cessna_3/imu_link::imu_sensor</imuName>
      <connectionTimeoutMaxCount>5</connectionTimeoutMaxCount>
      <control channel='2'>
        <type>VELOCITY</type>
        <offset>0</offset>
        <p_gain>.1</p_gain>
        <i_gain>0</i_gain>
        <d_gain>0</d_gain>
        <i_max>0</i_max>
        <i_min>0</i_min>
        <cmd_max>2.5</cmd_max>
        <cmd_min>0</cmd_min>
        <jointName>cessna_3/propeller_joint</jointName>
        <multiplier>838</multiplier>
        <rotorVelocitySlowdownSim>1</rotorVelocitySlowdownSim>
      </control>
      <control channel='0'>
        <type>POSITION</type>
        <offset>-0.5</offset>
        <p_gain>2.00</p_gain>
        <i_gain>0</i_gain>
        <d_gain>1.50</d_gain>
        <i_max>0</i_max>
        <i_min>0</i_min>
        <cmd_max>1.0</cmd_max>
        <cmd_min>-1.0</cmd_min>
        <multiplier>-1</multiplier>
        <jointName>cessna_3/left_aileron_joint</jointName>
        <controlVelocitySlowdownSim>1</controlVelocitySlowdownSim>
      </control>
      <control channel='0'>
        <type>POSITION</type>
        <offset>-0.5</offset>
        <p_gain>2.00</p_gain>
        <i_gain>0</i_gain>
        <d_gain>1.50</d_gain>
        <i_max>0</i_max>
        <i_min>0</i_min>
        <cmd_max>1.0</cmd_max>
        <cmd_min>-1.0</cmd_min>
        <multiplier>1</multiplier>
        <jointName>cessna_3/right_aileron_joint</jointName>
        <controlVelocitySlowdownSim>1</controlVelocitySlowdownSim>
      </control>
      <control channel='1'>
        <type>POSITION</type>
        <offset>-0.5</offset>
        <p_gain>2.00</p_gain>
        <i_gain>0</i_gain>
        <d_gain>1.50</d_gain>
        <i_max>0</i_max>
        <i_min>0</i_min>
        <cmd_max>1.0</cmd_max>
        <cmd_min>-1.0</cmd_min>
        <multiplier>1</multiplier>
        <jointName>cessna_3/elevators_joint</jointName>
        <controlVelocitySlowdownSim>1</controlVelocitySlowdownSim>
      </control>
      <control channel='3'>
        <type>POSITION</type>
        <offset>-0.5</offset>
        <p_gain>2.00</p_gain>
        <i_gain>0</i_gain>
        <d_gain>1.50</d_gain>
        <i_max>0</i_max>
        <i_min>0</i_min>
        <cmd_max>1.0</cmd_max>
        <cmd_min>-1.0</cmd_min>
        <multiplier>1</multiplier>
        <jointName>cessna_3/rudder_joint</jointName>
        <controlVelocitySlowdownSim>1</controlVelocitySlowdownSim>
      </control>
      <robotNamespace>/cessna0</robotNamespace>
    </plugin>
    <plugin name='elevators_plugin' filename='libLiftDragPlugin.so'>
      <a0>-0.2</a0>
      <cla>4.752798721</cla>
      <cda>0.6417112299</cda>
      <cma>0.0</cma>
      <alpha_stall>0.3391428111</alpha_stall>
      <cla_stall>-3.85</cla_stall>
      <cda_stall>-0.9233984055</cda_stall>
      <cma_stall>0</cma_stall>
      <cp>-0.5 0 0</cp>
      <area>0.01</area>
      <air_density>1.2041</air_density>
      <forward>1 0 0</forward>
      <upward>0 0 1</upward>
      <control_joint_rad_to_cl>-4.0</control_joint_rad_to_cl>      
      <forward>1 0 0</forward>
      <link_name>cessna_3/base_link</link_name>
      <control_joint_name>cessna_3/elevators_joint</control_joint_name>
      <robotNamespace>/cessna0</robotNamespace>
    </plugin>
    <plugin name='left_aileron_plugin' filename='libLiftDragPlugin.so'>
      <a0>0.05984281113</a0>
      <cla>4.752798721</cla>
      <cda>0.6417112299</cda>
      <cma>-1.8</cma>
      <alpha_stall>0.3391428111</alpha_stall>
      <cla_stall>-3.85</cla_stall>
      <cda_stall>-0.9233984055</cda_stall>
      <cma_stall>0</cma_stall>
      <cp>-0.1 0.2205 0.15</cp>
      <area>8.08255</area>
      <upward>0 0 1</upward>
      <control_joint_rad_to_cl>-2.0</control_joint_rad_to_cl>
      <forward>1 0 0</forward>
      <link_name>cessna_3/base_link</link_name>
      <control_joint_name>cessna_3/left_aileron_joint</control_joint_name>
      <robotNamespace>/cessna0</robotNamespace>
    </plugin>
    <plugin name='propeller_bottom_blade' filename='libLiftDragPlugin.so'>
      <a0>0.4</a0>
      <cla>4.752798721</cla>
      <cda>0.6417112299</cda>
      <cma>0</cma>
      <alpha_stall>1.5</alpha_stall>
      <cla_stall>-3.85</cla_stall>
      <cda_stall>-0.9233984055</cda_stall>
      <cma_stall>0</cma_stall>
      <cp>-0.37 0 -0.77</cp>
      <area>.0001</area>
      <air_density>1.2041</air_density>
      <forward>0 1 0</forward>
      <upward>1 0 0</upward>
      <link_name>cessna_3/propeller</link_name>
      <robotNamespace>/cessna0</robotNamespace>
    </plugin>
    <plugin name='propeller_top_blade' filename='libLiftDragPlugin.so'>
      <a0>0.4</a0>
      <cla>4.752798721</cla>
      <cda>0.6417112299</cda>
      <cma>0</cma>
      <alpha_stall>1.5</alpha_stall>
      <cla_stall>-3.85</cla_stall>
      <cda_stall>-0.9233984055</cda_stall>
      <cma_stall>0</cma_stall>
      <cp>-0.37 0 0.77</cp>
      <area>.0001</area>
      <air_density>1.2041</air_density>
      <forward>0 -1 0</forward>
      <upward>1 0 0</upward>
      <link_name>cessna_3/propeller</link_name>
      <robotNamespace>/cessna0</robotNamespace>
    </plugin>
    <plugin name='right_aileron_plugin' filename='libLiftDragPlugin.so'>
      <a0>0.05984281113</a0>
      <cla>4.752798721</cla>
      <cda>0.6417112299</cda>
      <cma>-1.8</cma>
      <alpha_stall>0.3391428111</alpha_stall>
      <cla_stall>-3.85</cla_stall>
      <cda_stall>-0.9233984055</cda_stall>
      <cma_stall>0</cma_stall>
      <cp>-0.1 -0.2205 0.15</cp>
      <area>8.08255</area>
      <upward>0 0 1</upward>
      <control_joint_rad_to_cl>-2.0</control_joint_rad_to_cl>
      <forward>1 0 0</forward>
      <link_name>cessna_3/base_link</link_name>
      <control_joint_name>cessna_3/right_aileron_joint</control_joint_name>
      <robotNamespace>/cessna0</robotNamespace>
    </plugin>
    <plugin name='rudder_plugin' filename='libLiftDragPlugin.so'>
      <a0>0.0</a0>
      <cla>4.752798721</cla>
      <cda>0.6417112299</cda>
      <cma>-1.8</cma>
      <alpha_stall>0.3391428111</alpha_stall>
      <cla_stall>-3.85</cla_stall>
      <cda_stall>-0.9233984055</cda_stall>
      <cma_stall>0</cma_stall>
      <cp>-0.6 0 0.155</cp>
      <area>.15329</area>
      <upward>0 1 0</upward>
      <control_joint_rad_to_cl>4.0</control_joint_rad_to_cl>
      <forward>1 0 0</forward>
      <link_name>cessna_3/base_link</link_name>
      <control_joint_name>cessna_3/rudder_joint</control_joint_name>
      <robotNamespace>/cessna0</robotNamespace>
    </plugin>
  </model>
</sdf>
