<?xml version="1.0" ?>
<sdf version="1.6">
  <model name="zephyr_body">
    <pose>0 0 0.02577 0 0 0</pose>

    <!-- this model is -y forward, x-left and z-up -->
    <link name="wing">
      <inertial>
        <pose>0 -0.12 0 0 0 0</pose>
        <mass>1.5</mass>
        <inertia>
          <ixx>0.083137104</ixx>
          <ixy>0</ixy>
          <iyy>0.387382402</iyy>
          <ixz>0</ixz>
          <iyz>0</iyz>
          <izz>0.469845106</izz>
        </inertia>
      </inertial>
      <visual name="visual">
        <geometry>
          <mesh>
            <uri>model://zephyr_delta_wing/meshes/wing.dae</uri>
            <submesh>
              <name>Wing</name>
              <center>true</center>
            </submesh>
          </mesh>
        </geometry>
      </visual>
      <collision name="body_collision">
        <geometry>
          <mesh>
            <uri>model://zephyr_delta_wing/meshes/wing.dae</uri>
            <submesh>
              <name>Wing</name>
              <center>true</center>
            </submesh>
          </mesh>
        </geometry>
      </collision>
      <collision name="right_rudder_collision">
        <pose>-0.76435 0.33918 0.002 -0.03 0 0</pose>
        <geometry>
          <box>
            <size>.005 0.12993 .12688</size>
          </box>
        </geometry>
      </collision>
      <collision name="left_rudder_collision">
        <pose>0.76435 0.33918 0.002 -0.03 0 0</pose>
        <geometry>
          <box>
            <size>.005 0.12993 .12688</size>
          </box>
        </geometry>
      </collision>
      <!-- save for debugging use
      <visual name="LDcanard">
        <pose>0 -0.1 0.0 0 0 0</pose>
        <geometry>
          <sphere>
            <radius>0.03</radius>
          </sphere>
        </geometry>
      </visual>
      <visual name="LDleft_wing">
        <pose>0.7 0.20 0.0 0 0 0</pose>
        <geometry>
          <sphere>
            <radius>0.03</radius>
          </sphere>
        </geometry>
      </visual>
      <visual name="LDright_wing">
        <pose>-0.7 0.20 0.0 0 0 0</pose>
        <geometry>
          <sphere>
            <radius>0.03</radius>
          </sphere>
        </geometry>
      </visual>
      <visual name="LD3">
        <pose>0.76 0.30 0.025 0 0 0</pose>
        <geometry>
          <sphere>
            <radius>0.03</radius>
          </sphere>
        </geometry>
      </visual>
      <visual name="LD4">
        <pose>-0.76 0.30 0.025 0 0 0</pose>
        <geometry>
          <sphere>
            <radius>0.03</radius>
          </sphere>
        </geometry>
      </visual>
      -->
      </link>
      <sensor name="gps_sensor" type="gps">
        <pose>0 0 0  0 0 0</pose>
        <update_rate>10.0</update_rate>
        <always_on>true</always_on>
        <gps>
          <position_sensing>
            <horizontal>
              <noise type="gaussian_quantized">
                <mean>0</mean>
                <stddev>1</stddev>
                <bias_mean>3</bias_mean>
                <bias_stddev>1</bias_stddev>
                <precision>0.5</precision>
              </noise>
            </horizontal>
            <vertical>
              <noise type="gaussian_quantized">
                <mean>0</mean>
                <stddev>1</stddev>
                <bias_mean>3</bias_mean>
                <bias_stddev>1</bias_stddev>
                <precision>1.0</precision>
              </noise>
            </vertical>
          </position_sensing>
          <velocity_sensing>
            <horizontal>
              <noise type="gaussian_quantized">
                <mean>0</mean>
                <stddev>0.1</stddev>
                <bias_mean>0.1</bias_mean>
                <bias_stddev>0.1</bias_stddev>
                <precision>0.1</precision>
              </noise>
            </horizontal>
            <vertical>
              <noise type="gaussian_quantized">
                <mean>0</mean>
                <stddev>0.2</stddev>
                <bias_mean>0.2</bias_mean>
                <bias_stddev>0.2</bias_stddev>
                <precision>0.2</precision>
              </noise>
            </vertical>
          </velocity_sensing>
        </gps>
      </sensor>
    <link name='zephyr/imu_link'>
      <inertial>
        <pose>0 0 0 0 0 0</pose>
        <mass>0.15</mass>
        <inertia>
          <ixx>0.00001</ixx>
          <ixy>0</ixy>
          <ixz>0</ixz>
          <iyy>0.00002</iyy>
          <iyz>0</iyz>
          <izz>0.00002</izz>
        </inertia>
      </inertial>
      <sensor name="imu_sensor" type="imu">
        <pose>0 0 0 3.141593 0 -1.57079</pose>
        <always_on>1</always_on>
        <update_rate>1000.0</update_rate>
      </sensor>
    </link>
    <joint name='zephyr/imu_joint' type='revolute'>
      <child>zephyr/imu_link</child>
      <parent>wing</parent>
      <axis>
        <xyz>0 0 1</xyz>
        <limit>
          <lower>0</lower>
          <upper>0</upper>
          <effort>0</effort>
          <velocity>0</velocity>
        </limit>
        <dynamics>
          <damping>1.0</damping>
        </dynamics>
        <use_parent_model_frame>1</use_parent_model_frame>
      </axis>
      <physics>
        <ode>
          <implicit_spring_damper>1</implicit_spring_damper>
        </ode>
      </physics>
    </joint>
    <link name="propeller">
      <!--<pose>0 0.1174 -0.007 0 1.57079 0</pose>-->
      <pose>0 0.07 0.008 0 1.57079 0</pose>
      <inertial>
        <mass>.05</mass>
        <inertia>
          <ixx>0.000367571</ixx>
          <ixy>0</ixy>
          <iyy>0.00036985</iyy>
          <ixz>0</ixz>
          <iyz>0</iyz>
          <izz>0.000003187</izz>
        </inertia>
      </inertial>
      <visual name="visual">
        <geometry>
          <mesh>
            <uri>model://zephyr_delta_wing/meshes/wing.dae</uri>
            <submesh>
              <name>Propeller</name>
              <center>true</center>
            </submesh>
          </mesh>
        </geometry>
      </visual>
      <collision name="blade1">
        <pose>0 0 0.074205 0 0  0.3</pose>
        <geometry>
          <box>
            <size>0.02561 0.00541 0.14841</size>
          </box>
        </geometry>
      </collision>
      <collision name="blade2">
        <pose>0 0 -0.074205 0 0  -0.3</pose>
        <geometry>
          <box>
            <size>0.02561 0.00541 0.14841</size>
          </box>
        </geometry>
      </collision>
      <!-- save for debugging use
      <visual name="LD1">
        <pose>0 0 0.074205 0 0  0.3</pose>
        <geometry>
         <sphere>
            <radius>0.02</radius>
          </sphere>
        </geometry>
      </visual>
      <visual name="LD2">
        <pose>0 0 -0.074205 0 0  -0.3</pose>
        <geometry>
          <sphere>
            <radius>0.02</radius>
          </sphere>
        </geometry>
      </visual>
      -->
    </link>

    <link name="flap_left">
      <pose>0.4530 .239 0.007 0 0 0</pose>
      <inertial>
        <pose>0 0 0 0 0 0.32445671</pose>
        <mass>.1</mass>
        <inertia>
          <ixx>0.000102319</ixx>
          <ixy>0</ixy>
          <iyy>0.00334417</iyy>
          <ixz>0</ixz>
          <iyz>0</iyz>
          <izz>0.003446072</izz>
        </inertia>
      </inertial>
      <visual name="visual">
        <geometry>
          <mesh>
            <uri>model://zephyr_delta_wing/meshes/wing.dae</uri>
            <submesh>
              <name>Flap_Left</name>
              <center>true</center>
            </submesh>
          </mesh>
        </geometry>
      </visual>
      <collision name="collision">
        <pose>-0.01 0.01 0 0 0 0.32445671</pose>
        <geometry>
          <box>
            <size>0.633463031 0.110694312 0.005</size>
          </box>
        </geometry>
      </collision>
    </link>

    <link name="flap_right">
      <pose>-0.4530 .239 0.007 0 0 0</pose>
      <inertial>
        <pose>0 0 0 0 0 -0.32445671</pose>
        <mass>.1</mass>
        <inertia>
          <ixx>0.000102319</ixx>
          <ixy>0</ixy>
          <iyy>0.00334417</iyy>
          <ixz>0</ixz>
          <iyz>0</iyz>
          <izz>0.003446072</izz>
        </inertia>
      </inertial>
      <visual name="visual">
        <geometry>
          <mesh>
            <uri>model://zephyr_delta_wing/meshes/wing.dae</uri>
            <submesh>
              <name>Flap_Right</name>
              <center>true</center>
            </submesh>
          </mesh>
        </geometry>
      </visual>
      <collision name="collision">
        <pose>0.01 0.01 0 0 0 -0.32445671</pose>
        <geometry>
          <box>
            <size>0.633463031 0.110694312 0.005</size>
          </box>
        </geometry>
      </collision>
    </link>

    <joint name="propeller_joint" type="revolute">
      <parent>wing</parent>
      <child>propeller</child>
      <axis>
        <xyz>0 -1 0</xyz>
        <dynamics>
          <damping>0.002</damping>
        </dynamics>
      </axis>
      <physics>
        <ode>
          <implicit_spring_damper>1</implicit_spring_damper>
        </ode>
      </physics>
    </joint>

    <joint name="flap_left_joint" type="revolute">
      <parent>wing</parent>
      <child>flap_left</child>
      <pose>0 -0.04 0 0 0 0</pose>
      <axis>
        <xyz>1 0.330321014 0</xyz>
        <limit>
          <lower>-0.524</lower>
          <upper>0.524</upper>
        </limit>
        <dynamics>
          <damping>0.1</damping>
        </dynamics>
      </axis>
      <physics>
        <ode>
          <implicit_spring_damper>1</implicit_spring_damper>
        </ode>
      </physics>
    </joint>

    <joint name="flap_right_joint" type="revolute">
      <parent>wing</parent>
      <child>flap_right</child>
      <pose>0 -0.04 0 0 0 0</pose>
      <axis>
        <xyz>1 -0.330321014 0</xyz>
        <limit>
          <lower>-0.524</lower>
          <upper>0.524</upper>
        </limit>
        <dynamics>
          <damping>0.1</damping>
        </dynamics>
      </axis>
      <physics>
        <ode>
          <implicit_spring_damper>1</implicit_spring_damper>
        </ode>
      </physics>
    </joint>
  </model>
</sdf>
