<sdf version='1.7'>
  <world name='default'>
    <gui fullscreen='0'>
      <camera name='user_camera'>
        <pose>1975.16 2211.72 12.201 0 0.397795 -0.900164</pose>
        <view_controller>orbit</view_controller>
        <projection_type>perspective</projection_type>
      </camera>
      <plugin name='keyboard' filename='libKeyboardGUIPlugin.so'/>
    </gui>
    <physics name='default_physics' default='0' type='ode'>
      <ode>
        <solver>
          <type>quick</type>
          <iters>100</iters>
          <sor>1</sor>
          <use_dynamic_moi_rescaling>0</use_dynamic_moi_rescaling>
        </solver>
        <constraints>
          <cfm>0</cfm>
          <erp>0.2</erp>
          <contact_max_correcting_vel>0.1</contact_max_correcting_vel>
          <contact_surface_layer>0</contact_surface_layer>
        </constraints>
      </ode>
      <real_time_update_rate>400</real_time_update_rate>
      <max_step_size>0.0025</max_step_size>
      <real_time_factor>1</real_time_factor>
    </physics>
    <scene>
      <sky>
        <clouds>
          <speed>5</speed>
        </clouds>
      </sky>
      <ambient>0.95 0.95 0.95 1</ambient>
      <background>0.3 0.3 0.3 1</background>
      <shadows>1</shadows>
    </scene>
    <gravity>0 0 -9.8</gravity>
    <magnetic_field>6e-06 2.3e-05 -4.2e-05</magnetic_field>
    <atmosphere type='adiabatic'/>
    <audio>
      <device>default</device>
    </audio>
    <wind/>
    <spherical_coordinates>
      <surface_model>EARTH_WGS84</surface_model>
      <latitude_deg>0</latitude_deg>
      <longitude_deg>0</longitude_deg>
      <elevation>0</elevation>
      <heading_deg>0</heading_deg>
    </spherical_coordinates>
    <state world_name='default'>
      <sim_time>900 605000000</sim_time>
      <real_time>28 437943550</real_time>
      <wall_time>1651274472 285892798</wall_time>
      <iterations>9177</iterations>
      <model name='cessna_with_camera'>
        <pose>1996.99 2200.86 0.024387 0 -2e-06 0</pose>
        <scale>1 1 1</scale>
        <link name='cessna_with_camera/base_link'>
          <pose>1996.99 2200.86 0.024387 0 -2e-06 0</pose>
          <velocity>-0 -0 -0 0 -0 0</velocity>
          <acceleration>0 -0 0 0 -0 0</acceleration>
          <wrench>0 -0 0 0 -0 0</wrench>
        </link>
        <link name='cessna_with_camera/elevators'>
          <pose>1996.43 2200.86 0.081386 0 -0 0</pose>
          <velocity>0 0 -0 0 -0 0</velocity>
          <acceleration>0 0 0 0 -0 0</acceleration>
          <wrench>0 0 0 0 -0 0</wrench>
        </link>
        <link name='cessna_with_camera/imu_link'>
          <pose>1996.99 2200.86 0.024387 0 -2e-06 0</pose>
          <velocity>0 0 -0 0 -0 0</velocity>
          <acceleration>-0 0 -0 0 -0 0</acceleration>
          <wrench>-0 0 -0 0 -0 0</wrench>
        </link>
        <link name='cessna_with_camera/left_aileron'>
          <pose>1996.85 2201.23 0.174386 0.05 -0 -0.12</pose>
          <velocity>-0 -0 -0 0 -0 0</velocity>
          <acceleration>0 0 0 0 -0 0</acceleration>
          <wrench>0 0 0 0 -0 0</wrench>
        </link>
        <link name='cessna_with_camera/propeller'>
          <pose>1997.17 2200.86 0.109887 0 -2e-06 0</pose>
          <velocity>0 0 -0 0 -0 0</velocity>
          <acceleration>0 0 0 0 -0 0</acceleration>
          <wrench>0 0 0 0 -0 0</wrench>
        </link>
        <link name='cessna_with_camera/right_aileron'>
          <pose>1996.85 2200.49 0.174386 -0.05 -0 0.12</pose>
          <velocity>-0 -0 -0 0 -0 0</velocity>
          <acceleration>0 0 -0 0 -0 0</acceleration>
          <wrench>0 0 -0 0 -0 0</wrench>
        </link>
        <link name='cessna_with_camera/rudder'>
          <pose>1996.48 2200.86 0.349386 0 -0.350002 0</pose>
          <velocity>-0 -0 -0 0 -0 0</velocity>
          <acceleration>0 -0 0 0 -0 0</acceleration>
          <wrench>0 -0 0 0 -0 0</wrench>
        </link>
      </model>
      <model name='cube_qr_added'>
        <pose>2057.46 1817.02 1 0 -0 0</pose>
        <scale>1 1 1</scale>
        <link name='link'>
          <pose>2057.46 1817.02 1 0 -0 0</pose>
          <velocity>0 0 0 0 -0 0</velocity>
          <acceleration>0 0 0 0 -0 0</acceleration>
          <wrench>0 0 0 0 -0 0</wrench>
        </link>
      </model>
      <model name='istanbul_airport'>
        <pose>2009.06 2195.17 0 0 -0 0</pose>
        <scale>1 1 1</scale>
        <link name='link'>
          <pose>2009.06 2195.17 0 0 -0 0</pose>
          <velocity>0 0 0 0 -0 0</velocity>
          <acceleration>0 0 0 0 -0 0</acceleration>
          <wrench>0 0 0 0 -0 0</wrench>
        </link>
      </model>
      <model name='istikbalgoklerdedir_q'>
        <pose>2011.73 1722.38 2.51239 -0.905158 0 0</pose>
        <scale>1 1 1</scale>
        <link name='link'>
          <pose>2011.73 1722.38 2.51239 -0.905158 0 0</pose>
          <velocity>0 0 0 0 -0 0</velocity>
          <acceleration>0 0 0 0 -0 0</acceleration>
          <wrench>0 0 0 0 -0 0</wrench>
        </link>
      </model>
      <model name='istikbalgoklerdedir_q_0'>
        <pose>2009.76 1720.12 2.30268 0 -0.921999 0</pose>
        <scale>1 1 1</scale>
        <link name='link'>
          <pose>2009.76 1720.12 2.30268 0 -0.921999 0</pose>
          <velocity>0 0 0 0 -0 0</velocity>
          <acceleration>0 0 0 0 -0 0</acceleration>
          <wrench>0 0 0 0 -0 0</wrench>
        </link>
      </model>
      <model name='istikbalgoklerdedir_q_1'>
        <pose>2014.39 1720.73 1.96979 0 0.915981 0</pose>
        <scale>1 1 1</scale>
        <link name='link'>
          <pose>2014.39 1720.73 1.96979 0 0.915981 0</pose>
          <velocity>0 0 0 0 -0 0</velocity>
          <acceleration>0 0 0 0 -0 0</acceleration>
          <wrench>0 0 0 0 -0 0</wrench>
        </link>
      </model>
      <model name='istikbalgoklerdedir_q_2'>
        <pose>2011.71 1718.08 2.10607 0.941603 -0 0</pose>
        <scale>1 1 1</scale>
        <link name='link'>
          <pose>2011.71 1718.08 2.10607 0.941603 -0 0</pose>
          <velocity>0 0 0 0 -0 0</velocity>
          <acceleration>0 0 0 0 -0 0</acceleration>
          <wrench>0 0 0 0 -0 0</wrench>
        </link>
      </model>
      <model name='mustafakemalataturk_m'>
        <pose>2059.62 1819.16 5.50298 0 -0 0</pose>
        <scale>1 1 1</scale>
        <link name='link'>
          <pose>2059.62 1819.16 5.50298 0 -0 0</pose>
          <velocity>0 0 0 0 -0 0</velocity>
          <acceleration>0 0 0 0 -0 0</acceleration>
          <wrench>0 0 0 0 -0 0</wrench>
        </link>
      </model>
      <model name='mustafakemalataturk_m_0'>
        <pose>2058.8 1821.29 2.73692 1.5708 -0 0</pose>
        <scale>1 1 1</scale>
        <link name='link'>
          <pose>2058.8 1821.29 2.73692 1.5708 -0 0</pose>
          <velocity>0 0 0 0 -0 0</velocity>
          <acceleration>0 0 0 0 -0 0</acceleration>
          <wrench>0 0 0 0 -0 0</wrench>
        </link>
      </model>
      <model name='mustafakemalataturk_m_1'>
        <pose>2057.4 1818.82 2.36857 3.14159 -1.57079 3.14159</pose>
        <scale>1 1 1</scale>
        <link name='link'>
          <pose>2057.4 1818.82 2.36857 3.14159 -1.57079 3.14159</pose>
          <velocity>0 0 0 0 -0 0</velocity>
          <acceleration>0 0 0 0 -0 0</acceleration>
          <wrench>0 0 0 0 -0 0</wrench>
        </link>
      </model>
      <model name='mustafakemalataturk_m_2'>
        <pose>2059.16 1816.94 2.78986 1.5708 -0 0</pose>
        <scale>1 1 1</scale>
        <link name='link'>
          <pose>2059.16 1816.94 2.78986 1.5708 -0 0</pose>
          <velocity>0 0 0 0 -0 0</velocity>
          <acceleration>0 0 0 0 -0 0</acceleration>
          <wrench>0 0 0 0 -0 0</wrench>
        </link>
      </model>
      <model name='mustafakemalataturk_m_3'>
        <pose>2061.79 1819.38 2.6622 3.14159 -1.57079 3.14159</pose>
        <scale>1 1 1</scale>
        <link name='link'>
          <pose>2061.79 1819.38 2.6622 3.14159 -1.57079 3.14159</pose>
          <velocity>0 0 0 0 -0 0</velocity>
          <acceleration>0 0 0 0 -0 0</acceleration>
          <wrench>0 0 0 0 -0 0</wrench>
        </link>
      </model>
      <model name='piramid_qr_added'>
        <pose>2008.94 1723.47 1 0 -0 0</pose>
        <scale>1 1 1</scale>
        <link name='link'>
          <pose>2008.94 1723.47 1 0 -0 0</pose>
          <velocity>0 0 0 0 -0 0</velocity>
          <acceleration>0 0 0 0 -0 0</acceleration>
          <wrench>0 0 0 0 -0 0</wrench>
        </link>
      </model>
      <model name='piramid_qr_cutted'>
        <pose>2055.85 1917.85 1 0 -0 0</pose>
        <scale>1 1 1</scale>
        <link name='link'>
          <pose>2055.85 1917.85 1 0 -0 0</pose>
          <velocity>0 0 0 0 -0 0</velocity>
          <acceleration>0 0 0 0 -0 0</acceleration>
          <wrench>0 0 0 0 -0 0</wrench>
        </link>
      </model>
      <model name='square_qr'>
        <pose>2084.87 1821.16 1 0 -0 0</pose>
        <scale>1 1 1</scale>
        <link name='link'>
          <pose>2084.87 1821.16 1 0 -0 0</pose>
          <velocity>0 0 0 0 -0 0</velocity>
          <acceleration>0 0 0 0 -0 0</acceleration>
          <wrench>0 0 0 0 -0 0</wrench>
        </link>
      </model>
      <model name='teknofest_h'>
        <pose>2058.14 1921.88 2.01862 -1.07261 0 0</pose>
        <scale>1 1 1</scale>
        <link name='link'>
          <pose>2058.14 1921.88 2.01862 -1.07261 0 0</pose>
          <velocity>0 0 0 0 -0 0</velocity>
          <acceleration>0 0 0 0 -0 0</acceleration>
          <wrench>0 0 0 0 -0 0</wrench>
        </link>
      </model>
      <model name='teknofest_h_0'>
        <pose>2058.11 1920.15 3.05744 0 -0 0</pose>
        <scale>1 1 1</scale>
        <link name='link'>
          <pose>2058.11 1920.15 3.05744 0 -0 0</pose>
          <velocity>0 0 0 0 -0 0</velocity>
          <acceleration>0 0 0 0 -0 0</acceleration>
          <wrench>0 0 0 0 -0 0</wrench>
        </link>
      </model>
      <model name='teknofest_h_1'>
        <pose>2058.08 1918.41 2.12337 1.09939 -0 0</pose>
        <scale>1 1 1</scale>
        <link name='link'>
          <pose>2058.08 1918.41 2.12337 1.09939 -0 0</pose>
          <velocity>0 0 0 0 -0 0</velocity>
          <acceleration>0 0 0 0 -0 0</acceleration>
          <wrench>0 0 0 0 -0 0</wrench>
        </link>
      </model>
      <model name='teknofest_h_2'>
        <pose>2056.38 1920.13 2.04592 0 -1.09274 0</pose>
        <scale>1 1 1</scale>
        <link name='link'>
          <pose>2056.38 1920.13 2.04592 0 -1.09274 0</pose>
          <velocity>0 0 0 0 -0 0</velocity>
          <acceleration>0 0 0 0 -0 0</acceleration>
          <wrench>0 0 0 0 -0 0</wrench>
        </link>
      </model>
      <model name='teknofest_h_3'>
        <pose>2059.88 1920.2 2.01705 0 1.04273 0</pose>
        <scale>1 1 1</scale>
        <link name='link'>
          <pose>2059.88 1920.2 2.01705 0 1.04273 0</pose>
          <velocity>0 0 0 0 -0 0</velocity>
          <acceleration>0 0 0 0 -0 0</acceleration>
          <wrench>0 0 0 0 -0 0</wrench>
        </link>
      </model>
      <model name='testucusu_m'>
        <pose>2086.38 1822.73 1.2058 0 -0 0</pose>
        <scale>1 1 1</scale>
        <link name='link'>
          <pose>2086.38 1822.73 1.2058 0 -0 0</pose>
          <velocity>0 0 0 0 -0 0</velocity>
          <acceleration>0 0 0 0 -0 0</acceleration>
          <wrench>0 0 0 0 -0 0</wrench>
        </link>
      </model>
      <model name='zephyr_with_camera'>
        <pose>1992.27 2199.71 0.061748 -0.013754 0.035508 -0.003255</pose>
        <scale>1 1 1</scale>
        <link name='ZED_stereocamera::link'>
          <pose>1992.28 2199.38 0.346217 -0.035515 -0.013745 -1.57357</pose>
          <velocity>-1.9e-05 0.000274 0.000117 -3.3e-05 1.7e-05 -0.000139</velocity>
          <acceleration>-0.000561 0.004689 0.001842 -0.000378 -0.030578 0.000323</acceleration>
          <wrench>-8.9e-05 0.000745 0.000293 0 -0 0</wrench>
        </link>
        <link name='cam_link'>
          <pose>1992.27 2199.71 0.061748 -0.013754 0.035508 -0.003255</pose>
          <velocity>3.7e-05 0.000264 0.000107 -3.4e-05 2.3e-05 -0.000139</velocity>
          <acceleration>-8.3e-05 0.00185 -0.001713 -0.010015 -0.000838 -8.6e-05</acceleration>
          <wrench>-1e-06 1.9e-05 -1.7e-05 0 -0 0</wrench>
        </link>
        <link name='skid_pad'>
          <pose>1992.27 2199.64 0.04273 -0.013727 0.035431 -0.003244</pose>
          <velocity>2.3e-05 0.000263 0.000121 1.4e-05 4.1e-05 -0.000147</velocity>
          <acceleration>-5.5e-05 0.000316 -0.001019 -0.009244 -0.001693 0.000455</acceleration>
          <wrench>-5e-06 3.2e-05 -0.000102 0 -0 0</wrench>
        </link>
        <link name='zephyr_delta_wing::flap_left'>
          <pose>1992.74 2199.95 0.23025 -0.514252 -0.121539 0.039186</pose>
          <velocity>7.3e-05 0.000207 8.9e-05 -1e-05 3.1e-05 -0.00014</velocity>
          <acceleration>-0.0002 0.00341 -0.003794 -0.012787 -0.001715 0.000484</acceleration>
          <wrench>-2e-05 0.000341 -0.000379 0 -0 0</wrench>
        </link>
        <link name='zephyr_delta_wing::flap_right'>
          <pose>1991.83 2199.95 0.262528 -0.517337 0.192495 -0.046179</pose>
          <velocity>8.7e-05 0.000367 0.000167 0.001673 -0.000548 -0.000191</velocity>
          <acceleration>-0.001531 0.000535 -0.010324 -0.184374 0.05789 0.010291</acceleration>
          <wrench>-0.000153 5.3e-05 -0.001032 0 -0 0</wrench>
        </link>
        <link name='zephyr_delta_wing::propeller'>
          <pose>1992.28 2199.79 0.268635 -2.10139 1.55486 -2.10421</pose>
          <velocity>5.1e-05 0.000271 0.000105 -3.4e-05 5.1e-05 -0.000139</velocity>
          <acceleration>-0.000259 0.003878 -0.002463 -1.15517 0.003171 0.009234</acceleration>
          <wrench>-1.3e-05 0.000194 -0.000123 0 -0 0</wrench>
        </link>
        <link name='zephyr_delta_wing::wing'>
          <pose>1992.28 2199.72 0.261603 -0.013754 0.035508 -0.003255</pose>
          <velocity>4.2e-05 0.000271 0.000108 -3.4e-05 2.3e-05 -0.000139</velocity>
          <acceleration>-0.00027 0.003825 -0.000559 -0.009986 -0.000811 0.000207</acceleration>
          <wrench>-0.000405 0.005738 -0.000839 0 -0 0</wrench>
        </link>
        <link name='zephyr_delta_wing::zephyr/imu_link'>
          <pose>1992.28 2199.72 0.261603 -0.013754 0.035508 -0.003255</pose>
          <velocity>4.2e-05 0.000271 0.000108 -3.5e-05 2.3e-05 -0.000139</velocity>
          <acceleration>-0.000259 0.003809 -0.001761 -0.010008 -0.000822 3.1e-05</acceleration>
          <wrench>-3.9e-05 0.000571 -0.000264 0 -0 0</wrench>
        </link>
      </model>
      <light name='sun'>
        <pose>1865.5 2039.39 10 0 -0 0</pose>
      </light>
    </state>
    <model name='cube_qr_added'>
      <pose>2057.46 1817.02 1 0 -0 0</pose>
      <static>1</static>
      <link name='link'>
        <visual name='visual'>
          <geometry>
            <mesh>
              <scale>2 2 2</scale>
              <uri>model://cube_qr_added/meshes/cube_qr_added.dae</uri>
            </mesh>
          </geometry>
          <material>
            <script>
              <name>Gazebo/White</name>
              <uri>__default__</uri>
            </script>
          </material>
        </visual>
        <self_collide>0</self_collide>
        <enable_wind>0</enable_wind>
        <kinematic>0</kinematic>
      </link>
    </model>
    <model name='square_qr'>
      <pose>2084.87 1821.16 1 0 -0 0</pose>
      <static>1</static>
      <link name='link'>
        <visual name='visual'>
          <geometry>
            <mesh>
              <uri>model://square_qr/meshes/square_qr.dae</uri>
            </mesh>
          </geometry>
          <material>
            <script>
              <name>Gazebo/White</name>
              <uri>__default__</uri>
            </script>
          </material>
        </visual>
        <self_collide>0</self_collide>
        <enable_wind>0</enable_wind>
        <kinematic>0</kinematic>
      </link>
    </model>
    <model name='piramid_qr_added'>
      <pose>2008.94 1723.47 1 0 -0 0</pose>
      <static>1</static>
      <link name='link'>
        <visual name='visual'>
          <geometry>
            <mesh>
              <scale>5 5 5</scale>
              <uri>model://piramid_qr_added/meshes/piramid_qr_added.dae</uri>
            </mesh>
          </geometry>
          <material>
            <script>
              <name>Gazebo/White</name>
              <uri>__default__</uri>
            </script>
          </material>
        </visual>
        <self_collide>0</self_collide>
        <enable_wind>0</enable_wind>
        <kinematic>0</kinematic>
      </link>
    </model>
    <model name='piramid_qr_cutted'>
      <pose>2055.85 1917.85 1 0 -0 0</pose>
      <static>1</static>
      <link name='link'>
        <visual name='visual'>
          <geometry>
            <mesh>
              <scale>3 3 3</scale>
              <uri>model://piramid_qr_cutted/meshes/piramid_qr_cutted.dae</uri>
            </mesh>
          </geometry>
          <material>
            <script>
              <name>Gazebo/White</name>
              <uri>__default__</uri>
            </script>
          </material>
        </visual>
        <self_collide>0</self_collide>
        <enable_wind>0</enable_wind>
        <kinematic>0</kinematic>
      </link>
    </model>
    <model name='teknofest_h'>
      <pose>2058.71 1924.45 1 0 -0 0</pose>
      <static>1</static>
      <link name='link'>
        <visual name='visual'>
          <geometry>
            <mesh>
              <scale>3 3 1e-06</scale>
              <uri>model://QR_12/meshes/teknofest_h.stl</uri>
            </mesh>
          </geometry>
          <material>
            <script>
              <name>Gazebo/Black</name>
              <uri>__default__</uri>
            </script>
          </material>
        </visual>
        <self_collide>0</self_collide>
        <enable_wind>0</enable_wind>
        <kinematic>0</kinematic>
      </link>
    </model>
    <model name='teknofest_h_0'>
      <pose>2063.33 1920.33 1 0 -0 0</pose>
      <static>1</static>
      <link name='link'>
        <visual name='visual'>
          <geometry>
            <mesh>
              <scale>3 3 1e-06</scale>
              <uri>model://QR_12/meshes/teknofest_h.stl</uri>
            </mesh>
          </geometry>
          <material>
            <script>
              <name>Gazebo/Black</name>
              <uri>__default__</uri>
            </script>
          </material>
        </visual>
        <self_collide>0</self_collide>
        <enable_wind>0</enable_wind>
        <kinematic>0</kinematic>
      </link>
    </model>
    <model name='teknofest_h_1'>
      <pose>2057.78 1914.68 1 0 -0 0</pose>
      <static>1</static>
      <link name='link'>
        <visual name='visual'>
          <geometry>
            <mesh>
              <scale>3 3 1e-06</scale>
              <uri>model://QR_12/meshes/teknofest_h.stl</uri>
            </mesh>
          </geometry>
          <material>
            <script>
              <name>Gazebo/Black</name>
              <uri>__default__</uri>
            </script>
          </material>
        </visual>
        <self_collide>0</self_collide>
        <enable_wind>0</enable_wind>
        <kinematic>0</kinematic>
      </link>
    </model>
    <model name='teknofest_h_2'>
      <pose>2053.21 1919.4 1 0 -0 0</pose>
      <static>1</static>
      <link name='link'>
        <visual name='visual'>
          <geometry>
            <mesh>
              <scale>3 3 1e-06</scale>
              <uri>model://QR_12/meshes/teknofest_h.stl</uri>
            </mesh>
          </geometry>
          <material>
            <script>
              <name>Gazebo/Black</name>
              <uri>__default__</uri>
            </script>
          </material>
        </visual>
        <self_collide>0</self_collide>
        <enable_wind>0</enable_wind>
        <kinematic>0</kinematic>
      </link>
    </model>
    <model name='teknofest_h_3'>
      <pose>2063.19 1923.32 1 0 -0 0</pose>
      <static>1</static>
      <link name='link'>
        <visual name='visual'>
          <geometry>
            <mesh>
              <scale>3 3 1e-06</scale>
              <uri>model://QR_12/meshes/teknofest_h.stl</uri>
            </mesh>
          </geometry>
          <material>
            <script>
              <name>Gazebo/Black</name>
              <uri>__default__</uri>
            </script>
          </material>
        </visual>
        <self_collide>0</self_collide>
        <enable_wind>0</enable_wind>
        <kinematic>0</kinematic>
      </link>
    </model>
    <model name='testucusu_m'>
      <pose>2086.38 1822.73 1 0 -0 0</pose>
      <static>1</static>
      <link name='link'>
        <visual name='visual'>
          <geometry>
            <mesh>
              <scale>3 3 1e-06</scale>
              <uri>model://QR_06/meshes/testucusu_m.stl</uri>
            </mesh>
          </geometry>
          <material>
            <script>
              <name>Gazebo/Black</name>
              <uri>__default__</uri>
            </script>
          </material>
        </visual>
        <self_collide>0</self_collide>
        <enable_wind>0</enable_wind>
        <kinematic>0</kinematic>
      </link>
    </model>
    <model name='mustafakemalataturk_m'>
      <pose>2065.61 1819.53 1 0 -0 0</pose>
      <static>1</static>
      <link name='link'>
        <visual name='visual'>
          <geometry>
            <mesh>
              <scale>3 3 1e-06</scale>
              <uri>model://QR_14/meshes/mustafakemalataturk_m.stl</uri>
            </mesh>
          </geometry>
          <material>
            <script>
              <name>Gazebo/Black</name>
              <uri>__default__</uri>
            </script>
          </material>
        </visual>
        <self_collide>0</self_collide>
        <enable_wind>0</enable_wind>
        <kinematic>0</kinematic>
      </link>
    </model>
    <model name='mustafakemalataturk_m_0'>
      <pose>2059.93 1823.49 1 0 -0 0</pose>
      <static>1</static>
      <link name='link'>
        <visual name='visual'>
          <geometry>
            <mesh>
              <scale>3 3 1e-06</scale>
              <uri>model://QR_14/meshes/mustafakemalataturk_m.stl</uri>
            </mesh>
          </geometry>
          <material>
            <script>
              <name>Gazebo/Black</name>
              <uri>__default__</uri>
            </script>
          </material>
        </visual>
        <self_collide>0</self_collide>
        <enable_wind>0</enable_wind>
        <kinematic>0</kinematic>
      </link>
    </model>
    <model name='mustafakemalataturk_m_1'>
      <pose>2054.12 1818.17 1 0 -0 0</pose>
      <static>1</static>
      <link name='link'>
        <visual name='visual'>
          <geometry>
            <mesh>
              <scale>3 3 1e-06</scale>
              <uri>model://QR_14/meshes/mustafakemalataturk_m.stl</uri>
            </mesh>
          </geometry>
          <material>
            <script>
              <name>Gazebo/Black</name>
              <uri>__default__</uri>
            </script>
          </material>
        </visual>
        <self_collide>0</self_collide>
        <enable_wind>0</enable_wind>
        <kinematic>0</kinematic>
      </link>
    </model>
    <model name='mustafakemalataturk_m_2'>
      <pose>2059.16 1812.95 1 0 -0 0</pose>
      <static>1</static>
      <link name='link'>
        <visual name='visual'>
          <geometry>
            <mesh>
              <scale>3 3 1e-06</scale>
              <uri>model://QR_14/meshes/mustafakemalataturk_m.stl</uri>
            </mesh>
          </geometry>
          <material>
            <script>
              <name>Gazebo/Black</name>
              <uri>__default__</uri>
            </script>
          </material>
        </visual>
        <self_collide>0</self_collide>
        <enable_wind>0</enable_wind>
        <kinematic>0</kinematic>
      </link>
    </model>
    <model name='mustafakemalataturk_m_3'>
      <pose>2064.09 1823.31 1 0 -0 0</pose>
      <static>1</static>
      <link name='link'>
        <visual name='visual'>
          <geometry>
            <mesh>
              <scale>3 3 1e-06</scale>
              <uri>model://QR_14/meshes/mustafakemalataturk_m.stl</uri>
            </mesh>
          </geometry>
          <material>
            <script>
              <name>Gazebo/Black</name>
              <uri>__default__</uri>
            </script>
          </material>
        </visual>
        <self_collide>0</self_collide>
        <enable_wind>0</enable_wind>
        <kinematic>0</kinematic>
      </link>
    </model>
    <model name='istikbalgoklerdedir_q'>
      <pose>2012.12 1726.12 1 0 -0 0</pose>
      <static>1</static>
      <link name='link'>
        <visual name='visual'>
          <geometry>
            <mesh>
              <scale>3 3 1e-06</scale>
              <uri>model://QR_17/meshes/istikbalgoklerdedir_q.stl</uri>
            </mesh>
          </geometry>
          <material>
            <script>
              <name>Gazebo/Black</name>
              <uri>__default__</uri>
            </script>
          </material>
        </visual>
        <self_collide>0</self_collide>
        <enable_wind>0</enable_wind>
        <kinematic>0</kinematic>
      </link>
    </model>
    <model name='istikbalgoklerdedir_q_0'>
      <pose>2006.64 1720.06 1 0 -0 0</pose>
      <static>1</static>
      <link name='link'>
        <visual name='visual'>
          <geometry>
            <mesh>
              <scale>3 3 1e-06</scale>
              <uri>model://QR_17/meshes/istikbalgoklerdedir_q.stl</uri>
            </mesh>
          </geometry>
          <material>
            <script>
              <name>Gazebo/Black</name>
              <uri>__default__</uri>
            </script>
          </material>
        </visual>
        <self_collide>0</self_collide>
        <enable_wind>0</enable_wind>
        <kinematic>0</kinematic>
      </link>
    </model>
    <model name='istikbalgoklerdedir_q_1'>
      <pose>2017.61 1720.73 1 0 -0 0</pose>
      <static>1</static>
      <link name='link'>
        <visual name='visual'>
          <geometry>
            <mesh>
              <scale>3 3 1e-06</scale>
              <uri>model://QR_17/meshes/istikbalgoklerdedir_q.stl</uri>
            </mesh>
          </geometry>
          <material>
            <script>
              <name>Gazebo/Black</name>
              <uri>__default__</uri>
            </script>
          </material>
        </visual>
        <self_collide>0</self_collide>
        <enable_wind>0</enable_wind>
        <kinematic>0</kinematic>
      </link>
    </model>
    <model name='istikbalgoklerdedir_q_2'>
      <pose>2011.14 1713.98 1 0 -0 0</pose>
      <static>1</static>
      <link name='link'>
        <visual name='visual'>
          <geometry>
            <mesh>
              <scale>3 3 1e-06</scale>
              <uri>model://QR_17/meshes/istikbalgoklerdedir_q.stl</uri>
            </mesh>
          </geometry>
          <material>
            <script>
              <name>Gazebo/Black</name>
              <uri>__default__</uri>
            </script>
          </material>
        </visual>
        <self_collide>0</self_collide>
        <enable_wind>0</enable_wind>
        <kinematic>0</kinematic>
      </link>
    </model>
    <light name='sun' type='directional'>
      <cast_shadows>1</cast_shadows>
      <pose>1865.5 2039.39 10 0 -0 0</pose>
      <diffuse>0.8 0.8 0.8 1</diffuse>
      <specular>0.2 0.2 0.2 1</specular>
      <attenuation>
        <range>1000</range>
        <constant>0.9</constant>
        <linear>0.01</linear>
        <quadratic>0.001</quadratic>
      </attenuation>
      <direction>-0.5 0.1 -0.9</direction>
      <spot>
        <inner_angle>0</inner_angle>
        <outer_angle>0</outer_angle>
        <falloff>0</falloff>
      </spot>
    </light>
    <model name='istanbul_airport'>
      <static>1</static>
      <link name='link'>
        <collision name='collision_mcmillan'>
          <geometry>
            <heightmap>
              <uri>model://istanbul_airport/media/istanbul_airport.tif</uri>
              <pos>2000 -1000 -785</pos>
              <texture>
                <size>10</size>
                <diffuse>__default__</diffuse>
                <normal>__default__</normal>
              </texture>
              <blend>
                <min_height>0</min_height>
                <fade_dist>0</fade_dist>
              </blend>
            </heightmap>
          </geometry>
          <max_contacts>10</max_contacts>
          <surface>
            <contact>
              <ode/>
            </contact>
            <bounce/>
            <friction>
              <torsional>
                <ode/>
              </torsional>
              <ode/>
            </friction>
          </surface>
        </collision>
        <visual name='visual_mcmillan'>
          <geometry>
            <heightmap>
              <texture>
                <diffuse>model://istanbul_airport/media/textures/istanbul_airport.png</diffuse>
                <normal>file://media/materials/textures/flat_normal.png</normal>
                <size>8193</size>
                <box>
                  <size>1000 1000 0.5</size>
                </box>
              </texture>
              <uri>model://istanbul_airport/media/istanbul_airport.tif</uri>
              <pos>2000 -1000 -800</pos>
              <blend>
                <min_height>0</min_height>
                <fade_dist>0</fade_dist>
              </blend>
            </heightmap>
          </geometry>
        </visual>
        <self_collide>0</self_collide>
        <enable_wind>0</enable_wind>
        <kinematic>0</kinematic>
      </link>
      <pose>2009.06 2195.17 0 0 -0 0</pose>
    </model>
    <model name='zephyr_with_camera'>
      <pose>1992.34 2200.86 0 0 -0 0</pose>
      <frame name='zephyr_delta_wing::__model__' attached_to='zephyr_delta_wing::wing'>
        <pose relative_to='__model__'>0 0 0.2 0 -0 0</pose>
      </frame>
      <link name='zephyr_delta_wing::wing'>
        <inertial>
          <pose>0 -0.12 0 0 -0 0</pose>
          <mass>1.5</mass>
          <inertia>
            <ixx>0.0831371</ixx>
            <ixy>0</ixy>
            <iyy>0.387382</iyy>
            <ixz>0</ixz>
            <iyz>0</iyz>
            <izz>0.469845</izz>
          </inertia>
        </inertial>
        <visual name='visual'>
          <geometry>
            <mesh>
              <uri>model://zephyr_delta_wing/meshes/wing.dae</uri>
              <submesh>
                <name>Wing</name>
                <center>1</center>
              </submesh>
            </mesh>
          </geometry>
        </visual>
        <collision name='body_collision'>
          <geometry>
            <mesh>
              <uri>model://zephyr_delta_wing/meshes/wing.dae</uri>
              <submesh>
                <name>Wing</name>
                <center>1</center>
              </submesh>
            </mesh>
          </geometry>
          <max_contacts>10</max_contacts>
          <surface>
            <contact>
              <ode/>
            </contact>
            <bounce/>
            <friction>
              <torsional>
                <ode/>
              </torsional>
              <ode/>
            </friction>
          </surface>
        </collision>
        <collision name='right_rudder_collision'>
          <pose>-0.76435 0.33918 0.002 -0.03 0 0</pose>
          <geometry>
            <box>
              <size>0.005 0.12993 0.12688</size>
            </box>
          </geometry>
          <max_contacts>10</max_contacts>
          <surface>
            <contact>
              <ode/>
            </contact>
            <bounce/>
            <friction>
              <torsional>
                <ode/>
              </torsional>
              <ode/>
            </friction>
          </surface>
        </collision>
        <collision name='left_rudder_collision'>
          <pose>0.76435 0.33918 0.002 -0.03 0 0</pose>
          <geometry>
            <box>
              <size>0.005 0.12993 0.12688</size>
            </box>
          </geometry>
          <max_contacts>10</max_contacts>
          <surface>
            <contact>
              <ode/>
            </contact>
            <bounce/>
            <friction>
              <torsional>
                <ode/>
              </torsional>
              <ode/>
            </friction>
          </surface>
        </collision>
        <pose relative_to='zephyr_delta_wing::__model__'>0 0 0 0 -0 0</pose>
        <self_collide>0</self_collide>
        <enable_wind>0</enable_wind>
        <kinematic>0</kinematic>
      </link>
      <link name='zephyr_delta_wing::zephyr/imu_link'>
        <inertial>
          <pose>0 0 0 0 -0 0</pose>
          <mass>0.15</mass>
          <inertia>
            <ixx>1e-05</ixx>
            <ixy>0</ixy>
            <ixz>0</ixz>
            <iyy>2e-05</iyy>
            <iyz>0</iyz>
            <izz>2e-05</izz>
          </inertia>
        </inertial>
        <sensor name='imu_sensor' type='imu'>
          <pose>0 0 0 -3.14159 -0 -1.57079</pose>
          <always_on>1</always_on>
          <update_rate>1000</update_rate>
          <imu/>
        </sensor>
        <pose relative_to='zephyr_delta_wing::__model__'>0 0 0 0 -0 0</pose>
        <self_collide>0</self_collide>
        <enable_wind>0</enable_wind>
        <kinematic>0</kinematic>
      </link>
      <joint name='zephyr_delta_wing::zephyr/imu_joint' type='revolute'>
        <child>zephyr_delta_wing::zephyr/imu_link</child>
        <parent>zephyr_delta_wing::wing</parent>
        <axis>
          <xyz expressed_in='zephyr_delta_wing::__model__'>0 0 1</xyz>
          <limit>
            <lower>0</lower>
            <upper>0</upper>
            <effort>0</effort>
            <velocity>0</velocity>
          </limit>
          <dynamics>
            <damping>1</damping>
            <spring_reference>0</spring_reference>
            <spring_stiffness>0</spring_stiffness>
          </dynamics>
        </axis>
        <physics>
          <ode>
            <implicit_spring_damper>1</implicit_spring_damper>
            <limit>
              <cfm>0</cfm>
              <erp>0.2</erp>
            </limit>
          </ode>
        </physics>
      </joint>
      <link name='zephyr_delta_wing::propeller'>
        <pose relative_to='zephyr_delta_wing::__model__'>0 0.07 0.008 0 1.57079 0</pose>
        <inertial>
          <mass>0.05</mass>
          <inertia>
            <ixx>0.000367571</ixx>
            <ixy>0</ixy>
            <iyy>0.00036985</iyy>
            <ixz>0</ixz>
            <iyz>0</iyz>
            <izz>3.187e-06</izz>
          </inertia>
          <pose>0 0 0 0 -0 0</pose>
        </inertial>
        <visual name='visual'>
          <geometry>
            <mesh>
              <uri>model://zephyr_delta_wing/meshes/wing.dae</uri>
              <submesh>
                <name>Propeller</name>
                <center>1</center>
              </submesh>
            </mesh>
          </geometry>
        </visual>
        <collision name='blade1'>
          <pose>0 0 0.074205 0 -0 0.3</pose>
          <geometry>
            <box>
              <size>0.02561 0.00541 0.14841</size>
            </box>
          </geometry>
          <max_contacts>10</max_contacts>
          <surface>
            <contact>
              <ode/>
            </contact>
            <bounce/>
            <friction>
              <torsional>
                <ode/>
              </torsional>
              <ode/>
            </friction>
          </surface>
        </collision>
        <collision name='blade2'>
          <pose>0 0 -0.074205 0 0 -0.3</pose>
          <geometry>
            <box>
              <size>0.02561 0.00541 0.14841</size>
            </box>
          </geometry>
          <max_contacts>10</max_contacts>
          <surface>
            <contact>
              <ode/>
            </contact>
            <bounce/>
            <friction>
              <torsional>
                <ode/>
              </torsional>
              <ode/>
            </friction>
          </surface>
        </collision>
        <self_collide>0</self_collide>
        <enable_wind>0</enable_wind>
        <kinematic>0</kinematic>
      </link>
      <link name='zephyr_delta_wing::flap_left'>
        <pose relative_to='zephyr_delta_wing::__model__'>0.453 0.239 0.007 0 -0 0</pose>
        <inertial>
          <pose>0 0 0 0 -0 0.324457</pose>
          <mass>0.1</mass>
          <inertia>
            <ixx>0.000102319</ixx>
            <ixy>0</ixy>
            <iyy>0.00334417</iyy>
            <ixz>0</ixz>
            <iyz>0</iyz>
            <izz>0.00344607</izz>
          </inertia>
        </inertial>
        <visual name='visual'>
          <geometry>
            <mesh>
              <uri>model://zephyr_delta_wing/meshes/wing.dae</uri>
              <submesh>
                <name>Flap_Left</name>
                <center>1</center>
              </submesh>
            </mesh>
          </geometry>
        </visual>
        <collision name='collision'>
          <pose>-0.01 0.01 0 0 -0 0.324457</pose>
          <geometry>
            <box>
              <size>0.633463 0.110694 0.005</size>
            </box>
          </geometry>
          <max_contacts>10</max_contacts>
          <surface>
            <contact>
              <ode/>
            </contact>
            <bounce/>
            <friction>
              <torsional>
                <ode/>
              </torsional>
              <ode/>
            </friction>
          </surface>
        </collision>
        <self_collide>0</self_collide>
        <enable_wind>0</enable_wind>
        <kinematic>0</kinematic>
      </link>
      <link name='zephyr_delta_wing::flap_right'>
        <pose relative_to='zephyr_delta_wing::__model__'>-0.453 0.239 0.007 0 -0 0</pose>
        <inertial>
          <pose>0 0 0 0 0 -0.324457</pose>
          <mass>0.1</mass>
          <inertia>
            <ixx>0.000102319</ixx>
            <ixy>0</ixy>
            <iyy>0.00334417</iyy>
            <ixz>0</ixz>
            <iyz>0</iyz>
            <izz>0.00344607</izz>
          </inertia>
        </inertial>
        <visual name='visual'>
          <geometry>
            <mesh>
              <uri>model://zephyr_delta_wing/meshes/wing.dae</uri>
              <submesh>
                <name>Flap_Right</name>
                <center>1</center>
              </submesh>
            </mesh>
          </geometry>
        </visual>
        <collision name='collision'>
          <pose>0.01 0.01 0 0 0 -0.324457</pose>
          <geometry>
            <box>
              <size>0.633463 0.110694 0.005</size>
            </box>
          </geometry>
          <max_contacts>10</max_contacts>
          <surface>
            <contact>
              <ode/>
            </contact>
            <bounce/>
            <friction>
              <torsional>
                <ode/>
              </torsional>
              <ode/>
            </friction>
          </surface>
        </collision>
        <self_collide>0</self_collide>
        <enable_wind>0</enable_wind>
        <kinematic>0</kinematic>
      </link>
      <joint name='zephyr_delta_wing::propeller_joint' type='revolute'>
        <parent>zephyr_delta_wing::wing</parent>
        <child>zephyr_delta_wing::propeller</child>
        <axis>
          <xyz>0 -1 0</xyz>
          <dynamics>
            <damping>0.002</damping>
            <spring_reference>0</spring_reference>
            <spring_stiffness>0</spring_stiffness>
          </dynamics>
          <limit>
            <lower>-1e+16</lower>
            <upper>1e+16</upper>
          </limit>
        </axis>
        <physics>
          <ode>
            <implicit_spring_damper>1</implicit_spring_damper>
            <limit>
              <cfm>0</cfm>
              <erp>0.2</erp>
            </limit>
          </ode>
        </physics>
      </joint>
      <joint name='zephyr_delta_wing::flap_left_joint' type='revolute'>
        <parent>zephyr_delta_wing::wing</parent>
        <child>zephyr_delta_wing::flap_left</child>
        <pose>0 -0.04 0 0 -0 0</pose>
        <axis>
          <xyz>1 0.330321 0</xyz>
          <limit>
            <lower>-0.524</lower>
            <upper>0.524</upper>
          </limit>
          <dynamics>
            <damping>0.1</damping>
            <spring_reference>0</spring_reference>
            <spring_stiffness>0</spring_stiffness>
          </dynamics>
        </axis>
        <physics>
          <ode>
            <implicit_spring_damper>1</implicit_spring_damper>
            <limit>
              <cfm>0</cfm>
              <erp>0.2</erp>
            </limit>
          </ode>
        </physics>
      </joint>
      <joint name='zephyr_delta_wing::flap_right_joint' type='revolute'>
        <parent>zephyr_delta_wing::wing</parent>
        <child>zephyr_delta_wing::flap_right</child>
        <pose>0 -0.04 0 0 -0 0</pose>
        <axis>
          <xyz>1 -0.330321 0</xyz>
          <limit>
            <lower>-0.524</lower>
            <upper>0.524</upper>
          </limit>
          <dynamics>
            <damping>0.1</damping>
            <spring_reference>0</spring_reference>
            <spring_stiffness>0</spring_stiffness>
          </dynamics>
        </axis>
        <physics>
          <ode>
            <implicit_spring_damper>1</implicit_spring_damper>
            <limit>
              <cfm>0</cfm>
              <erp>0.2</erp>
            </limit>
          </ode>
        </physics>
      </joint>
      <plugin name='invisible_canard' filename='libLiftDragPlugin.so'>
        <a0>0.13</a0>
        <cla>3.7</cla>
        <cda>0.06417112299</cda>
        <cma>-1.8</cma>
        <alpha_stall>0.3391428111</alpha_stall>
        <cla_stall>-3.85</cla_stall>
        <cda_stall>-0.9233984055</cda_stall>
        <cma_stall>0</cma_stall>
        <cp>0 -0.1 0</cp>
        <area>0.50</area>
        <air_density>1.2041</air_density>
        <forward>0 -1 0</forward>
        <upward>0 0 1</upward>
        <link_name>zephyr_delta_wing::wing</link_name>
      </plugin>
      <plugin name='left_wing' filename='libLiftDragPlugin.so'>
        <a0>0.15</a0>
        <cla>6.8</cla>
        <cda>0.06417112299</cda>
        <cma>-1.8</cma>
        <alpha_stall>0.6391428111</alpha_stall>
        <cla_stall>-3.85</cla_stall>
        <cda_stall>-0.9233984055</cda_stall>
        <cma_stall>0</cma_stall>
        <cp>0.7 0.20 0</cp>
        <area>0.10</area>
        <air_density>1.2041</air_density>
        <forward>0 -1 0</forward>
        <upward>0 0 1</upward>
        <link_name>zephyr_delta_wing::wing</link_name>
        <control_joint_name>zephyr_delta_wing::flap_left_joint</control_joint_name>
        <control_joint_rad_to_cl>-5.0</control_joint_rad_to_cl>
      </plugin>
      <plugin name='right_wing' filename='libLiftDragPlugin.so'>
        <a0>0.15</a0>
        <cla>6.8</cla>
        <cda>0.06417112299</cda>
        <cma>-1.8</cma>
        <alpha_stall>0.6391428111</alpha_stall>
        <cla_stall>-3.85</cla_stall>
        <cda_stall>-0.9233984055</cda_stall>
        <cma_stall>0</cma_stall>
        <cp>-0.7 0.20 0</cp>
        <area>0.10</area>
        <air_density>1.2041</air_density>
        <forward>0 -1 0</forward>
        <upward>0 0 1</upward>
        <link_name>zephyr_delta_wing::wing</link_name>
        <control_joint_name>zephyr_delta_wing::flap_right_joint</control_joint_name>
        <control_joint_rad_to_cl>-5.0</control_joint_rad_to_cl>
      </plugin>
      <plugin name='left_rudder' filename='libLiftDragPlugin.so'>
        <a0>0.0</a0>
        <cla>4.752798721</cla>
        <cda>0.6417112299</cda>
        <cma>-1.8</cma>
        <alpha_stall>0.3391428111</alpha_stall>
        <cla_stall>-3.85</cla_stall>
        <cda_stall>-0.9233984055</cda_stall>
        <cma_stall>0</cma_stall>
        <cp>-0.76 0.30 0.025</cp>
        <area>0.12</area>
        <air_density>1.2041</air_density>
        <forward>0 -1 0</forward>
        <upward>1 0 0</upward>
        <link_name>zephyr_delta_wing::wing</link_name>
      </plugin>
      <plugin name='right_rudder' filename='libLiftDragPlugin.so'>
        <a0>0.0</a0>
        <cla>4.752798721</cla>
        <cda>0.6417112299</cda>
        <cma>-1.8</cma>
        <alpha_stall>0.3391428111</alpha_stall>
        <cla_stall>-3.85</cla_stall>
        <cda_stall>-0.9233984055</cda_stall>
        <cma_stall>0</cma_stall>
        <cp>0.76 0.30 0.025</cp>
        <area>0.12</area>
        <air_density>1.2041</air_density>
        <forward>0 -1 0</forward>
        <upward>1 0 0</upward>
        <link_name>zephyr_delta_wing::wing</link_name>
      </plugin>
      <plugin name='propeller_blade_1' filename='libLiftDragPlugin.so'>
        <a0>0.30</a0>
        <alpha_stall>1.4</alpha_stall>
        <cla>4.2500</cla>
        <cda>0.10</cda>
        <cma>0.00</cma>
        <cla_stall>-0.025</cla_stall>
        <cda_stall>0.0</cda_stall>
        <cma_stall>0.0</cma_stall>
        <area>0.02</area>
        <air_density>1.2041</air_density>
        <cp>0 0 0.074205</cp>
        <forward>-1 0 0</forward>
        <upward>0 -1 0</upward>
        <link_name>zephyr_delta_wing::propeller</link_name>
      </plugin>
      <plugin name='propeller_blade_2' filename='libLiftDragPlugin.so'>
        <a0>0.30</a0>
        <alpha_stall>1.4</alpha_stall>
        <cla>4.2500</cla>
        <cda>0.10</cda>
        <cma>0.00</cma>
        <cla_stall>-0.025</cla_stall>
        <cda_stall>0.0</cda_stall>
        <cma_stall>0.0</cma_stall>
        <area>0.02</area>
        <air_density>1.2041</air_density>
        <cp>0 0 -0.074205</cp>
        <forward>1 0 0</forward>
        <upward>0 -1 0</upward>
        <link_name>zephyr_delta_wing::propeller</link_name>
      </plugin>
      <frame name='ZED_stereocamera::__model__' attached_to='ZED_stereocamera::link'>
        <pose relative_to='__model__'>0 -0.34 0.28 0 -0 -1.5708</pose>
      </frame>
      <link name='ZED_stereocamera::link'>
        <pose relative_to='ZED_stereocamera::__model__'>0 0 0 0 -0 0</pose>
        <inertial>
          <mass>0.159</mass>
          <inertia>
            <ixx>1.2e-05</ixx>
            <iyy>0.000406</iyy>
            <izz>0.000418</izz>
            <ixy>0</ixy>
            <ixz>0</ixz>
            <iyz>0</iyz>
          </inertia>
          <pose>0 0 0 0 -0 0</pose>
        </inertial>
        <collision name='collision'>
          <geometry>
            <box>
              <size>0.1 0.1 0.1</size>
            </box>
          </geometry>
          <max_contacts>10</max_contacts>
          <surface>
            <contact>
              <ode/>
            </contact>
            <bounce/>
            <friction>
              <torsional>
                <ode/>
              </torsional>
              <ode/>
            </friction>
          </surface>
        </collision>
        <visual name='visual'>
          <geometry>
            <mesh>
              <uri>model://ZED_stereocamera/meshes/ZED.stl</uri>
            </mesh>
          </geometry>
          <material>
            <script>
              <name>Gazebo/Grey</name>
              <uri>__default__</uri>
            </script>
          </material>
        </visual>
        <visual name='visual_lens_left'>
          <pose>0 0 0 0 1.57 0</pose>
          <geometry>
            <cylinder>
              <radius>0.007</radius>
              <length>0.03</length>
            </cylinder>
          </geometry>
          <material>
            <script>
              <uri>file://media/materials/scripts/gazebo.material</uri>
              <name>Gazebo/WideLensMap</name>
            </script>
          </material>
        </visual>
        <sensor name='camera' type='camera'>
          <always_on>1</always_on>
          <update_rate>41</update_rate>
          <visualize>0</visualize>
          <plugin name='camera_controller' filename='libgazebo_ros_camera.so'>
            <always_on>1</always_on>
            <update_rate>41</update_rate>
            <cameraName>zephyr</cameraName>
            <imageTopicName>image_raw</imageTopicName>
            <cameraInfoTopicName>camera_info</cameraInfoTopicName>
            <frameName>camera_link</frameName>
          </plugin>
          <plugin name='GstCameraPlugin' filename='libgazebo_gst_camera_plugin.so'>
            <robotNamespace/>
            <udpHost>127.0.0.1</udpHost>
            <udpPort>9999</udpPort>
          </plugin>
          <camera name='left'>
            <pose>0 0 0 0 -0 0</pose>
            <horizontal_fov>1.91986</horizontal_fov>
            <image>
              <width>1280</width>
              <height>720</height>
            </image>
            <clip>
              <near>0.1</near>
              <far>5000</far>
            </clip>
          </camera>
        </sensor>
        <self_collide>0</self_collide>
        <enable_wind>0</enable_wind>
        <kinematic>0</kinematic>
      </link>
      <link name='cam_link'>
        <pose>0 0 0 0 -0 0</pose>
        <inertial>
          <mass>0.01</mass>
          <inertia>
            <ixx>0.0001</ixx>
            <iyy>0.0001</iyy>
            <izz>0.0001</izz>
            <ixy>0</ixy>
            <ixz>0</ixz>
            <iyz>0</iyz>
          </inertia>
          <pose>0 0 0 0 -0 0</pose>
        </inertial>
        <self_collide>0</self_collide>
        <enable_wind>0</enable_wind>
        <kinematic>0</kinematic>
      </link>
      <joint name='camera_mount' type='fixed'>
        <child>ZED_stereocamera::link</child>
        <parent>zephyr_delta_wing::wing</parent>
        <axis>
          <xyz>0 0 1</xyz>
          <limit>
            <upper>0</upper>
            <lower>0</lower>
          </limit>
        </axis>
      </joint>
      <joint name='virtual_camera_mount' type='fixed'>
        <child>cam_link</child>
        <parent>zephyr_delta_wing::wing</parent>
        <axis>
          <xyz>0 0 1</xyz>
          <limit>
            <upper>0</upper>
            <lower>0</lower>
          </limit>
        </axis>
      </joint>
      <link name='skid_pad'>
        <pose>0 -0.07 -0.02 0 -0 0</pose>
        <inertial>
          <mass>0.1</mass>
          <inertia>
            <ixx>0.00431371</ixx>
            <ixy>0</ixy>
            <iyy>0.00387382</iyy>
            <ixz>0</ixz>
            <iyz>0</iyz>
            <izz>0.00809845</izz>
          </inertia>
          <pose>0 0 0 0 -0 0</pose>
        </inertial>
        <collision name='skid_pad'>
          <pose>0 0 0 0 -0 0</pose>
          <geometry>
            <box>
              <size>1 0.5 0.05</size>
            </box>
          </geometry>
          <surface>
            <contact>
              <ode>
                <kp>100000</kp>
                <kd>1</kd>
                <min_depth>0.01</min_depth>
                <max_vel>1</max_vel>
              </ode>
            </contact>
            <friction>
              <ode>
                <mu>0.3</mu>
                <fdir1>0 1 0</fdir1>
              </ode>
              <torsional>
                <ode/>
              </torsional>
            </friction>
            <bounce/>
          </surface>
          <max_contacts>10</max_contacts>
        </collision>
        <self_collide>0</self_collide>
        <enable_wind>0</enable_wind>
        <kinematic>0</kinematic>
      </link>
      <joint name='skid_pad_joint' type='fixed'>
        <parent>zephyr_delta_wing::wing</parent>
        <child>skid_pad</child>
        <axis>
          <limit>
            <lower>0</lower>
            <upper>0</upper>
          </limit>
          <xyz expressed_in='__model__'>0 1 0</xyz>
        </axis>
      </joint>
      <plugin name='ardupilot_plugin' filename='libArduPilotPlugin.so'>
        <fdm_addr>127.0.0.1</fdm_addr>
        <fdm_port_in>9012</fdm_port_in>
        <fdm_port_out>9013</fdm_port_out>
        <modelXYZToAirplaneXForwardZDown>0 0 0 3.141593 0 0</modelXYZToAirplaneXForwardZDown>
        <gazeboXYZToNED>0 0 0 3.141593 0 0</gazeboXYZToNED>
        <imuName>zephyr_with_camera::zephyr_delta_wing::zephyr/imu_link::imu_sensor</imuName>
        <connectionTimeoutMaxCount>5</connectionTimeoutMaxCount>
        <control channel='2'>
          <multiplier>838</multiplier>
          <offset>0.2</offset>
          <type>VELOCITY</type>
          <p_gain>0.5</p_gain>
          <i_gain>0</i_gain>
          <d_gain>0</d_gain>
          <i_max>0</i_max>
          <i_min>0</i_min>
          <cmd_max>2.0</cmd_max>
          <cmd_min>0.0</cmd_min>
          <jointName>zephyr_delta_wing::propeller_joint</jointName>
        </control>
        <control channel='0'>
          <multiplier>-1</multiplier>
          <offset>-0.5</offset>
          <type>POSITION</type>
          <p_gain>10.0</p_gain>
          <i_gain>0</i_gain>
          <d_gain>0</d_gain>
          <i_max>0</i_max>
          <i_min>0</i_min>
          <cmd_max>2.0</cmd_max>
          <cmd_min>-2.0</cmd_min>
          <jointName>zephyr_delta_wing::flap_left_joint</jointName>
        </control>
        <control channel='1'>
          <multiplier>-1</multiplier>
          <offset>-0.5</offset>
          <type>POSITION</type>
          <p_gain>10.0</p_gain>
          <i_gain>0</i_gain>
          <d_gain>0</d_gain>
          <i_max>0</i_max>
          <i_min>0</i_min>
          <cmd_max>2.0</cmd_max>
          <cmd_min>-2.0</cmd_min>
          <jointName>zephyr_delta_wing::flap_right_joint</jointName>
        </control>
      </plugin>
      <sensor name='gps_sensor' type='gps'>
        <pose>0 0 0 0 0 0</pose>
        <update_rate>10.0</update_rate>
        <always_on>1</always_on>
        <gps>
          <position_sensing>
            <horizontal>
              <noise type='gaussian_quantized'>
                <mean>0</mean>
                <stddev>1</stddev>
                <bias_mean>3</bias_mean>
                <bias_stddev>1</bias_stddev>
                <precision>0.5</precision>
              </noise>
            </horizontal>
            <vertical>
              <noise type='gaussian_quantized'>
                <mean>0</mean>
                <stddev>1</stddev>
                <bias_mean>3</bias_mean>
                <bias_stddev>1</bias_stddev>
                <precision>1.0</precision>
              </noise>
            </vertical>
          </position_sensing>
          <velocity_sensing>
            <horizontal>
              <noise type='gaussian_quantized'>
                <mean>0</mean>
                <stddev>0.1</stddev>
                <bias_mean>0.1</bias_mean>
                <bias_stddev>0.1</bias_stddev>
                <precision>0.1</precision>
              </noise>
            </horizontal>
            <vertical>
              <noise type='gaussian_quantized'>
                <mean>0</mean>
                <stddev>0.2</stddev>
                <bias_mean>0.2</bias_mean>
                <bias_stddev>0.2</bias_stddev>
                <precision>0.2</precision>
              </noise>
            </vertical>
          </velocity_sensing>
        </gps>
      </sensor>
    </model>
    <model name='cessna_with_camera'>
      <link name='cessna_with_camera/base_link'>
        <inertial>
          <pose>-0.00391 0 0.09273 0 -0 0</pose>
          <mass>4.001</mass>
          <inertia>
            <ixx>0.128638</ixx>
            <ixy>0</ixy>
            <ixz>-2.83339e-05</ixz>
            <iyy>0.18283</iyy>
            <iyz>0</iyz>
            <izz>0.26782</izz>
          </inertia>
        </inertial>
        <sensor name='cam' type='camera'>
          <pose>0.179 0 0.0855 0 -0 0</pose>
          <camera>
            <horizontal_fov>1.2</horizontal_fov>
            <image>
              <width>1280</width>
              <height>720</height>
            </image>
            <clip>
              <near>0.1</near>
              <far>5000</far>
            </clip>
          </camera>
          <always_on>1</always_on>
          <update_rate>41</update_rate>
          <visualize>0</visualize>
          <plugin name='camera_controller' filename='libgazebo_ros_camera.so'>
            <always_on>1</always_on>
            <update_rate>41</update_rate>
            <cameraName>cessna</cameraName>
            <imageTopicName>image_raw</imageTopicName>
            <cameraInfoTopicName>camera_info</cameraInfoTopicName>
            <frameName>camera_link</frameName>
          </plugin>
        </sensor>
        <self_collide>0</self_collide>
        <enable_wind>0</enable_wind>
        <kinematic>0</kinematic>
        <pose>0 0 0 -0 -0 -0</pose>
        <visual name='cessna_with_camera/base_link_visual'>
          <pose>0 0 0 0 -0 0</pose>
          <geometry>
            <mesh>
              <scale>0.1 0.1 0.1</scale>
              <uri>model://cessna/meshes/body.dae</uri>
            </mesh>
          </geometry>
          <material>
            <script>
              <name>Gazebo</name>
              <uri>file://media/materials/scripts/gazebo.material</uri>
            </script>
            <shader type='pixel'/>
          </material>
          <transparency>0</transparency>
          <cast_shadows>0</cast_shadows>
        </visual>
        <collision name='cessna_with_camera/base_link_collision'>
          <laser_retro>0</laser_retro>
          <max_contacts>10</max_contacts>
          <pose>0 0 0 0 -0 0</pose>
          <geometry>
            <box>
              <size>1 0.5 0.05</size>
            </box>
          </geometry>
          <surface>
            <friction>
              <ode>
                <mu>0.1</mu>
                <mu2>0.1</mu2>
                <fdir1>0 0 0</fdir1>
                <slip1>0</slip1>
                <slip2>0</slip2>
              </ode>
              <torsional>
                <coefficient>1</coefficient>
                <patch_radius>0</patch_radius>
                <surface_radius>0</surface_radius>
                <use_patch_radius>1</use_patch_radius>
                <ode>
                  <slip>0</slip>
                </ode>
              </torsional>
            </friction>
            <bounce>
              <restitution_coefficient>0</restitution_coefficient>
              <threshold>1e+06</threshold>
            </bounce>
            <contact>
              <collide_without_contact>0</collide_without_contact>
              <collide_without_contact_bitmask>1</collide_without_contact_bitmask>
              <collide_bitmask>1</collide_bitmask>
              <ode>
                <soft_cfm>0</soft_cfm>
                <soft_erp>0.2</soft_erp>
                <kp>1e+13</kp>
                <kd>1</kd>
                <max_vel>100</max_vel>
                <min_depth>0.001</min_depth>
              </ode>
              <bullet>
                <split_impulse>1</split_impulse>
                <split_impulse_penetration_threshold>-0.01</split_impulse_penetration_threshold>
                <soft_cfm>0</soft_cfm>
                <soft_erp>0.2</soft_erp>
                <kp>1e+13</kp>
                <kd>1</kd>
              </bullet>
            </contact>
          </surface>
        </collision>
      </link>
      <link name='cessna_with_camera/elevators'>
        <pose>-0.555 -0 0.057 -0 -0 -0</pose>
        <inertial>
          <pose>0 0 0 0 -0 0</pose>
          <mass>0.0001</mass>
          <inertia>
            <ixx>0.0038166</ixx>
            <ixy>0</ixy>
            <ixz>0</ixz>
            <iyy>0.0036</iyy>
            <iyz>0</iyz>
            <izz>0.003816</izz>
          </inertia>
        </inertial>
        <self_collide>0</self_collide>
        <enable_wind>0</enable_wind>
        <kinematic>0</kinematic>
        <visual name='cessna_with_camera/elevators_visual'>
          <pose>0.555 0 -0.057 0 -0 0</pose>
          <geometry>
            <mesh>
              <scale>0.1 0.1 0.1</scale>
              <uri>model://cessna/meshes/elevators.dae</uri>
            </mesh>
          </geometry>
          <material>
            <shader type='pixel'/>
          </material>
          <transparency>0</transparency>
          <cast_shadows>0</cast_shadows>
        </visual>
      </link>
      <link name='cessna_with_camera/imu_link'>
        <pose>0 0 0 -0 -0 -0</pose>
        <inertial>
          <pose>0 0 0 0 -0 0</pose>
          <mass>0.15</mass>
          <inertia>
            <ixx>1e-05</ixx>
            <ixy>0</ixy>
            <ixz>0</ixz>
            <iyy>2e-05</iyy>
            <iyz>0</iyz>
            <izz>3e-05</izz>
          </inertia>
        </inertial>
        <sensor name='imu_sensor' type='imu'>
          <pose>0 0 0 -3.14159 -0 0</pose>
          <always_on>1</always_on>
          <update_rate>1000</update_rate>
          <imu/>
        </sensor>
        <self_collide>0</self_collide>
        <enable_wind>0</enable_wind>
        <kinematic>0</kinematic>
      </link>
      <link name='cessna_with_camera/left_aileron'>
        <pose>-0.145 0.37 0.15 0.05 -0 -0.12</pose>
        <inertial>
          <pose>0 0 0 0 -0 0</pose>
          <mass>0.0001</mass>
          <inertia>
            <ixx>0.0038166</ixx>
            <ixy>0</ixy>
            <ixz>0</ixz>
            <iyy>0.0036</iyy>
            <iyz>0</iyz>
            <izz>0.003816</izz>
          </inertia>
        </inertial>
        <self_collide>0</self_collide>
        <enable_wind>0</enable_wind>
        <kinematic>0</kinematic>
        <visual name='cessna_with_camera/left_aileron_visual'>
          <pose>0.195 -0.36 -0.12 -0.05 -0 0.12</pose>
          <geometry>
            <mesh>
              <scale>0.1 0.1 0.1</scale>
              <uri>model://cessna/meshes/left_aileron.dae</uri>
            </mesh>
          </geometry>
          <material>
            <shader type='pixel'/>
          </material>
          <transparency>0</transparency>
          <cast_shadows>0</cast_shadows>
        </visual>
      </link>
      <link name='cessna_with_camera/propeller'>
        <pose>0.179 -0 0.0855 -0 -0 -0</pose>
        <inertial>
          <pose>0 0 0 0 -0 0</pose>
          <mass>0.025</mass>
          <inertia>
            <ixx>7.5067e-05</ixx>
            <ixy>0</ixy>
            <ixz>0</ixz>
            <iyy>7.515e-05</iyy>
            <iyz>0</iyz>
            <izz>6.8275e-07</izz>
          </inertia>
        </inertial>
        <self_collide>0</self_collide>
        <enable_wind>0</enable_wind>
        <kinematic>0</kinematic>
        <visual name='cessna_with_camera/propeller_visual'>
          <pose>0 0 0 0 -0 0</pose>
          <geometry>
            <mesh>
              <scale>0.1 0.1 0.1</scale>
              <uri>model://cessna/meshes/cessna_prop.dae</uri>
            </mesh>
          </geometry>
          <material>
            <script>
              <name>Gazebo/Blue</name>
              <uri>file://media/materials/scripts/gazebo.material</uri>
            </script>
            <shader type='pixel'/>
          </material>
          <transparency>0</transparency>
          <cast_shadows>0</cast_shadows>
        </visual>
      </link>
      <link name='cessna_with_camera/right_aileron'>
        <pose>-0.145 -0.37 0.15 -0.05 -0 0.12</pose>
        <inertial>
          <pose>0 0 0 0 -0 0</pose>
          <mass>0.0001</mass>
          <inertia>
            <ixx>0.0038166</ixx>
            <ixy>0</ixy>
            <ixz>0</ixz>
            <iyy>0.0036</iyy>
            <iyz>0</iyz>
            <izz>0.003816</izz>
          </inertia>
        </inertial>
        <self_collide>0</self_collide>
        <enable_wind>0</enable_wind>
        <kinematic>0</kinematic>
        <visual name='cessna_with_camera/right_aileron_visual'>
          <pose>0.195 0.36 -0.12 0.05 -0 -0.12</pose>
          <geometry>
            <mesh>
              <scale>0.1 0.1 0.1</scale>
              <uri>model://cessna/meshes/right_aileron.dae</uri>
            </mesh>
          </geometry>
          <material>
            <shader type='pixel'/>
          </material>
          <transparency>0</transparency>
          <cast_shadows>0</cast_shadows>
        </visual>
      </link>
      <link name='cessna_with_camera/rudder'>
        <pose>-0.51 0 0.325 0 -0.35 0</pose>
        <inertial>
          <pose>0 0 0 0 -0 0</pose>
          <mass>0.0001</mass>
          <inertia>
            <ixx>0.0038166</ixx>
            <ixy>0</ixy>
            <ixz>0</ixz>
            <iyy>0.0036</iyy>
            <iyz>0</iyz>
            <izz>0.003816</izz>
          </inertia>
        </inertial>
        <self_collide>0</self_collide>
        <enable_wind>0</enable_wind>
        <kinematic>0</kinematic>
        <visual name='cessna_with_camera/rudder_visual'>
          <pose>0.36 0 -0.475 0 0.35 0</pose>
          <geometry>
            <mesh>
              <scale>0.1 0.1 0.1</scale>
              <uri>model://cessna/meshes/rudder.dae</uri>
            </mesh>
          </geometry>
          <material>
            <shader type='pixel'/>
          </material>
          <transparency>0</transparency>
          <cast_shadows>0</cast_shadows>
        </visual>
      </link>
      <joint name='cessna_with_camera/elevators_joint' type='revolute'>
        <parent>cessna_with_camera/base_link</parent>
        <child>cessna_with_camera/elevators</child>
        <pose>0 0 0 0 -0 0</pose>
        <axis>
          <xyz>0 1 0</xyz>
          <limit>
            <lower>-0.78</lower>
            <upper>0.78</upper>
            <effort>-1</effort>
            <velocity>-1</velocity>
          </limit>
          <dynamics>
            <spring_reference>0</spring_reference>
            <spring_stiffness>0</spring_stiffness>
            <damping>0</damping>
            <friction>0</friction>
          </dynamics>
        </axis>
        <physics>
          <ode>
            <limit>
              <cfm>0</cfm>
              <erp>0.2</erp>
            </limit>
            <suspension>
              <cfm>0</cfm>
              <erp>0.2</erp>
            </suspension>
          </ode>
        </physics>
      </joint>
      <joint name='cessna_with_camera/imu_joint' type='revolute'>
        <parent>cessna_with_camera/base_link</parent>
        <child>cessna_with_camera/imu_link</child>
        <pose>0 0 0 0 -0 0</pose>
        <axis>
          <xyz>1 0 0</xyz>
          <limit>
            <lower>0</lower>
            <upper>0</upper>
            <effort>0</effort>
            <velocity>0</velocity>
          </limit>
          <dynamics>
            <spring_reference>0</spring_reference>
            <spring_stiffness>0</spring_stiffness>
            <damping>1</damping>
            <friction>0</friction>
          </dynamics>
        </axis>
        <physics>
          <ode>
            <limit>
              <cfm>0</cfm>
              <erp>0.2</erp>
            </limit>
            <suspension>
              <cfm>0</cfm>
              <erp>0.2</erp>
            </suspension>
          </ode>
        </physics>
      </joint>
      <joint name='cessna_with_camera/left_aileron_joint' type='revolute'>
        <parent>cessna_with_camera/base_link</parent>
        <child>cessna_with_camera/left_aileron</child>
        <pose>0 0 -0 0 -0 0</pose>
        <axis>
          <xyz>0 1 0</xyz>
          <limit>
            <lower>-0.78</lower>
            <upper>0.78</upper>
            <effort>-1</effort>
            <velocity>-1</velocity>
          </limit>
          <dynamics>
            <spring_reference>0</spring_reference>
            <spring_stiffness>0</spring_stiffness>
            <damping>0</damping>
            <friction>0</friction>
          </dynamics>
        </axis>
        <physics>
          <ode>
            <limit>
              <cfm>0</cfm>
              <erp>0.2</erp>
            </limit>
            <suspension>
              <cfm>0</cfm>
              <erp>0.2</erp>
            </suspension>
          </ode>
        </physics>
      </joint>
      <joint name='cessna_with_camera/propeller_joint' type='revolute'>
        <parent>cessna_with_camera/base_link</parent>
        <child>cessna_with_camera/propeller</child>
        <pose>0 0 0 0 -0 0</pose>
        <axis>
          <xyz>1 0 0</xyz>
          <limit>
            <lower>-1e+16</lower>
            <upper>1e+16</upper>
            <effort>-1</effort>
            <velocity>-1</velocity>
          </limit>
          <dynamics>
            <spring_reference>0</spring_reference>
            <spring_stiffness>0</spring_stiffness>
            <damping>0.001</damping>
            <friction>0</friction>
          </dynamics>
        </axis>
        <physics>
          <ode>
            <limit>
              <cfm>0</cfm>
              <erp>0.2</erp>
            </limit>
            <suspension>
              <cfm>0</cfm>
              <erp>0.2</erp>
            </suspension>
          </ode>
        </physics>
      </joint>
      <joint name='cessna_with_camera/right_aileron_joint' type='revolute'>
        <parent>cessna_with_camera/base_link</parent>
        <child>cessna_with_camera/right_aileron</child>
        <pose>0 -0 -0 0 -0 0</pose>
        <axis>
          <xyz>0 1 0</xyz>
          <limit>
            <lower>-0.78</lower>
            <upper>0.78</upper>
            <effort>-1</effort>
            <velocity>-1</velocity>
          </limit>
          <dynamics>
            <spring_reference>0</spring_reference>
            <spring_stiffness>0</spring_stiffness>
            <damping>0</damping>
            <friction>0</friction>
          </dynamics>
        </axis>
        <physics>
          <ode>
            <limit>
              <cfm>0</cfm>
              <erp>0.2</erp>
            </limit>
            <suspension>
              <cfm>0</cfm>
              <erp>0.2</erp>
            </suspension>
          </ode>
        </physics>
      </joint>
      <joint name='cessna_with_camera/rudder_joint' type='revolute'>
        <parent>cessna_with_camera/base_link</parent>
        <child>cessna_with_camera/rudder</child>
        <pose>-0 0 0 0 -0 0</pose>
        <axis>
          <xyz>0 0 1</xyz>
          <limit>
            <lower>-0.78</lower>
            <upper>0.78</upper>
            <effort>-1</effort>
            <velocity>-1</velocity>
          </limit>
          <dynamics>
            <spring_reference>0</spring_reference>
            <spring_stiffness>0</spring_stiffness>
            <damping>0</damping>
            <friction>0</friction>
          </dynamics>
        </axis>
        <physics>
          <ode>
            <limit>
              <cfm>0</cfm>
              <erp>0.2</erp>
            </limit>
            <suspension>
              <cfm>0</cfm>
              <erp>0.2</erp>
            </suspension>
          </ode>
        </physics>
      </joint>
      <static>0</static>
      <allow_auto_disable>1</allow_auto_disable>
      <plugin name='cessna_with_camera_arduplane_plugin' filename='libArduPilotPlugin.so'>
        <fdm_addr>127.0.0.1</fdm_addr>
        <fdm_port_in>9002</fdm_port_in>
        <fdm_port_out>9003</fdm_port_out>
        <modelXYZToAirplaneXForwardZDown>0 0 0 0 0 0</modelXYZToAirplaneXForwardZDown>
        <gazeboXYZToNED>0 0 0 3.141593 0 0</gazeboXYZToNED>
        <imuName>cessna_with_camera/imu_link::imu_sensor</imuName>
        <connectionTimeoutMaxCount>5</connectionTimeoutMaxCount>
        <control channel='2'>
          <type>VELOCITY</type>
          <offset>0</offset>
          <p_gain>.1</p_gain>
          <i_gain>0</i_gain>
          <d_gain>0</d_gain>
          <i_max>0</i_max>
          <i_min>0</i_min>
          <cmd_max>2.5</cmd_max>
          <cmd_min>0</cmd_min>
          <jointName>cessna_with_camera/propeller_joint</jointName>
          <multiplier>838</multiplier>
          <rotorVelocitySlowdownSim>1</rotorVelocitySlowdownSim>
        </control>
        <control channel='0'>
          <type>POSITION</type>
          <offset>-0.5</offset>
          <p_gain>2.00</p_gain>
          <i_gain>0</i_gain>
          <d_gain>1.50</d_gain>
          <i_max>0</i_max>
          <i_min>0</i_min>
          <cmd_max>1.0</cmd_max>
          <cmd_min>-1.0</cmd_min>
          <multiplier>-1</multiplier>
          <jointName>cessna_with_camera/left_aileron_joint</jointName>
          <controlVelocitySlowdownSim>1</controlVelocitySlowdownSim>
        </control>
        <control channel='0'>
          <type>POSITION</type>
          <offset>-0.5</offset>
          <p_gain>2.00</p_gain>
          <i_gain>0</i_gain>
          <d_gain>1.50</d_gain>
          <i_max>0</i_max>
          <i_min>0</i_min>
          <cmd_max>1.0</cmd_max>
          <cmd_min>-1.0</cmd_min>
          <multiplier>1</multiplier>
          <jointName>cessna_with_camera/right_aileron_joint</jointName>
          <controlVelocitySlowdownSim>1</controlVelocitySlowdownSim>
        </control>
        <control channel='1'>
          <type>POSITION</type>
          <offset>-0.5</offset>
          <p_gain>2.00</p_gain>
          <i_gain>0</i_gain>
          <d_gain>1.50</d_gain>
          <i_max>0</i_max>
          <i_min>0</i_min>
          <cmd_max>1.0</cmd_max>
          <cmd_min>-1.0</cmd_min>
          <multiplier>1</multiplier>
          <jointName>cessna_with_camera/elevators_joint</jointName>
          <controlVelocitySlowdownSim>1</controlVelocitySlowdownSim>
        </control>
        <control channel='3'>
          <type>POSITION</type>
          <offset>-0.5</offset>
          <p_gain>2.00</p_gain>
          <i_gain>0</i_gain>
          <d_gain>1.50</d_gain>
          <i_max>0</i_max>
          <i_min>0</i_min>
          <cmd_max>1.0</cmd_max>
          <cmd_min>-1.0</cmd_min>
          <multiplier>1</multiplier>
          <jointName>cessna_with_camera/rudder_joint</jointName>
          <controlVelocitySlowdownSim>1</controlVelocitySlowdownSim>
        </control>
        <robotNamespace>/cessna1</robotNamespace>
      </plugin>
      <plugin name='elevators_plugin' filename='libLiftDragPlugin.so'>
        <forward>1 0 0</forward>
        <link_name>cessna_with_camera/base_link</link_name>
        <control_joint_name>cessna_with_camera/elevators_joint</control_joint_name>
        <robotNamespace>/cessna1</robotNamespace>
      </plugin>
      <plugin name='left_aileron_plugin' filename='libLiftDragPlugin.so'>
        <a0>0.05984281113</a0>
        <cla>4.752798721</cla>
        <cda>0.6417112299</cda>
        <cma>-1.8</cma>
        <alpha_stall>0.3391428111</alpha_stall>
        <cla_stall>-3.85</cla_stall>
        <cda_stall>-0.9233984055</cda_stall>
        <cma_stall>0</cma_stall>
        <cp>-0.1 0.2205 0.15</cp>
        <area>8.08255</area>
        <upward>0 0 1</upward>
        <control_joint_rad_to_cl>-2.0</control_joint_rad_to_cl>
        <forward>1 0 0</forward>
        <link_name>cessna_with_camera/base_link</link_name>
        <control_joint_name>cessna_with_camera/left_aileron_joint</control_joint_name>
        <robotNamespace>/cessna1</robotNamespace>
      </plugin>
      <plugin name='propeller_bottom_blade' filename='libLiftDragPlugin.so'>
        <a0>0.4</a0>
        <cla>4.752798721</cla>
        <cda>0.6417112299</cda>
        <cma>0</cma>
        <alpha_stall>1.5</alpha_stall>
        <cla_stall>-3.85</cla_stall>
        <cda_stall>-0.9233984055</cda_stall>
        <cma_stall>0</cma_stall>
        <cp>-0.37 0 -0.77</cp>
        <area>.0001</area>
        <air_density>1.2041</air_density>
        <forward>0 1 0</forward>
        <upward>1 0 0</upward>
        <link_name>cessna_with_camera/propeller</link_name>
        <robotNamespace>/cessna1</robotNamespace>
      </plugin>
      <plugin name='propeller_top_blade' filename='libLiftDragPlugin.so'>
        <a0>0.4</a0>
        <cla>4.752798721</cla>
        <cda>0.6417112299</cda>
        <cma>0</cma>
        <alpha_stall>1.5</alpha_stall>
        <cla_stall>-3.85</cla_stall>
        <cda_stall>-0.9233984055</cda_stall>
        <cma_stall>0</cma_stall>
        <cp>-0.37 0 0.77</cp>
        <area>.0001</area>
        <air_density>1.2041</air_density>
        <forward>0 -1 0</forward>
        <upward>1 0 0</upward>
        <link_name>cessna_with_camera/propeller</link_name>
        <robotNamespace>/cessna1</robotNamespace>
      </plugin>
      <plugin name='right_aileron_plugin' filename='libLiftDragPlugin.so'>
        <a0>0.05984281113</a0>
        <cla>4.752798721</cla>
        <cda>0.6417112299</cda>
        <cma>-1.8</cma>
        <alpha_stall>0.3391428111</alpha_stall>
        <cla_stall>-3.85</cla_stall>
        <cda_stall>-0.9233984055</cda_stall>
        <cma_stall>0</cma_stall>
        <cp>-0.1 -0.2205 0.15</cp>
        <area>8.08255</area>
        <upward>0 0 1</upward>
        <control_joint_rad_to_cl>-2.0</control_joint_rad_to_cl>
        <forward>1 0 0</forward>
        <link_name>cessna_with_camera/base_link</link_name>
        <control_joint_name>cessna_with_camera/right_aileron_joint</control_joint_name>
        <robotNamespace>/cessna1</robotNamespace>
      </plugin>
      <plugin name='rudder_plugin' filename='libLiftDragPlugin.so'>
        <a0>0.0</a0>
        <cla>4.752798721</cla>
        <cda>0.6417112299</cda>
        <cma>-1.8</cma>
        <alpha_stall>0.3391428111</alpha_stall>
        <cla_stall>-3.85</cla_stall>
        <cda_stall>-0.9233984055</cda_stall>
        <cma_stall>0</cma_stall>
        <cp>-0.6 0 0.155</cp>
        <area>.15329</area>
        <upward>0 1 0</upward>
        <control_joint_rad_to_cl>4.0</control_joint_rad_to_cl>
        <forward>1 0 0</forward>
        <link_name>cessna_with_camera/base_link</link_name>
        <control_joint_name>cessna_with_camera/rudder_joint</control_joint_name>
        <robotNamespace>/cessna1</robotNamespace>
      </plugin>
      <pose>1995.1 2202.9 0 0 -0 0</pose>
    </model>
  </world>
</sdf>
