<sdf version='1.7'>
  <world name='default'>
    <gui fullscreen='0'>
      <camera name='user_camera'>
        <pose>114.909 133.863 31.7611 0 0.287846 -0.708926</pose>
        <view_controller>orbit</view_controller>
        <projection_type>perspective</projection_type>
      </camera>
      <plugin name='keyboard' filename='libKeyboardGUIPlugin.so'/>
    </gui>
    <physics name='default_physics' default='0' type='ode'>
      <ode>
        <solver>
          <type>quick</type>
          <iters>100</iters>
          <sor>1</sor>
          <use_dynamic_moi_rescaling>0</use_dynamic_moi_rescaling>
        </solver>
        <constraints>
          <cfm>0</cfm>
          <erp>0.2</erp>
          <contact_max_correcting_vel>0.1</contact_max_correcting_vel>
          <contact_surface_layer>0</contact_surface_layer>
        </constraints>
      </ode>
      <real_time_update_rate>400</real_time_update_rate>
      <max_step_size>0.0025</max_step_size>
      <real_time_factor>1</real_time_factor>
    </physics>
    <scene>
      <sky>
        <clouds>
          <speed>5</speed>
        </clouds>
      </sky>
      <ambient>0.95 0.95 0.95 1</ambient>
      <background>0.3 0.3 0.3 1</background>
      <shadows>1</shadows>
    </scene>
    <gravity>0 0 -9.8</gravity>
    <magnetic_field>6e-06 2.3e-05 -4.2e-05</magnetic_field>
    <atmosphere type='adiabatic'/>
    <audio>
      <device>default</device>
    </audio>
    <wind/>
    <spherical_coordinates>
      <surface_model>EARTH_WGS84</surface_model>
      <latitude_deg>0</latitude_deg>
      <longitude_deg>0</longitude_deg>
      <elevation>0</elevation>
      <heading_deg>0</heading_deg>
    </spherical_coordinates>
    <state world_name='default'>
      <sim_time>672 17500000</sim_time>
      <real_time>35 231326880</real_time>
      <wall_time>1651274980 985197592</wall_time>
      <iterations>12586</iterations>
      <model name='cessna_1'>
        <pose>170.883 102.901 13.6401 0.074867 -0.086663 -0.036829</pose>
        <scale>1 1 1</scale>
        <link name='cessna_1/base_link'>
          <pose>170.883 102.901 13.6401 0.074867 -0.086663 -0.036829</pose>
          <velocity>0 0 -0 0 -0 0</velocity>
          <acceleration>-0 0 -0 0 -0 0</acceleration>
          <wrench>-0 0 -0 0 -0 0</wrench>
        </link>
        <link name='cessna_1/elevators'>
          <pose>170.325 102.918 13.6486 0.074728 0.061506 -0.025734</pose>
          <velocity>0 0 -0 0.000149 0.004907 0.000367</velocity>
          <acceleration>0 0 0 0 -0 0</acceleration>
          <wrench>0 0 0 0 -0 0</wrench>
        </link>
        <link name='cessna_1/imu_link'>
          <pose>170.883 102.901 13.6401 0.074867 -0.086663 -0.036829</pose>
          <velocity>0 0 -0 0 -0 0</velocity>
          <acceleration>-0 0 -0 0 -0 0</acceleration>
          <wrench>-0 0 -0 0 -0 0</wrench>
        </link>
        <link name='cessna_1/left_aileron'>
          <pose>170.737 103.265 13.8041 0.136374 -0.174388 -0.170218</pose>
          <velocity>0 0 -0 -0.002262 -0.015342 -0.002095</velocity>
          <acceleration>0 0 0 0 -0 0</acceleration>
          <wrench>0 0 0 0 -0 0</wrench>
        </link>
        <link name='cessna_1/propeller'>
          <pose>171.054 102.889 13.7405 0.022967 -0.086663 -0.036829</pose>
          <velocity>0 0 -0 0 -0 0</velocity>
          <acceleration>-0 0 0 0 -0 0</acceleration>
          <wrench>-0 0 0 0 -0 0</wrench>
        </link>
        <link name='cessna_1/right_aileron'>
          <pose>170.714 102.527 13.749 0.014253 0.226812 0.087907</pose>
          <velocity>0 0 -0 -0.001501 0.017678 0.000246</velocity>
          <acceleration>-0 0 -0 0 -0 0</acceleration>
          <wrench>-0 0 -0 0 -0 0</wrench>
        </link>
        <link name='cessna_1/rudder'>
          <pose>170.346 102.897 13.9188 -0.261617 -0.361481 0.775918</pose>
          <velocity>0 0 -0 0.002029 0.000261 -0.004314</velocity>
          <acceleration>-0 -0 -0 0 -0 0</acceleration>
          <wrench>-0 -0 -0 0 -0 0</wrench>
        </link>
      </model>
      <model name='cube_qr_added'>
        <pose>622.998 137.263 1 0 -0 0</pose>
        <scale>1 1 1</scale>
        <link name='link'>
          <pose>622.998 137.263 1 0 -0 0</pose>
          <velocity>0 0 0 0 -0 0</velocity>
          <acceleration>0 0 0 0 -0 0</acceleration>
          <wrench>0 0 0 0 -0 0</wrench>
        </link>
      </model>
      <model name='heightmap'>
        <pose>3.4355 1.4445 0 0 -0 0</pose>
        <scale>1 1 1</scale>
        <link name='link'>
          <pose>3.4355 1.4445 0 0 -0 0</pose>
          <velocity>0 0 0 0 -0 0</velocity>
          <acceleration>0 0 0 0 -0 0</acceleration>
          <wrench>0 0 0 0 -0 0</wrench>
        </link>
      </model>
      <model name='istikbalgoklerdedir_q'>
        <pose>573.281 -48.0778 2.1302 -0.92429 0 0</pose>
        <scale>1 1 1</scale>
        <link name='link'>
          <pose>573.281 -48.0778 2.1302 -0.92429 0 0</pose>
          <velocity>0 0 0 0 -0 0</velocity>
          <acceleration>0 0 0 0 -0 0</acceleration>
          <wrench>0 0 0 0 -0 0</wrench>
        </link>
      </model>
      <model name='istikbalgoklerdedir_q_0'>
        <pose>571.357 -50.1727 2.2135 0 -0.92377 0</pose>
        <scale>1 1 1</scale>
        <link name='link'>
          <pose>571.357 -50.1727 2.2135 0 -0.92377 0</pose>
          <velocity>0 0 0 0 -0 0</velocity>
          <acceleration>0 0 0 0 -0 0</acceleration>
          <wrench>0 0 0 0 -0 0</wrench>
        </link>
      </model>
      <model name='istikbalgoklerdedir_q_1'>
        <pose>573.406 -52.4528 2.3199 0.887667 -0 0</pose>
        <scale>1 1 1</scale>
        <link name='link'>
          <pose>573.406 -52.4528 2.3199 0.887667 -0 0</pose>
          <velocity>0 0 0 0 -0 0</velocity>
          <acceleration>0 0 0 0 -0 0</acceleration>
          <wrench>0 0 0 0 -0 0</wrench>
        </link>
      </model>
      <model name='istikbalgoklerdedir_q_2'>
        <pose>575.216 -49.9618 2.89125 0 0.922451 0</pose>
        <scale>1 1 1</scale>
        <link name='link'>
          <pose>575.216 -49.9618 2.89125 0 0.922451 0</pose>
          <velocity>0 0 0 0 -0 0</velocity>
          <acceleration>0 0 0 0 -0 0</acceleration>
          <wrench>0 0 0 0 -0 0</wrench>
        </link>
      </model>
      <model name='mustafakemalataturk_m'>
        <pose>577.664 77.0007 2.07285 1.1092 -0 0</pose>
        <scale>1 1 1</scale>
        <link name='link'>
          <pose>577.664 77.0007 2.07285 1.1092 -0 0</pose>
          <velocity>0 0 0 0 -0 0</velocity>
          <acceleration>0 0 0 0 -0 0</acceleration>
          <wrench>0 0 0 0 -0 0</wrench>
        </link>
      </model>
      <model name='mustafakemalataturk_m_0'>
        <pose>577.533 80.5429 1.99197 -1.0493 0 0</pose>
        <scale>1 1 1</scale>
        <link name='link'>
          <pose>577.533 80.5429 1.99197 -1.0493 0 0</pose>
          <velocity>0 0 0 0 -0 0</velocity>
          <acceleration>0 0 0 0 -0 0</acceleration>
          <wrench>0 0 0 0 -0 0</wrench>
        </link>
      </model>
      <model name='mustafakemalataturk_m_1'>
        <pose>579.296 78.7844 2.02859 0 1.07161 0</pose>
        <scale>1 1 1</scale>
        <link name='link'>
          <pose>579.296 78.7844 2.02859 0 1.07161 0</pose>
          <velocity>0 0 0 0 -0 0</velocity>
          <acceleration>0 0 0 0 -0 0</acceleration>
          <wrench>0 0 0 0 -0 0</wrench>
        </link>
      </model>
      <model name='mustafakemalataturk_m_2'>
        <pose>575.839 78.8093 2.08774 0 -1.02191 0</pose>
        <scale>1 1 1</scale>
        <link name='link'>
          <pose>575.839 78.8093 2.08774 0 -1.02191 0</pose>
          <velocity>0 0 0 0 -0 0</velocity>
          <acceleration>0 0 0 0 -0 0</acceleration>
          <wrench>0 0 0 0 -0 0</wrench>
        </link>
      </model>
      <model name='mustafakemalataturk_m_3'>
        <pose>577.557 78.8155 3.08352 0 -0 0</pose>
        <scale>1 1 1</scale>
        <link name='link'>
          <pose>577.557 78.8155 3.08352 0 -0 0</pose>
          <velocity>0 0 0 0 -0 0</velocity>
          <acceleration>0 0 0 0 -0 0</acceleration>
          <wrench>0 0 0 0 -0 0</wrench>
        </link>
      </model>
      <model name='piramid_qr_added'>
        <pose>570.474 -47.2439 1 0 -0 0</pose>
        <scale>1 1 1</scale>
        <link name='link'>
          <pose>570.474 -47.2439 1 0 -0 0</pose>
          <velocity>0 0 0 0 -0 0</velocity>
          <acceleration>0 0 0 0 -0 0</acceleration>
          <wrench>0 0 0 0 -0 0</wrench>
        </link>
      </model>
      <model name='piramid_qr_cutted'>
        <pose>575.303 76.5247 1 0 -0 0</pose>
        <scale>1 1 1</scale>
        <link name='link'>
          <pose>575.303 76.5247 1 0 -0 0</pose>
          <velocity>0 0 0 0 -0 0</velocity>
          <acceleration>0 0 0 0 -0 0</acceleration>
          <wrench>0 0 0 0 -0 0</wrench>
        </link>
      </model>
      <model name='square_qr'>
        <pose>514.1 223.068 1 0 -0 0</pose>
        <scale>1 1 1</scale>
        <link name='link'>
          <pose>514.1 223.068 1 0 -0 0</pose>
          <velocity>0 0 0 0 -0 0</velocity>
          <acceleration>0 0 0 0 -0 0</acceleration>
          <wrench>0 0 0 0 -0 0</wrench>
        </link>
      </model>
      <model name='teknofest_h'>
        <pose>625.378 141.545 2.92254 -1.5708 0 0</pose>
        <scale>1 1 1</scale>
        <link name='link'>
          <pose>625.378 141.545 2.92254 -1.5708 0 0</pose>
          <velocity>0 0 0 0 -0 0</velocity>
          <acceleration>0 0 0 0 -0 0</acceleration>
          <wrench>0 0 0 0 -0 0</wrench>
        </link>
      </model>
      <model name='teknofest_h_0'>
        <pose>627.28 139.476 2.56519 3.14159 1.57079 3.14159</pose>
        <scale>1 1 1</scale>
        <link name='link'>
          <pose>627.28 139.476 2.56519 3.14159 1.57079 3.14159</pose>
          <velocity>0 0 0 0 -0 0</velocity>
          <acceleration>0 0 0 0 -0 0</acceleration>
          <wrench>0 0 0 0 -0 0</wrench>
        </link>
      </model>
      <model name='teknofest_h_1'>
        <pose>625.155 137.249 3.25488 1.5708 -0 0</pose>
        <scale>1 1 1</scale>
        <link name='link'>
          <pose>625.155 137.249 3.25488 1.5708 -0 0</pose>
          <velocity>0 0 0 0 -0 0</velocity>
          <acceleration>0 0 0 0 -0 0</acceleration>
          <wrench>0 0 0 0 -0 0</wrench>
        </link>
      </model>
      <model name='teknofest_h_2'>
        <pose>622.971 140.039 3.19742 3.14159 -1.57079 3.14159</pose>
        <scale>1 1 1</scale>
        <link name='link'>
          <pose>622.971 140.039 3.19742 3.14159 -1.57079 3.14159</pose>
          <velocity>0 0 0 0 -0 0</velocity>
          <acceleration>0 0 0 0 -0 0</acceleration>
          <wrench>0 0 0 0 -0 0</wrench>
        </link>
      </model>
      <model name='teknofest_h_3'>
        <pose>625.371 139.72 5.2565 0 -0 0</pose>
        <scale>1 1 1</scale>
        <link name='link'>
          <pose>625.371 139.72 5.2565 0 -0 0</pose>
          <velocity>0 0 0 0 -0 0</velocity>
          <acceleration>0 0 0 0 -0 0</acceleration>
          <wrench>0 0 0 0 -0 0</wrench>
        </link>
      </model>
      <model name='testucusu_m'>
        <pose>515.375 224.607 1.09305 0 -0 0</pose>
        <scale>1 1 1</scale>
        <link name='link'>
          <pose>515.375 224.607 1.09305 0 -0 0</pose>
          <velocity>0 0 0 0 -0 0</velocity>
          <acceleration>0 0 0 0 -0 0</acceleration>
          <wrench>0 0 0 0 -0 0</wrench>
        </link>
      </model>
      <model name='zephyr_with_camera'>
        <pose>140.522 117.02 12.7274 0.074497 -0.040213 -0.057996</pose>
        <scale>1 1 1</scale>
        <link name='ZED_stereocamera::link'>
          <pose>140.491 116.661 12.9811 0.040305 0.074447 -1.6258</pose>
          <velocity>-9e-06 -3e-05 9.9e-05 -4.3e-05 -1.6e-05 -8e-06</velocity>
          <acceleration>0.000402 0.001465 0.002514 -0.000506 -0.007624 -0.000895</acceleration>
          <wrench>6.4e-05 0.000233 0.0004 0 -0 0</wrench>
        </link>
        <link name='cam_link'>
          <pose>140.522 117.02 12.7274 0.074496 -0.040213 -0.057996</pose>
          <velocity>-7e-06 -4.1e-05 9.6e-05 -4.9e-05 -7e-06 -8e-06</velocity>
          <acceleration>-0.000143 0.000724 0.001409 -0.00303 0.000798 -0.00034</acceleration>
          <wrench>-1e-06 7e-06 1.4e-05 0 -0 0</wrench>
        </link>
        <link name='skid_pad'>
          <pose>140.52 116.952 12.7023 0.074483 -0.040155 -0.05799</pose>
          <velocity>-7e-06 -3.9e-05 0.000105 -7e-05 8e-06 -9e-06</velocity>
          <acceleration>-7.3e-05 -2.6e-05 0.001582 -0.002858 -0.000179 -0.000202</acceleration>
          <wrench>-7e-06 -3e-06 0.000158 0 -0 0</wrench>
        </link>
        <link name='zephyr_delta_wing::flap_left'>
          <pose>140.98 117.213 12.9505 -0.427687 -0.200371 -0.029239</pose>
          <velocity>-4.3e-05 5.6e-05 0.000283 0.005433 0.001455 0.000341</velocity>
          <acceleration>0.003751 -0.007854 -0.018835 -0.691249 -0.149746 -0.076611</acceleration>
          <wrench>0.000375 -0.000785 -0.001883 0 -0 0</wrench>
        </link>
        <link name='zephyr_delta_wing::flap_right'>
          <pose>140.074 117.266 12.9139 -0.425305 0.119961 -0.086373</pose>
          <velocity>-6e-06 -2.9e-05 8.1e-05 -4.8e-05 -7e-06 -8e-06</velocity>
          <acceleration>9.2e-05 0.001411 0.001009 -0.002794 0.000897 -0.00039</acceleration>
          <wrench>9e-06 0.000141 0.000101 0 -0 0</wrench>
        </link>
        <link name='zephyr_delta_wing::propeller'>
          <pose>140.517 117.074 12.9399 1.51401 1.49624 1.45886</pose>
          <velocity>-8e-06 -3.1e-05 9.4e-05 -4.8e-05 -8e-06 -8e-06</velocity>
          <acceleration>4.8e-05 0.001336 0.001222 -0.353317 0.019596 -0.001486</acceleration>
          <wrench>2e-06 6.7e-05 6.1e-05 0 -0 0</wrench>
        </link>
        <link name='zephyr_delta_wing::wing'>
          <pose>140.514 117.005 12.9267 0.074497 -0.040213 -0.057996</pose>
          <velocity>-8e-06 -3.2e-05 9.7e-05 -4.8e-05 -7e-06 -8e-06</velocity>
          <acceleration>-3.4e-05 0.001273 0.001801 -0.003252 0.000945 -0.000441</acceleration>
          <wrench>-5.1e-05 0.00191 0.002702 0 -0 0</wrench>
        </link>
        <link name='zephyr_delta_wing::zephyr/imu_link'>
          <pose>140.514 117.005 12.9267 0.074497 -0.040213 -0.057996</pose>
          <velocity>-8e-06 -3.2e-05 9.7e-05 -4.8e-05 -7e-06 -8e-06</velocity>
          <acceleration>1.4e-05 0.001298 0.001434 -0.003083 0.000891 -0.000394</acceleration>
          <wrench>2e-06 0.000195 0.000215 0 -0 0</wrench>
        </link>
      </model>
      <light name='sun'>
        <pose>71.4111 102.829 10 0 -0 0</pose>
      </light>
    </state>
    <model name='heightmap'>
      <static>1</static>
      <link name='link'>
        <collision name='collision_mcmillan'>
          <geometry>
            <heightmap>
              <uri>model://mcmillan_airfield/media/mcmillan_elevation.tif</uri>
              <pos>500 500 -300</pos>
              <texture>
                <size>10</size>
                <diffuse>__default__</diffuse>
                <normal>__default__</normal>
              </texture>
              <blend>
                <min_height>0</min_height>
                <fade_dist>0</fade_dist>
              </blend>
            </heightmap>
          </geometry>
          <max_contacts>10</max_contacts>
          <surface>
            <contact>
              <ode/>
            </contact>
            <bounce/>
            <friction>
              <torsional>
                <ode/>
              </torsional>
              <ode/>
            </friction>
          </surface>
        </collision>
        <visual name='visual_mcmillan'>
          <geometry>
            <heightmap>
              <texture>
                <diffuse>model://mcmillan_airfield/media/textures/mcmillan_color.png</diffuse>
                <normal>file://media/materials/textures/flat_normal.png</normal>
                <size>5700</size>
              </texture>
              <uri>model://mcmillan_airfield/media/mcmillan_elevation.tif</uri>
              <pos>500 500 -300</pos>
              <blend>
                <min_height>0</min_height>
                <fade_dist>0</fade_dist>
              </blend>
            </heightmap>
          </geometry>
        </visual>
        <self_collide>0</self_collide>
        <enable_wind>0</enable_wind>
        <kinematic>0</kinematic>
      </link>
      <pose>3.4355 1.4445 0 0 -0 0</pose>
    </model>
    <model name='square_qr'>
      <pose>514.1 223.068 1 0 -0 0</pose>
      <static>1</static>
      <link name='link'>
        <visual name='visual'>
          <geometry>
            <mesh>
              <uri>model://square_qr/meshes/square_qr.dae</uri>
            </mesh>
          </geometry>
          <material>
            <script>
              <name>Gazebo/White</name>
              <uri>__default__</uri>
            </script>
          </material>
        </visual>
        <self_collide>0</self_collide>
        <enable_wind>0</enable_wind>
        <kinematic>0</kinematic>
      </link>
    </model>
    <model name='cube_qr_added'>
      <pose>622.998 137.263 1 0 -0 0</pose>
      <static>1</static>
      <link name='link'>
        <visual name='visual'>
          <geometry>
            <mesh>
              <scale>2 2 2</scale>
              <uri>model://cube_qr_added/meshes/cube_qr_added.dae</uri>
            </mesh>
          </geometry>
          <material>
            <script>
              <name>Gazebo/White</name>
              <uri>__default__</uri>
            </script>
          </material>
        </visual>
        <self_collide>0</self_collide>
        <enable_wind>0</enable_wind>
        <kinematic>0</kinematic>
      </link>
    </model>
    <model name='piramid_qr_cutted'>
      <pose>575.303 76.5247 1 0 -0 0</pose>
      <static>1</static>
      <link name='link'>
        <visual name='visual'>
          <geometry>
            <mesh>
              <scale>3 3 3</scale>
              <uri>model://piramid_qr_cutted/meshes/piramid_qr_cutted.dae</uri>
            </mesh>
          </geometry>
          <material>
            <script>
              <name>Gazebo/White</name>
              <uri>__default__</uri>
            </script>
          </material>
        </visual>
        <self_collide>0</self_collide>
        <enable_wind>0</enable_wind>
        <kinematic>0</kinematic>
      </link>
    </model>
    <model name='piramid_qr_added'>
      <pose>570.474 -47.2439 1 0 -0 0</pose>
      <static>1</static>
      <link name='link'>
        <visual name='visual'>
          <geometry>
            <mesh>
              <scale>5 5 5</scale>
              <uri>model://piramid_qr_added/meshes/piramid_qr_added.dae</uri>
            </mesh>
          </geometry>
          <material>
            <script>
              <name>Gazebo/White</name>
              <uri>__default__</uri>
            </script>
          </material>
        </visual>
        <self_collide>0</self_collide>
        <enable_wind>0</enable_wind>
        <kinematic>0</kinematic>
      </link>
    </model>
    <model name='testucusu_m'>
      <pose>515.375 224.607 1 0 -0 0</pose>
      <static>1</static>
      <link name='link'>
        <visual name='visual'>
          <geometry>
            <mesh>
              <scale>3 3 1e-06</scale>
              <uri>model://QR_06/meshes/testucusu_m.stl</uri>
            </mesh>
          </geometry>
          <material>
            <script>
              <name>Gazebo/Black</name>
              <uri>__default__</uri>
            </script>
          </material>
        </visual>
        <self_collide>0</self_collide>
        <enable_wind>0</enable_wind>
        <kinematic>0</kinematic>
      </link>
    </model>
    <model name='teknofest_h'>
      <pose>625.378 145.332 1 0 -0 0</pose>
      <static>1</static>
      <link name='link'>
        <visual name='visual'>
          <geometry>
            <mesh>
              <scale>3 3 1e-06</scale>
              <uri>model://QR_12/meshes/teknofest_h.stl</uri>
            </mesh>
          </geometry>
          <material>
            <script>
              <name>Gazebo/Black</name>
              <uri>__default__</uri>
            </script>
          </material>
        </visual>
        <self_collide>0</self_collide>
        <enable_wind>0</enable_wind>
        <kinematic>0</kinematic>
      </link>
    </model>
    <model name='teknofest_h_0'>
      <pose>634.61 140.12 1 0 -0 0</pose>
      <static>1</static>
      <link name='link'>
        <visual name='visual'>
          <geometry>
            <mesh>
              <scale>3 3 1e-06</scale>
              <uri>model://QR_12/meshes/teknofest_h.stl</uri>
            </mesh>
          </geometry>
          <material>
            <script>
              <name>Gazebo/Black</name>
              <uri>__default__</uri>
            </script>
          </material>
        </visual>
        <self_collide>0</self_collide>
        <enable_wind>0</enable_wind>
        <kinematic>0</kinematic>
      </link>
    </model>
    <model name='teknofest_h_1'>
      <pose>627.345 132.159 1 0 -0 0</pose>
      <static>1</static>
      <link name='link'>
        <visual name='visual'>
          <geometry>
            <mesh>
              <scale>3 3 1e-06</scale>
              <uri>model://QR_12/meshes/teknofest_h.stl</uri>
            </mesh>
          </geometry>
          <material>
            <script>
              <name>Gazebo/Black</name>
              <uri>__default__</uri>
            </script>
          </material>
        </visual>
        <self_collide>0</self_collide>
        <enable_wind>0</enable_wind>
        <kinematic>0</kinematic>
      </link>
    </model>
    <model name='teknofest_h_2'>
      <pose>619.434 140.039 1 0 -0 0</pose>
      <static>1</static>
      <link name='link'>
        <visual name='visual'>
          <geometry>
            <mesh>
              <scale>3 3 1e-06</scale>
              <uri>model://QR_12/meshes/teknofest_h.stl</uri>
            </mesh>
          </geometry>
          <material>
            <script>
              <name>Gazebo/Black</name>
              <uri>__default__</uri>
            </script>
          </material>
        </visual>
        <self_collide>0</self_collide>
        <enable_wind>0</enable_wind>
        <kinematic>0</kinematic>
      </link>
    </model>
    <model name='teknofest_h_3'>
      <pose>618.989 132.825 1 0 -0 0</pose>
      <static>1</static>
      <link name='link'>
        <visual name='visual'>
          <geometry>
            <mesh>
              <scale>3 3 1e-06</scale>
              <uri>model://QR_12/meshes/teknofest_h.stl</uri>
            </mesh>
          </geometry>
          <material>
            <script>
              <name>Gazebo/Black</name>
              <uri>__default__</uri>
            </script>
          </material>
        </visual>
        <self_collide>0</self_collide>
        <enable_wind>0</enable_wind>
        <kinematic>0</kinematic>
      </link>
    </model>
    <model name='mustafakemalataturk_m'>
      <pose>578.264 73.8867 1 0 -0 0</pose>
      <static>1</static>
      <link name='link'>
        <visual name='visual'>
          <geometry>
            <mesh>
              <scale>3 3 1e-06</scale>
              <uri>model://QR_14/meshes/mustafakemalataturk_m.stl</uri>
            </mesh>
          </geometry>
          <material>
            <script>
              <name>Gazebo/Black</name>
              <uri>__default__</uri>
            </script>
          </material>
        </visual>
        <self_collide>0</self_collide>
        <enable_wind>0</enable_wind>
        <kinematic>0</kinematic>
      </link>
    </model>
    <model name='mustafakemalataturk_m_0'>
      <pose>577.789 84.9396 1 0 -0 0</pose>
      <static>1</static>
      <link name='link'>
        <visual name='visual'>
          <geometry>
            <mesh>
              <scale>3 3 1e-06</scale>
              <uri>model://QR_14/meshes/mustafakemalataturk_m.stl</uri>
            </mesh>
          </geometry>
          <material>
            <script>
              <name>Gazebo/Black</name>
              <uri>__default__</uri>
            </script>
          </material>
        </visual>
        <self_collide>0</self_collide>
        <enable_wind>0</enable_wind>
        <kinematic>0</kinematic>
      </link>
    </model>
    <model name='mustafakemalataturk_m_1'>
      <pose>583.18 78.7299 1 0 -0 0</pose>
      <static>1</static>
      <link name='link'>
        <visual name='visual'>
          <geometry>
            <mesh>
              <scale>3 3 1e-06</scale>
              <uri>model://QR_14/meshes/mustafakemalataturk_m.stl</uri>
            </mesh>
          </geometry>
          <material>
            <script>
              <name>Gazebo/Black</name>
              <uri>__default__</uri>
            </script>
          </material>
        </visual>
        <self_collide>0</self_collide>
        <enable_wind>0</enable_wind>
        <kinematic>0</kinematic>
      </link>
    </model>
    <model name='mustafakemalataturk_m_2'>
      <pose>571.354 77.6674 1 0 -0 0</pose>
      <static>1</static>
      <link name='link'>
        <visual name='visual'>
          <geometry>
            <mesh>
              <scale>3 3 1e-06</scale>
              <uri>model://QR_14/meshes/mustafakemalataturk_m.stl</uri>
            </mesh>
          </geometry>
          <material>
            <script>
              <name>Gazebo/Black</name>
              <uri>__default__</uri>
            </script>
          </material>
        </visual>
        <self_collide>0</self_collide>
        <enable_wind>0</enable_wind>
        <kinematic>0</kinematic>
      </link>
    </model>
    <model name='mustafakemalataturk_m_3'>
      <pose>572.377 81.8753 1 0 -0 0</pose>
      <static>1</static>
      <link name='link'>
        <visual name='visual'>
          <geometry>
            <mesh>
              <scale>3 3 1e-06</scale>
              <uri>model://QR_14/meshes/mustafakemalataturk_m.stl</uri>
            </mesh>
          </geometry>
          <material>
            <script>
              <name>Gazebo/Black</name>
              <uri>__default__</uri>
            </script>
          </material>
        </visual>
        <self_collide>0</self_collide>
        <enable_wind>0</enable_wind>
        <kinematic>0</kinematic>
      </link>
    </model>
    <model name='istikbalgoklerdedir_q'>
      <pose>573.281 -44.5002 1 0 -0 0</pose>
      <static>1</static>
      <link name='link'>
        <visual name='visual'>
          <geometry>
            <mesh>
              <scale>3 3 1e-06</scale>
              <uri>model://QR_17/meshes/istikbalgoklerdedir_q.stl</uri>
            </mesh>
          </geometry>
          <material>
            <script>
              <name>Gazebo/Black</name>
              <uri>__default__</uri>
            </script>
          </material>
        </visual>
        <self_collide>0</self_collide>
        <enable_wind>0</enable_wind>
        <kinematic>0</kinematic>
      </link>
    </model>
    <model name='istikbalgoklerdedir_q_0'>
      <pose>568.007 -48.9312 1 0 -0 0</pose>
      <static>1</static>
      <link name='link'>
        <visual name='visual'>
          <geometry>
            <mesh>
              <scale>3 3 1e-06</scale>
              <uri>model://QR_17/meshes/istikbalgoklerdedir_q.stl</uri>
            </mesh>
          </geometry>
          <material>
            <script>
              <name>Gazebo/Black</name>
              <uri>__default__</uri>
            </script>
          </material>
        </visual>
        <self_collide>0</self_collide>
        <enable_wind>0</enable_wind>
        <kinematic>0</kinematic>
      </link>
    </model>
    <model name='istikbalgoklerdedir_q_1'>
      <pose>573.406 -56.6808 1 0 -0 0</pose>
      <static>1</static>
      <link name='link'>
        <visual name='visual'>
          <geometry>
            <mesh>
              <scale>3 3 1e-06</scale>
              <uri>model://QR_17/meshes/istikbalgoklerdedir_q.stl</uri>
            </mesh>
          </geometry>
          <material>
            <script>
              <name>Gazebo/Black</name>
              <uri>__default__</uri>
            </script>
          </material>
        </visual>
        <self_collide>0</self_collide>
        <enable_wind>0</enable_wind>
        <kinematic>0</kinematic>
      </link>
    </model>
    <model name='istikbalgoklerdedir_q_2'>
      <pose>580.174 -49.8626 1 0 -0 0</pose>
      <static>1</static>
      <link name='link'>
        <visual name='visual'>
          <geometry>
            <mesh>
              <scale>3 3 1e-06</scale>
              <uri>model://QR_17/meshes/istikbalgoklerdedir_q.stl</uri>
            </mesh>
          </geometry>
          <material>
            <script>
              <name>Gazebo/Black</name>
              <uri>__default__</uri>
            </script>
          </material>
        </visual>
        <self_collide>0</self_collide>
        <enable_wind>0</enable_wind>
        <kinematic>0</kinematic>
      </link>
    </model>
    <light name='sun' type='directional'>
      <cast_shadows>1</cast_shadows>
      <pose>71.4111 102.829 10 0 -0 0</pose>
      <diffuse>0.8 0.8 0.8 1</diffuse>
      <specular>0.2 0.2 0.2 1</specular>
      <attenuation>
        <range>1000</range>
        <constant>0.9</constant>
        <linear>0.01</linear>
        <quadratic>0.001</quadratic>
      </attenuation>
      <direction>-0.5 0.1 -0.9</direction>
      <spot>
        <inner_angle>0</inner_angle>
        <outer_angle>0</outer_angle>
        <falloff>0</falloff>
      </spot>
    </light>
    <model name='zephyr_with_camera'>
      <pose>161.098 103.519 0 0 -0 0</pose>
      <frame name='zephyr_delta_wing::__model__' attached_to='zephyr_delta_wing::wing'>
        <pose relative_to='__model__'>0 0 0.2 0 -0 0</pose>
      </frame>
      <link name='zephyr_delta_wing::wing'>
        <inertial>
          <pose>0 -0.12 0 0 -0 0</pose>
          <mass>1.5</mass>
          <inertia>
            <ixx>0.0831371</ixx>
            <ixy>0</ixy>
            <iyy>0.387382</iyy>
            <ixz>0</ixz>
            <iyz>0</iyz>
            <izz>0.469845</izz>
          </inertia>
        </inertial>
        <visual name='visual'>
          <geometry>
            <mesh>
              <uri>model://zephyr_delta_wing/meshes/wing.dae</uri>
              <submesh>
                <name>Wing</name>
                <center>1</center>
              </submesh>
            </mesh>
          </geometry>
        </visual>
        <collision name='body_collision'>
          <geometry>
            <mesh>
              <uri>model://zephyr_delta_wing/meshes/wing.dae</uri>
              <submesh>
                <name>Wing</name>
                <center>1</center>
              </submesh>
            </mesh>
          </geometry>
          <max_contacts>10</max_contacts>
          <surface>
            <contact>
              <ode/>
            </contact>
            <bounce/>
            <friction>
              <torsional>
                <ode/>
              </torsional>
              <ode/>
            </friction>
          </surface>
        </collision>
        <collision name='right_rudder_collision'>
          <pose>-0.76435 0.33918 0.002 -0.03 0 0</pose>
          <geometry>
            <box>
              <size>0.005 0.12993 0.12688</size>
            </box>
          </geometry>
          <max_contacts>10</max_contacts>
          <surface>
            <contact>
              <ode/>
            </contact>
            <bounce/>
            <friction>
              <torsional>
                <ode/>
              </torsional>
              <ode/>
            </friction>
          </surface>
        </collision>
        <collision name='left_rudder_collision'>
          <pose>0.76435 0.33918 0.002 -0.03 0 0</pose>
          <geometry>
            <box>
              <size>0.005 0.12993 0.12688</size>
            </box>
          </geometry>
          <max_contacts>10</max_contacts>
          <surface>
            <contact>
              <ode/>
            </contact>
            <bounce/>
            <friction>
              <torsional>
                <ode/>
              </torsional>
              <ode/>
            </friction>
          </surface>
        </collision>
        <pose relative_to='zephyr_delta_wing::__model__'>0 0 0 0 -0 0</pose>
        <self_collide>0</self_collide>
        <enable_wind>0</enable_wind>
        <kinematic>0</kinematic>
      </link>
      <link name='zephyr_delta_wing::zephyr/imu_link'>
        <inertial>
          <pose>0 0 0 0 -0 0</pose>
          <mass>0.15</mass>
          <inertia>
            <ixx>1e-05</ixx>
            <ixy>0</ixy>
            <ixz>0</ixz>
            <iyy>2e-05</iyy>
            <iyz>0</iyz>
            <izz>2e-05</izz>
          </inertia>
        </inertial>
        <sensor name='imu_sensor' type='imu'>
          <pose>0 0 0 -3.14159 -0 -1.57079</pose>
          <always_on>1</always_on>
          <update_rate>1000</update_rate>
          <imu/>
        </sensor>
        <pose relative_to='zephyr_delta_wing::__model__'>0 0 0 0 -0 0</pose>
        <self_collide>0</self_collide>
        <enable_wind>0</enable_wind>
        <kinematic>0</kinematic>
      </link>
      <joint name='zephyr_delta_wing::zephyr/imu_joint' type='revolute'>
        <child>zephyr_delta_wing::zephyr/imu_link</child>
        <parent>zephyr_delta_wing::wing</parent>
        <axis>
          <xyz expressed_in='zephyr_delta_wing::__model__'>0 0 1</xyz>
          <limit>
            <lower>0</lower>
            <upper>0</upper>
            <effort>0</effort>
            <velocity>0</velocity>
          </limit>
          <dynamics>
            <damping>1</damping>
            <spring_reference>0</spring_reference>
            <spring_stiffness>0</spring_stiffness>
          </dynamics>
        </axis>
        <physics>
          <ode>
            <implicit_spring_damper>1</implicit_spring_damper>
            <limit>
              <cfm>0</cfm>
              <erp>0.2</erp>
            </limit>
          </ode>
        </physics>
      </joint>
      <link name='zephyr_delta_wing::propeller'>
        <pose relative_to='zephyr_delta_wing::__model__'>0 0.07 0.008 0 1.57079 0</pose>
        <inertial>
          <mass>0.05</mass>
          <inertia>
            <ixx>0.000367571</ixx>
            <ixy>0</ixy>
            <iyy>0.00036985</iyy>
            <ixz>0</ixz>
            <iyz>0</iyz>
            <izz>3.187e-06</izz>
          </inertia>
          <pose>0 0 0 0 -0 0</pose>
        </inertial>
        <visual name='visual'>
          <geometry>
            <mesh>
              <uri>model://zephyr_delta_wing/meshes/wing.dae</uri>
              <submesh>
                <name>Propeller</name>
                <center>1</center>
              </submesh>
            </mesh>
          </geometry>
        </visual>
        <collision name='blade1'>
          <pose>0 0 0.074205 0 -0 0.3</pose>
          <geometry>
            <box>
              <size>0.02561 0.00541 0.14841</size>
            </box>
          </geometry>
          <max_contacts>10</max_contacts>
          <surface>
            <contact>
              <ode/>
            </contact>
            <bounce/>
            <friction>
              <torsional>
                <ode/>
              </torsional>
              <ode/>
            </friction>
          </surface>
        </collision>
        <collision name='blade2'>
          <pose>0 0 -0.074205 0 0 -0.3</pose>
          <geometry>
            <box>
              <size>0.02561 0.00541 0.14841</size>
            </box>
          </geometry>
          <max_contacts>10</max_contacts>
          <surface>
            <contact>
              <ode/>
            </contact>
            <bounce/>
            <friction>
              <torsional>
                <ode/>
              </torsional>
              <ode/>
            </friction>
          </surface>
        </collision>
        <self_collide>0</self_collide>
        <enable_wind>0</enable_wind>
        <kinematic>0</kinematic>
      </link>
      <link name='zephyr_delta_wing::flap_left'>
        <pose relative_to='zephyr_delta_wing::__model__'>0.453 0.239 0.007 0 -0 0</pose>
        <inertial>
          <pose>0 0 0 0 -0 0.324457</pose>
          <mass>0.1</mass>
          <inertia>
            <ixx>0.000102319</ixx>
            <ixy>0</ixy>
            <iyy>0.00334417</iyy>
            <ixz>0</ixz>
            <iyz>0</iyz>
            <izz>0.00344607</izz>
          </inertia>
        </inertial>
        <visual name='visual'>
          <geometry>
            <mesh>
              <uri>model://zephyr_delta_wing/meshes/wing.dae</uri>
              <submesh>
                <name>Flap_Left</name>
                <center>1</center>
              </submesh>
            </mesh>
          </geometry>
        </visual>
        <collision name='collision'>
          <pose>-0.01 0.01 0 0 -0 0.324457</pose>
          <geometry>
            <box>
              <size>0.633463 0.110694 0.005</size>
            </box>
          </geometry>
          <max_contacts>10</max_contacts>
          <surface>
            <contact>
              <ode/>
            </contact>
            <bounce/>
            <friction>
              <torsional>
                <ode/>
              </torsional>
              <ode/>
            </friction>
          </surface>
        </collision>
        <self_collide>0</self_collide>
        <enable_wind>0</enable_wind>
        <kinematic>0</kinematic>
      </link>
      <link name='zephyr_delta_wing::flap_right'>
        <pose relative_to='zephyr_delta_wing::__model__'>-0.453 0.239 0.007 0 -0 0</pose>
        <inertial>
          <pose>0 0 0 0 0 -0.324457</pose>
          <mass>0.1</mass>
          <inertia>
            <ixx>0.000102319</ixx>
            <ixy>0</ixy>
            <iyy>0.00334417</iyy>
            <ixz>0</ixz>
            <iyz>0</iyz>
            <izz>0.00344607</izz>
          </inertia>
        </inertial>
        <visual name='visual'>
          <geometry>
            <mesh>
              <uri>model://zephyr_delta_wing/meshes/wing.dae</uri>
              <submesh>
                <name>Flap_Right</name>
                <center>1</center>
              </submesh>
            </mesh>
          </geometry>
        </visual>
        <collision name='collision'>
          <pose>0.01 0.01 0 0 0 -0.324457</pose>
          <geometry>
            <box>
              <size>0.633463 0.110694 0.005</size>
            </box>
          </geometry>
          <max_contacts>10</max_contacts>
          <surface>
            <contact>
              <ode/>
            </contact>
            <bounce/>
            <friction>
              <torsional>
                <ode/>
              </torsional>
              <ode/>
            </friction>
          </surface>
        </collision>
        <self_collide>0</self_collide>
        <enable_wind>0</enable_wind>
        <kinematic>0</kinematic>
      </link>
      <joint name='zephyr_delta_wing::propeller_joint' type='revolute'>
        <parent>zephyr_delta_wing::wing</parent>
        <child>zephyr_delta_wing::propeller</child>
        <axis>
          <xyz>0 -1 0</xyz>
          <dynamics>
            <damping>0.002</damping>
            <spring_reference>0</spring_reference>
            <spring_stiffness>0</spring_stiffness>
          </dynamics>
          <limit>
            <lower>-1e+16</lower>
            <upper>1e+16</upper>
          </limit>
        </axis>
        <physics>
          <ode>
            <implicit_spring_damper>1</implicit_spring_damper>
            <limit>
              <cfm>0</cfm>
              <erp>0.2</erp>
            </limit>
          </ode>
        </physics>
      </joint>
      <joint name='zephyr_delta_wing::flap_left_joint' type='revolute'>
        <parent>zephyr_delta_wing::wing</parent>
        <child>zephyr_delta_wing::flap_left</child>
        <pose>0 -0.04 0 0 -0 0</pose>
        <axis>
          <xyz>1 0.330321 0</xyz>
          <limit>
            <lower>-0.524</lower>
            <upper>0.524</upper>
          </limit>
          <dynamics>
            <damping>0.1</damping>
            <spring_reference>0</spring_reference>
            <spring_stiffness>0</spring_stiffness>
          </dynamics>
        </axis>
        <physics>
          <ode>
            <implicit_spring_damper>1</implicit_spring_damper>
            <limit>
              <cfm>0</cfm>
              <erp>0.2</erp>
            </limit>
          </ode>
        </physics>
      </joint>
      <joint name='zephyr_delta_wing::flap_right_joint' type='revolute'>
        <parent>zephyr_delta_wing::wing</parent>
        <child>zephyr_delta_wing::flap_right</child>
        <pose>0 -0.04 0 0 -0 0</pose>
        <axis>
          <xyz>1 -0.330321 0</xyz>
          <limit>
            <lower>-0.524</lower>
            <upper>0.524</upper>
          </limit>
          <dynamics>
            <damping>0.1</damping>
            <spring_reference>0</spring_reference>
            <spring_stiffness>0</spring_stiffness>
          </dynamics>
        </axis>
        <physics>
          <ode>
            <implicit_spring_damper>1</implicit_spring_damper>
            <limit>
              <cfm>0</cfm>
              <erp>0.2</erp>
            </limit>
          </ode>
        </physics>
      </joint>
      <plugin name='invisible_canard' filename='libLiftDragPlugin.so'>
        <a0>0.13</a0>
        <cla>3.7</cla>
        <cda>0.06417112299</cda>
        <cma>-1.8</cma>
        <alpha_stall>0.3391428111</alpha_stall>
        <cla_stall>-3.85</cla_stall>
        <cda_stall>-0.9233984055</cda_stall>
        <cma_stall>0</cma_stall>
        <cp>0 -0.1 0</cp>
        <area>0.50</area>
        <air_density>1.2041</air_density>
        <forward>0 -1 0</forward>
        <upward>0 0 1</upward>
        <link_name>zephyr_delta_wing::wing</link_name>
      </plugin>
      <plugin name='left_wing' filename='libLiftDragPlugin.so'>
        <a0>0.15</a0>
        <cla>6.8</cla>
        <cda>0.06417112299</cda>
        <cma>-1.8</cma>
        <alpha_stall>0.6391428111</alpha_stall>
        <cla_stall>-3.85</cla_stall>
        <cda_stall>-0.9233984055</cda_stall>
        <cma_stall>0</cma_stall>
        <cp>0.7 0.20 0</cp>
        <area>0.10</area>
        <air_density>1.2041</air_density>
        <forward>0 -1 0</forward>
        <upward>0 0 1</upward>
        <link_name>zephyr_delta_wing::wing</link_name>
        <control_joint_name>zephyr_delta_wing::flap_left_joint</control_joint_name>
        <control_joint_rad_to_cl>-5.0</control_joint_rad_to_cl>
      </plugin>
      <plugin name='right_wing' filename='libLiftDragPlugin.so'>
        <a0>0.15</a0>
        <cla>6.8</cla>
        <cda>0.06417112299</cda>
        <cma>-1.8</cma>
        <alpha_stall>0.6391428111</alpha_stall>
        <cla_stall>-3.85</cla_stall>
        <cda_stall>-0.9233984055</cda_stall>
        <cma_stall>0</cma_stall>
        <cp>-0.7 0.20 0</cp>
        <area>0.10</area>
        <air_density>1.2041</air_density>
        <forward>0 -1 0</forward>
        <upward>0 0 1</upward>
        <link_name>zephyr_delta_wing::wing</link_name>
        <control_joint_name>zephyr_delta_wing::flap_right_joint</control_joint_name>
        <control_joint_rad_to_cl>-5.0</control_joint_rad_to_cl>
      </plugin>
      <plugin name='left_rudder' filename='libLiftDragPlugin.so'>
        <a0>0.0</a0>
        <cla>4.752798721</cla>
        <cda>0.6417112299</cda>
        <cma>-1.8</cma>
        <alpha_stall>0.3391428111</alpha_stall>
        <cla_stall>-3.85</cla_stall>
        <cda_stall>-0.9233984055</cda_stall>
        <cma_stall>0</cma_stall>
        <cp>-0.76 0.30 0.025</cp>
        <area>0.12</area>
        <air_density>1.2041</air_density>
        <forward>0 -1 0</forward>
        <upward>1 0 0</upward>
        <link_name>zephyr_delta_wing::wing</link_name>
      </plugin>
      <plugin name='right_rudder' filename='libLiftDragPlugin.so'>
        <a0>0.0</a0>
        <cla>4.752798721</cla>
        <cda>0.6417112299</cda>
        <cma>-1.8</cma>
        <alpha_stall>0.3391428111</alpha_stall>
        <cla_stall>-3.85</cla_stall>
        <cda_stall>-0.9233984055</cda_stall>
        <cma_stall>0</cma_stall>
        <cp>0.76 0.30 0.025</cp>
        <area>0.12</area>
        <air_density>1.2041</air_density>
        <forward>0 -1 0</forward>
        <upward>1 0 0</upward>
        <link_name>zephyr_delta_wing::wing</link_name>
      </plugin>
      <plugin name='propeller_blade_1' filename='libLiftDragPlugin.so'>
        <a0>0.30</a0>
        <alpha_stall>1.4</alpha_stall>
        <cla>4.2500</cla>
        <cda>0.10</cda>
        <cma>0.00</cma>
        <cla_stall>-0.025</cla_stall>
        <cda_stall>0.0</cda_stall>
        <cma_stall>0.0</cma_stall>
        <area>0.02</area>
        <air_density>1.2041</air_density>
        <cp>0 0 0.074205</cp>
        <forward>-1 0 0</forward>
        <upward>0 -1 0</upward>
        <link_name>zephyr_delta_wing::propeller</link_name>
      </plugin>
      <plugin name='propeller_blade_2' filename='libLiftDragPlugin.so'>
        <a0>0.30</a0>
        <alpha_stall>1.4</alpha_stall>
        <cla>4.2500</cla>
        <cda>0.10</cda>
        <cma>0.00</cma>
        <cla_stall>-0.025</cla_stall>
        <cda_stall>0.0</cda_stall>
        <cma_stall>0.0</cma_stall>
        <area>0.02</area>
        <air_density>1.2041</air_density>
        <cp>0 0 -0.074205</cp>
        <forward>1 0 0</forward>
        <upward>0 -1 0</upward>
        <link_name>zephyr_delta_wing::propeller</link_name>
      </plugin>
      <frame name='ZED_stereocamera::__model__' attached_to='ZED_stereocamera::link'>
        <pose relative_to='__model__'>0 -0.34 0.28 0 -0 -1.5708</pose>
      </frame>
      <link name='ZED_stereocamera::link'>
        <pose relative_to='ZED_stereocamera::__model__'>0 0 0 0 -0 0</pose>
        <inertial>
          <mass>0.159</mass>
          <inertia>
            <ixx>1.2e-05</ixx>
            <iyy>0.000406</iyy>
            <izz>0.000418</izz>
            <ixy>0</ixy>
            <ixz>0</ixz>
            <iyz>0</iyz>
          </inertia>
          <pose>0 0 0 0 -0 0</pose>
        </inertial>
        <collision name='collision'>
          <geometry>
            <box>
              <size>0.1 0.1 0.1</size>
            </box>
          </geometry>
          <max_contacts>10</max_contacts>
          <surface>
            <contact>
              <ode/>
            </contact>
            <bounce/>
            <friction>
              <torsional>
                <ode/>
              </torsional>
              <ode/>
            </friction>
          </surface>
        </collision>
        <visual name='visual'>
          <geometry>
            <mesh>
              <uri>model://ZED_stereocamera/meshes/ZED.stl</uri>
            </mesh>
          </geometry>
          <material>
            <script>
              <name>Gazebo/Grey</name>
              <uri>__default__</uri>
            </script>
          </material>
        </visual>
        <visual name='visual_lens_left'>
          <pose>0 0 0 0 1.57 0</pose>
          <geometry>
            <cylinder>
              <radius>0.007</radius>
              <length>0.03</length>
            </cylinder>
          </geometry>
          <material>
            <script>
              <uri>file://media/materials/scripts/gazebo.material</uri>
              <name>Gazebo/WideLensMap</name>
            </script>
          </material>
        </visual>
        <sensor name='camera' type='camera'>
          <always_on>1</always_on>
          <update_rate>41</update_rate>
          <visualize>0</visualize>
          <plugin name='camera_controller' filename='libgazebo_ros_camera.so'>
            <always_on>1</always_on>
            <update_rate>41</update_rate>
            <cameraName>zephyr</cameraName>
            <imageTopicName>image_raw</imageTopicName>
            <cameraInfoTopicName>camera_info</cameraInfoTopicName>
            <frameName>camera_link</frameName>
          </plugin>
          <plugin name='GstCameraPlugin' filename='libgazebo_gst_camera_plugin.so'>
            <robotNamespace/>
            <udpHost>127.0.0.1</udpHost>
            <udpPort>9999</udpPort>
          </plugin>
          <camera name='left'>
            <pose>0 0 0 0 -0 0</pose>
            <horizontal_fov>1.91986</horizontal_fov>
            <image>
              <width>1280</width>
              <height>720</height>
            </image>
            <clip>
              <near>0.1</near>
              <far>5000</far>
            </clip>
          </camera>
        </sensor>
        <self_collide>0</self_collide>
        <enable_wind>0</enable_wind>
        <kinematic>0</kinematic>
      </link>
      <link name='cam_link'>
        <pose>0 0 0 0 -0 0</pose>
        <inertial>
          <mass>0.01</mass>
          <inertia>
            <ixx>0.0001</ixx>
            <iyy>0.0001</iyy>
            <izz>0.0001</izz>
            <ixy>0</ixy>
            <ixz>0</ixz>
            <iyz>0</iyz>
          </inertia>
          <pose>0 0 0 0 -0 0</pose>
        </inertial>
        <self_collide>0</self_collide>
        <enable_wind>0</enable_wind>
        <kinematic>0</kinematic>
      </link>
      <joint name='camera_mount' type='fixed'>
        <child>ZED_stereocamera::link</child>
        <parent>zephyr_delta_wing::wing</parent>
        <axis>
          <xyz>0 0 1</xyz>
          <limit>
            <upper>0</upper>
            <lower>0</lower>
          </limit>
        </axis>
      </joint>
      <joint name='virtual_camera_mount' type='fixed'>
        <child>cam_link</child>
        <parent>zephyr_delta_wing::wing</parent>
        <axis>
          <xyz>0 0 1</xyz>
          <limit>
            <upper>0</upper>
            <lower>0</lower>
          </limit>
        </axis>
      </joint>
      <link name='skid_pad'>
        <pose>0 -0.07 -0.02 0 -0 0</pose>
        <inertial>
          <mass>0.1</mass>
          <inertia>
            <ixx>0.00431371</ixx>
            <ixy>0</ixy>
            <iyy>0.00387382</iyy>
            <ixz>0</ixz>
            <iyz>0</iyz>
            <izz>0.00809845</izz>
          </inertia>
          <pose>0 0 0 0 -0 0</pose>
        </inertial>
        <collision name='skid_pad'>
          <pose>0 0 0 0 -0 0</pose>
          <geometry>
            <box>
              <size>1 0.5 0.05</size>
            </box>
          </geometry>
          <surface>
            <contact>
              <ode>
                <kp>100000</kp>
                <kd>1</kd>
                <min_depth>0.01</min_depth>
                <max_vel>1</max_vel>
              </ode>
            </contact>
            <friction>
              <ode>
                <mu>0.3</mu>
                <fdir1>0 1 0</fdir1>
              </ode>
              <torsional>
                <ode/>
              </torsional>
            </friction>
            <bounce/>
          </surface>
          <max_contacts>10</max_contacts>
        </collision>
        <self_collide>0</self_collide>
        <enable_wind>0</enable_wind>
        <kinematic>0</kinematic>
      </link>
      <joint name='skid_pad_joint' type='fixed'>
        <parent>zephyr_delta_wing::wing</parent>
        <child>skid_pad</child>
        <axis>
          <limit>
            <lower>0</lower>
            <upper>0</upper>
          </limit>
          <xyz expressed_in='__model__'>0 1 0</xyz>
        </axis>
      </joint>
      <plugin name='ardupilot_plugin' filename='libArduPilotPlugin.so'>
        <fdm_addr>127.0.0.1</fdm_addr>
        <fdm_port_in>9012</fdm_port_in>
        <fdm_port_out>9013</fdm_port_out>
        <modelXYZToAirplaneXForwardZDown>0 0 0 3.141593 0 0</modelXYZToAirplaneXForwardZDown>
        <gazeboXYZToNED>0 0 0 3.141593 0 0</gazeboXYZToNED>
        <imuName>zephyr_with_camera::zephyr_delta_wing::zephyr/imu_link::imu_sensor</imuName>
        <connectionTimeoutMaxCount>5</connectionTimeoutMaxCount>
        <control channel='2'>
          <multiplier>838</multiplier>
          <offset>0.2</offset>
          <type>VELOCITY</type>
          <p_gain>0.5</p_gain>
          <i_gain>0</i_gain>
          <d_gain>0</d_gain>
          <i_max>0</i_max>
          <i_min>0</i_min>
          <cmd_max>2.0</cmd_max>
          <cmd_min>0.0</cmd_min>
          <jointName>zephyr_delta_wing::propeller_joint</jointName>
        </control>
        <control channel='0'>
          <multiplier>-1</multiplier>
          <offset>-0.5</offset>
          <type>POSITION</type>
          <p_gain>10.0</p_gain>
          <i_gain>0</i_gain>
          <d_gain>0</d_gain>
          <i_max>0</i_max>
          <i_min>0</i_min>
          <cmd_max>2.0</cmd_max>
          <cmd_min>-2.0</cmd_min>
          <jointName>zephyr_delta_wing::flap_left_joint</jointName>
        </control>
        <control channel='1'>
          <multiplier>-1</multiplier>
          <offset>-0.5</offset>
          <type>POSITION</type>
          <p_gain>10.0</p_gain>
          <i_gain>0</i_gain>
          <d_gain>0</d_gain>
          <i_max>0</i_max>
          <i_min>0</i_min>
          <cmd_max>2.0</cmd_max>
          <cmd_min>-2.0</cmd_min>
          <jointName>zephyr_delta_wing::flap_right_joint</jointName>
        </control>
      </plugin>
      <sensor name='gps_sensor' type='gps'>
        <pose>0 0 0 0 0 0</pose>
        <update_rate>10.0</update_rate>
        <always_on>1</always_on>
        <gps>
          <position_sensing>
            <horizontal>
              <noise type='gaussian_quantized'>
                <mean>0</mean>
                <stddev>1</stddev>
                <bias_mean>3</bias_mean>
                <bias_stddev>1</bias_stddev>
                <precision>0.5</precision>
              </noise>
            </horizontal>
            <vertical>
              <noise type='gaussian_quantized'>
                <mean>0</mean>
                <stddev>1</stddev>
                <bias_mean>3</bias_mean>
                <bias_stddev>1</bias_stddev>
                <precision>1.0</precision>
              </noise>
            </vertical>
          </position_sensing>
          <velocity_sensing>
            <horizontal>
              <noise type='gaussian_quantized'>
                <mean>0</mean>
                <stddev>0.1</stddev>
                <bias_mean>0.1</bias_mean>
                <bias_stddev>0.1</bias_stddev>
                <precision>0.1</precision>
              </noise>
            </horizontal>
            <vertical>
              <noise type='gaussian_quantized'>
                <mean>0</mean>
                <stddev>0.2</stddev>
                <bias_mean>0.2</bias_mean>
                <bias_stddev>0.2</bias_stddev>
                <precision>0.2</precision>
              </noise>
            </vertical>
          </velocity_sensing>
        </gps>
      </sensor>
    </model>
    <model name='cessna_1'>
      <link name='cessna_1/base_link'>
        <inertial>
          <pose>-0.004 0 0.09271 0 -0 0</pose>
          <mass>4</mass>
          <inertia>
            <ixx>0.128531</ixx>
            <ixy>0</ixy>
            <ixz>0</ixz>
            <iyy>0.182593</iyy>
            <iyz>0</iyz>
            <izz>0.266689</izz>
          </inertia>
        </inertial>
        <self_collide>0</self_collide>
        <enable_wind>0</enable_wind>
        <kinematic>0</kinematic>
        <pose>0 0 0 0 -0 0</pose>
        <visual name='cessna_1/base_link_visual'>
          <pose>0 0 0 0 -0 0</pose>
          <geometry>
            <mesh>
              <scale>0.1 0.1 0.1</scale>
              <uri>model://cessna/meshes/body.dae</uri>
            </mesh>
          </geometry>
          <material>
            <script>
              <name>Gazebo</name>
              <uri>file://media/materials/scripts/gazebo.material</uri>
            </script>
            <shader type='pixel'/>
          </material>
          <transparency>0</transparency>
          <cast_shadows>0</cast_shadows>
        </visual>
        <collision name='cessna_1/base_link_collision'>
          <laser_retro>0</laser_retro>
          <max_contacts>10</max_contacts>
          <pose>0 0 0 0 -0 0</pose>
          <geometry>
            <box>
              <size>1 0.5 0.05</size>
            </box>
          </geometry>
          <surface>
            <friction>
              <ode>
                <mu>0.1</mu>
                <mu2>0.1</mu2>
                <fdir1>0 0 0</fdir1>
                <slip1>0</slip1>
                <slip2>0</slip2>
              </ode>
              <torsional>
                <coefficient>1</coefficient>
                <patch_radius>0</patch_radius>
                <surface_radius>0</surface_radius>
                <use_patch_radius>1</use_patch_radius>
                <ode>
                  <slip>0</slip>
                </ode>
              </torsional>
            </friction>
            <bounce>
              <restitution_coefficient>0</restitution_coefficient>
              <threshold>1e+06</threshold>
            </bounce>
            <contact>
              <collide_without_contact>0</collide_without_contact>
              <collide_without_contact_bitmask>1</collide_without_contact_bitmask>
              <collide_bitmask>1</collide_bitmask>
              <ode>
                <soft_cfm>0</soft_cfm>
                <soft_erp>0.2</soft_erp>
                <kp>1e+13</kp>
                <kd>1</kd>
                <max_vel>100</max_vel>
                <min_depth>0.001</min_depth>
              </ode>
              <bullet>
                <split_impulse>1</split_impulse>
                <split_impulse_penetration_threshold>-0.01</split_impulse_penetration_threshold>
                <soft_cfm>0</soft_cfm>
                <soft_erp>0.2</soft_erp>
                <kp>1e+13</kp>
                <kd>1</kd>
              </bullet>
            </contact>
          </surface>
        </collision>
      </link>
      <link name='cessna_1/elevators'>
        <pose>-0.555 -0 0.057 0 -0 0</pose>
        <inertial>
          <pose>0 0 0 0 -0 0</pose>
          <mass>0.0001</mass>
          <inertia>
            <ixx>0.0038166</ixx>
            <ixy>0</ixy>
            <ixz>0</ixz>
            <iyy>0.0036</iyy>
            <iyz>0</iyz>
            <izz>0.003816</izz>
          </inertia>
        </inertial>
        <self_collide>0</self_collide>
        <enable_wind>0</enable_wind>
        <kinematic>0</kinematic>
        <visual name='cessna_1/elevators_visual'>
          <pose>0.555 0 -0.057 0 -0 0</pose>
          <geometry>
            <mesh>
              <scale>0.1 0.1 0.1</scale>
              <uri>model://cessna/meshes/elevators.dae</uri>
            </mesh>
          </geometry>
          <material>
            <shader type='pixel'/>
          </material>
          <transparency>0</transparency>
          <cast_shadows>0</cast_shadows>
        </visual>
      </link>
      <link name='cessna_1/imu_link'>
        <pose>0 0 0 0 -0 0</pose>
        <inertial>
          <pose>0 0 0 0 -0 0</pose>
          <mass>0.15</mass>
          <inertia>
            <ixx>1e-05</ixx>
            <ixy>0</ixy>
            <ixz>0</ixz>
            <iyy>2e-05</iyy>
            <iyz>0</iyz>
            <izz>3e-05</izz>
          </inertia>
        </inertial>
        <sensor name='imu_sensor' type='imu'>
          <pose>0 0 0 -3.14159 -0 0</pose>
          <always_on>1</always_on>
          <update_rate>1000</update_rate>
          <imu/>
        </sensor>
        <self_collide>0</self_collide>
        <enable_wind>0</enable_wind>
        <kinematic>0</kinematic>
      </link>
      <link name='cessna_1/left_aileron'>
        <pose>-0.145 0.37 0.15 0.05 -0 -0.12</pose>
        <inertial>
          <pose>0 0 0 0 -0 0</pose>
          <mass>0.0001</mass>
          <inertia>
            <ixx>0.0038166</ixx>
            <ixy>0</ixy>
            <ixz>0</ixz>
            <iyy>0.0036</iyy>
            <iyz>0</iyz>
            <izz>0.003816</izz>
          </inertia>
        </inertial>
        <self_collide>0</self_collide>
        <enable_wind>0</enable_wind>
        <kinematic>0</kinematic>
        <visual name='cessna_1/left_aileron_visual'>
          <pose>0.195 -0.36 -0.12 -0.05 -0 0.12</pose>
          <geometry>
            <mesh>
              <scale>0.1 0.1 0.1</scale>
              <uri>model://cessna/meshes/left_aileron.dae</uri>
            </mesh>
          </geometry>
          <material>
            <shader type='pixel'/>
          </material>
          <transparency>0</transparency>
          <cast_shadows>0</cast_shadows>
        </visual>
      </link>
      <link name='cessna_1/propeller'>
        <pose>0.179 0 0.0855 0 -0 0</pose>
        <inertial>
          <pose>0 0 0 0 -0 0</pose>
          <mass>0.025</mass>
          <inertia>
            <ixx>7.5067e-05</ixx>
            <ixy>0</ixy>
            <ixz>0</ixz>
            <iyy>7.515e-05</iyy>
            <iyz>0</iyz>
            <izz>6.8275e-07</izz>
          </inertia>
        </inertial>
        <self_collide>0</self_collide>
        <enable_wind>0</enable_wind>
        <kinematic>0</kinematic>
        <visual name='cessna_1/propeller_visual'>
          <pose>0 0 0 0 -0 0</pose>
          <geometry>
            <mesh>
              <scale>0.1 0.1 0.1</scale>
              <uri>model://cessna/meshes/cessna_prop.dae</uri>
            </mesh>
          </geometry>
          <material>
            <script>
              <name>Gazebo/Blue</name>
              <uri>file://media/materials/scripts/gazebo.material</uri>
            </script>
            <shader type='pixel'/>
          </material>
          <transparency>0</transparency>
          <cast_shadows>0</cast_shadows>
        </visual>
      </link>
      <link name='cessna_1/right_aileron'>
        <pose>-0.145 -0.37 0.15 -0.05 -0 0.12</pose>
        <inertial>
          <pose>0 0 0 0 -0 0</pose>
          <mass>0.0001</mass>
          <inertia>
            <ixx>0.0038166</ixx>
            <ixy>0</ixy>
            <ixz>0</ixz>
            <iyy>0.0036</iyy>
            <iyz>0</iyz>
            <izz>0.003816</izz>
          </inertia>
        </inertial>
        <self_collide>0</self_collide>
        <enable_wind>0</enable_wind>
        <kinematic>0</kinematic>
        <visual name='cessna_1/right_aileron_visual'>
          <pose>0.195 0.36 -0.12 0.05 -0 -0.12</pose>
          <geometry>
            <mesh>
              <scale>0.1 0.1 0.1</scale>
              <uri>model://cessna/meshes/right_aileron.dae</uri>
            </mesh>
          </geometry>
          <material>
            <shader type='pixel'/>
          </material>
          <transparency>0</transparency>
          <cast_shadows>0</cast_shadows>
        </visual>
      </link>
      <link name='cessna_1/rudder'>
        <pose>-0.51 -0 0.325 0 -0.35 0</pose>
        <inertial>
          <pose>0 0 0 0 -0 0</pose>
          <mass>0.0001</mass>
          <inertia>
            <ixx>0.0038166</ixx>
            <ixy>0</ixy>
            <ixz>0</ixz>
            <iyy>0.0036</iyy>
            <iyz>0</iyz>
            <izz>0.003816</izz>
          </inertia>
        </inertial>
        <self_collide>0</self_collide>
        <enable_wind>0</enable_wind>
        <kinematic>0</kinematic>
        <visual name='cessna_1/rudder_visual'>
          <pose>0.36 0 -0.475 0 0.35 0</pose>
          <geometry>
            <mesh>
              <scale>0.1 0.1 0.1</scale>
              <uri>model://cessna/meshes/rudder.dae</uri>
            </mesh>
          </geometry>
          <material>
            <shader type='pixel'/>
          </material>
          <transparency>0</transparency>
          <cast_shadows>0</cast_shadows>
        </visual>
      </link>
      <joint name='cessna_1/elevators_joint' type='revolute'>
        <parent>cessna_1/base_link</parent>
        <child>cessna_1/elevators</child>
        <pose>0 0 0 0 -0 0</pose>
        <axis>
          <xyz>0 1 0</xyz>
          <limit>
            <lower>-0.78</lower>
            <upper>0.78</upper>
            <effort>-1</effort>
            <velocity>-1</velocity>
          </limit>
          <dynamics>
            <spring_reference>0</spring_reference>
            <spring_stiffness>0</spring_stiffness>
            <damping>0</damping>
            <friction>0</friction>
          </dynamics>
        </axis>
        <physics>
          <ode>
            <limit>
              <cfm>0</cfm>
              <erp>0.2</erp>
            </limit>
            <suspension>
              <cfm>0</cfm>
              <erp>0.2</erp>
            </suspension>
          </ode>
        </physics>
      </joint>
      <joint name='cessna_1/imu_joint' type='revolute'>
        <parent>cessna_1/base_link</parent>
        <child>cessna_1/imu_link</child>
        <pose>0 0 0 0 -0 0</pose>
        <axis>
          <xyz>1 0 0</xyz>
          <limit>
            <lower>0</lower>
            <upper>0</upper>
            <effort>0</effort>
            <velocity>0</velocity>
          </limit>
          <dynamics>
            <spring_reference>0</spring_reference>
            <spring_stiffness>0</spring_stiffness>
            <damping>1</damping>
            <friction>0</friction>
          </dynamics>
        </axis>
        <physics>
          <ode>
            <limit>
              <cfm>0</cfm>
              <erp>0.2</erp>
            </limit>
            <suspension>
              <cfm>0</cfm>
              <erp>0.2</erp>
            </suspension>
          </ode>
        </physics>
      </joint>
      <joint name='cessna_1/left_aileron_joint' type='revolute'>
        <parent>cessna_1/base_link</parent>
        <child>cessna_1/left_aileron</child>
        <pose>0 0 -0 0 -0 0</pose>
        <axis>
          <xyz>0 1 0</xyz>
          <limit>
            <lower>-0.78</lower>
            <upper>0.78</upper>
            <effort>-1</effort>
            <velocity>-1</velocity>
          </limit>
          <dynamics>
            <spring_reference>0</spring_reference>
            <spring_stiffness>0</spring_stiffness>
            <damping>0</damping>
            <friction>0</friction>
          </dynamics>
        </axis>
        <physics>
          <ode>
            <limit>
              <cfm>0</cfm>
              <erp>0.2</erp>
            </limit>
            <suspension>
              <cfm>0</cfm>
              <erp>0.2</erp>
            </suspension>
          </ode>
        </physics>
      </joint>
      <joint name='cessna_1/propeller_joint' type='revolute'>
        <parent>cessna_1/base_link</parent>
        <child>cessna_1/propeller</child>
        <pose>0 0 0 0 -0 0</pose>
        <axis>
          <xyz>1 0 0</xyz>
          <limit>
            <lower>-1e+16</lower>
            <upper>1e+16</upper>
            <effort>-1</effort>
            <velocity>-1</velocity>
          </limit>
          <dynamics>
            <spring_reference>0</spring_reference>
            <spring_stiffness>0</spring_stiffness>
            <damping>0.001</damping>
            <friction>0</friction>
          </dynamics>
        </axis>
        <physics>
          <ode>
            <limit>
              <cfm>0</cfm>
              <erp>0.2</erp>
            </limit>
            <suspension>
              <cfm>0</cfm>
              <erp>0.2</erp>
            </suspension>
          </ode>
        </physics>
      </joint>
      <joint name='cessna_1/right_aileron_joint' type='revolute'>
        <parent>cessna_1/base_link</parent>
        <child>cessna_1/right_aileron</child>
        <pose>0 -0 -0 0 -0 0</pose>
        <axis>
          <xyz>0 1 0</xyz>
          <limit>
            <lower>-0.78</lower>
            <upper>0.78</upper>
            <effort>-1</effort>
            <velocity>-1</velocity>
          </limit>
          <dynamics>
            <spring_reference>0</spring_reference>
            <spring_stiffness>0</spring_stiffness>
            <damping>0</damping>
            <friction>0</friction>
          </dynamics>
        </axis>
        <physics>
          <ode>
            <limit>
              <cfm>0</cfm>
              <erp>0.2</erp>
            </limit>
            <suspension>
              <cfm>0</cfm>
              <erp>0.2</erp>
            </suspension>
          </ode>
        </physics>
      </joint>
      <joint name='cessna_1/rudder_joint' type='revolute'>
        <parent>cessna_1/base_link</parent>
        <child>cessna_1/rudder</child>
        <pose>-0 0 0 0 -0 0</pose>
        <axis>
          <xyz>0 0 1</xyz>
          <limit>
            <lower>-0.78</lower>
            <upper>0.78</upper>
            <effort>-1</effort>
            <velocity>-1</velocity>
          </limit>
          <dynamics>
            <spring_reference>0</spring_reference>
            <spring_stiffness>0</spring_stiffness>
            <damping>0</damping>
            <friction>0</friction>
          </dynamics>
        </axis>
        <physics>
          <ode>
            <limit>
              <cfm>0</cfm>
              <erp>0.2</erp>
            </limit>
            <suspension>
              <cfm>0</cfm>
              <erp>0.2</erp>
            </suspension>
          </ode>
        </physics>
      </joint>
      <static>0</static>
      <allow_auto_disable>1</allow_auto_disable>
      <pose>170.903 102.97 0 0 -0 0</pose>
    </model>
  </world>
</sdf>
