<sdf version='1.7'>
  <world name='default'>
    <gui fullscreen='0'>
      <camera name='user_camera'>
        <pose>1988.39 2255.88 16.2504 0 0.196578 -1.52847</pose>
        <view_controller>orbit</view_controller>
        <projection_type>perspective</projection_type>
      </camera>
      <plugin name='keyboard' filename='libKeyboardGUIPlugin.so'/>
    </gui>
    <physics name='default_physics' default='0' type='ode'>
      <ode>
        <solver>
          <type>quick</type>
          <iters>100</iters>
          <sor>1</sor>
          <use_dynamic_moi_rescaling>0</use_dynamic_moi_rescaling>
        </solver>
        <constraints>
          <cfm>0</cfm>
          <erp>0.2</erp>
          <contact_max_correcting_vel>0.1</contact_max_correcting_vel>
          <contact_surface_layer>0</contact_surface_layer>
        </constraints>
      </ode>
      <real_time_update_rate>400</real_time_update_rate>
      <max_step_size>0.0025</max_step_size>
      <real_time_factor>1</real_time_factor>
    </physics>
    <scene>
      <sky>
        <clouds>
          <speed>5</speed>
        </clouds>
      </sky>
      <ambient>0.95 0.95 0.95 1</ambient>
      <background>0.3 0.3 0.3 1</background>
      <shadows>1</shadows>
    </scene>
    <gravity>0 0 -9.8</gravity>
    <magnetic_field>6e-06 2.3e-05 -4.2e-05</magnetic_field>
    <atmosphere type='adiabatic'/>
    <audio>
      <device>default</device>
    </audio>
    <wind/>
    <spherical_coordinates>
      <surface_model>EARTH_WGS84</surface_model>
      <latitude_deg>0</latitude_deg>
      <longitude_deg>0</longitude_deg>
      <elevation>0</elevation>
      <heading_deg>0</heading_deg>
    </spherical_coordinates>
    <state world_name='default'>
      <sim_time>1784 865000000</sim_time>
      <real_time>712 328897187</real_time>
      <wall_time>1645906266 466131037</wall_time>
      <iterations>284377</iterations>
      <model name='cessna_with_camera'>
        <pose>1996.99 2200.86 0.024382 2e-06 -0 -1.5708</pose>
        <scale>1 1 1</scale>
        <link name='cessna_with_camera/base_link'>
          <pose>1996.99 2200.86 0.024382 2e-06 -0 -1.5708</pose>
          <velocity>0 0 -0 0 -0 0</velocity>
          <acceleration>0 0 0 0 -0 0</acceleration>
          <wrench>0 0 0 0 -0 0</wrench>
        </link>
        <link name='cessna_with_camera/elevators'>
          <pose>1996.99 2201.41 0.081382 2e-06 -0 -1.5708</pose>
          <velocity>-0 -0 -0 0 -0 0</velocity>
          <acceleration>0 0 -0 0 -0 0</acceleration>
          <wrench>0 0 -0 0 -0 0</wrench>
        </link>
        <link name='cessna_with_camera/imu_link'>
          <pose>1996.99 2200.86 0.024382 2e-06 -0 -1.5708</pose>
          <velocity>-0 -0 -0 0 -0 0</velocity>
          <acceleration>0 0 0 0 -0 0</acceleration>
          <wrench>0 0 0 0 -0 0</wrench>
        </link>
        <link name='cessna_with_camera/left_aileron'>
          <pose>1997.36 2201 0.174383 0.050002 -0 -1.6908</pose>
          <velocity>0 0 -0 0 -0 0</velocity>
          <acceleration>0 0 -0 0 -0 0</acceleration>
          <wrench>0 0 -0 0 -0 0</wrench>
        </link>
        <link name='cessna_with_camera/propeller'>
          <pose>1996.99 2200.68 0.109882 -4.3e-05 -0 -1.5708</pose>
          <velocity>-0 -0 -0 0 -0 0</velocity>
          <acceleration>0 0 0 0 -0 0</acceleration>
          <wrench>0 0 0 0 -0 0</wrench>
        </link>
        <link name='cessna_with_camera/right_aileron'>
          <pose>1996.62 2201.01 0.174381 -0.049998 -0 -1.4508</pose>
          <velocity>0 0 -0 0 -0 0</velocity>
          <acceleration>0 0 0 0 -0 0</acceleration>
          <wrench>0 0 0 0 -0 0</wrench>
        </link>
        <link name='cessna_with_camera/rudder'>
          <pose>1996.99 2201.37 0.349382 2e-06 -0.35 -1.5708</pose>
          <velocity>0 0 -0 0 -0 0</velocity>
          <acceleration>0 -0 0 0 -0 0</acceleration>
          <wrench>0 -0 0 0 -0 0</wrench>
        </link>
      </model>
      <model name='cube_qr_added'>
        <pose>2057.46 1817.02 -0.051479 0 -0 0</pose>
        <scale>1 1 1</scale>
        <link name='link'>
          <pose>2057.46 1817.02 -0.051479 0 -0 0</pose>
          <velocity>0 0 0 0 -0 0</velocity>
          <acceleration>0 0 0 0 -0 0</acceleration>
          <wrench>0 0 0 0 -0 0</wrench>
        </link>
      </model>
      <model name='ground_plane'>
        <pose>0 0 0 0 -0 0</pose>
        <scale>1 1 1</scale>
        <link name='link'>
          <pose>0 0 0 0 -0 0</pose>
          <velocity>0 0 0 0 -0 0</velocity>
          <acceleration>0 0 0 0 -0 0</acceleration>
          <wrench>0 0 0 0 -0 0</wrench>
        </link>
      </model>
      <model name='istikbalgoklerdedir_q'>
        <pose>2012.07 1722.62 1.32004 -0.905158 0 0</pose>
        <scale>1 1 1</scale>
        <link name='link'>
          <pose>2012.07 1722.62 1.32004 -0.905158 0 0</pose>
          <velocity>0 0 0 0 -0 0</velocity>
          <acceleration>0 0 0 0 -0 0</acceleration>
          <wrench>0 0 0 0 -0 0</wrench>
        </link>
      </model>
      <model name='istikbalgoklerdedir_q_0'>
        <pose>2009.89 1720.44 1.366 0 -0.921999 0</pose>
        <scale>1 1 1</scale>
        <link name='link'>
          <pose>2009.89 1720.44 1.366 0 -0.921999 0</pose>
          <velocity>0 0 0 0 -0 0</velocity>
          <acceleration>0 0 0 0 -0 0</acceleration>
          <wrench>0 0 0 0 -0 0</wrench>
        </link>
      </model>
      <model name='istikbalgoklerdedir_q_1'>
        <pose>2013.91 1720.41 1.60179 0 0.915981 0</pose>
        <scale>1 1 1</scale>
        <link name='link'>
          <pose>2013.91 1720.41 1.60179 0 0.915981 0</pose>
          <velocity>0 0 0 0 -0 0</velocity>
          <acceleration>0 0 0 0 -0 0</acceleration>
          <wrench>0 0 0 0 -0 0</wrench>
        </link>
      </model>
      <model name='istikbalgoklerdedir_q_2'>
        <pose>2012.12 1718.46 1.52238 0.920054 -0 0</pose>
        <scale>1 1 1</scale>
        <link name='link'>
          <pose>2012.12 1718.46 1.52238 0.920054 -0 0</pose>
          <velocity>0 0 0 0 -0 0</velocity>
          <acceleration>0 0 0 0 -0 0</acceleration>
          <wrench>0 0 0 0 -0 0</wrench>
        </link>
      </model>
      <model name='mustafakemalataturk_m'>
        <pose>2059.62 1819.16 4.25702 0 -0 0</pose>
        <scale>1 1 1</scale>
        <link name='link'>
          <pose>2059.62 1819.16 4.25702 0 -0 0</pose>
          <velocity>0 0 0 0 -0 0</velocity>
          <acceleration>0 0 0 0 -0 0</acceleration>
          <wrench>0 0 0 0 -0 0</wrench>
        </link>
      </model>
      <model name='mustafakemalataturk_m_0'>
        <pose>2059.53 1821.41 1.9761 1.5708 -0 0</pose>
        <scale>1 1 1</scale>
        <link name='link'>
          <pose>2059.53 1821.41 1.9761 1.5708 -0 0</pose>
          <velocity>0 0 0 0 -0 0</velocity>
          <acceleration>0 0 0 0 -0 0</acceleration>
          <wrench>0 0 0 0 -0 0</wrench>
        </link>
      </model>
      <model name='mustafakemalataturk_m_1'>
        <pose>2057.39 1819.65 2.18035 3.14159 -1.57079 3.14159</pose>
        <scale>1 1 1</scale>
        <link name='link'>
          <pose>2057.39 1819.65 2.18035 3.14159 -1.57079 3.14159</pose>
          <velocity>0 0 0 0 -0 0</velocity>
          <acceleration>0 0 0 0 -0 0</acceleration>
          <wrench>0 0 0 0 -0 0</wrench>
        </link>
      </model>
      <model name='mustafakemalataturk_m_2'>
        <pose>2059.16 1816.94 2.78986 1.5708 -0 0</pose>
        <scale>1 1 1</scale>
        <link name='link'>
          <pose>2059.16 1816.94 2.78986 1.5708 -0 0</pose>
          <velocity>0 0 0 0 -0 0</velocity>
          <acceleration>0 0 0 0 -0 0</acceleration>
          <wrench>0 0 0 0 -0 0</wrench>
        </link>
      </model>
      <model name='mustafakemalataturk_m_3'>
        <pose>2061.82 1819.38 2.6622 3.14159 -1.57079 3.14159</pose>
        <scale>1 1 1</scale>
        <link name='link'>
          <pose>2061.82 1819.38 2.6622 3.14159 -1.57079 3.14159</pose>
          <velocity>0 0 0 0 -0 0</velocity>
          <acceleration>0 0 0 0 -0 0</acceleration>
          <wrench>0 0 0 0 -0 0</wrench>
        </link>
      </model>
      <model name='piramid_qr_added'>
        <pose>2008.94 1723.47 -0.028533 0 -0 0</pose>
        <scale>1 1 1</scale>
        <link name='link'>
          <pose>2008.94 1723.47 -0.028533 0 -0 0</pose>
          <velocity>0 0 0 0 -0 0</velocity>
          <acceleration>0 0 0 0 -0 0</acceleration>
          <wrench>0 0 0 0 -0 0</wrench>
        </link>
      </model>
      <model name='piramid_qr_cutted'>
        <pose>2055.85 1917.85 -0.031499 0 -0 0</pose>
        <scale>1 1 1</scale>
        <link name='link'>
          <pose>2055.85 1917.85 -0.031499 0 -0 0</pose>
          <velocity>0 0 0 0 -0 0</velocity>
          <acceleration>0 0 0 0 -0 0</acceleration>
          <wrench>0 0 0 0 -0 0</wrench>
        </link>
      </model>
      <model name='square_qr'>
        <pose>2084.87 1821.16 -0.068126 0 -0 0</pose>
        <scale>1 1 1</scale>
        <link name='link'>
          <pose>2084.87 1821.16 -0.068126 0 -0 0</pose>
          <velocity>0 0 0 0 -0 0</velocity>
          <acceleration>0 0 0 0 -0 0</acceleration>
          <wrench>0 0 0 0 -0 0</wrench>
        </link>
      </model>
      <model name='teknofest_h'>
        <pose>2058.14 1921.89 1.00612 -1.07261 0 0</pose>
        <scale>1 1 1</scale>
        <link name='link'>
          <pose>2058.14 1921.89 1.00612 -1.07261 0 0</pose>
          <velocity>0 0 0 0 -0 0</velocity>
          <acceleration>0 0 0 0 -0 0</acceleration>
          <wrench>0 0 0 0 -0 0</wrench>
        </link>
      </model>
      <model name='teknofest_h_0'>
        <pose>2058.11 1920.15 2.03063 0 -0 0</pose>
        <scale>1 1 1</scale>
        <link name='link'>
          <pose>2058.11 1920.15 2.03063 0 -0 0</pose>
          <velocity>0 0 0 0 -0 0</velocity>
          <acceleration>0 0 0 0 -0 0</acceleration>
          <wrench>0 0 0 0 -0 0</wrench>
        </link>
      </model>
      <model name='teknofest_h_1'>
        <pose>2058.08 1918.35 1.09942 1.03435 -0 0</pose>
        <scale>1 1 1</scale>
        <link name='link'>
          <pose>2058.08 1918.35 1.09942 1.03435 -0 0</pose>
          <velocity>0 0 0 0 -0 0</velocity>
          <acceleration>0 0 0 0 -0 0</acceleration>
          <wrench>0 0 0 0 -0 0</wrench>
        </link>
      </model>
      <model name='teknofest_h_2'>
        <pose>2056.31 1920.13 1.05679 0 -1.09274 0</pose>
        <scale>1 1 1</scale>
        <link name='link'>
          <pose>2056.31 1920.13 1.05679 0 -1.09274 0</pose>
          <velocity>0 0 0 0 -0 0</velocity>
          <acceleration>0 0 0 0 -0 0</acceleration>
          <wrench>0 0 0 0 -0 0</wrench>
        </link>
      </model>
      <model name='teknofest_h_3'>
        <pose>2059.89 1920.2 1.05405 0 1.04273 0</pose>
        <scale>1 1 1</scale>
        <link name='link'>
          <pose>2059.89 1920.2 1.05405 0 1.04273 0</pose>
          <velocity>0 0 0 0 -0 0</velocity>
          <acceleration>0 0 0 0 -0 0</acceleration>
          <wrench>0 0 0 0 -0 0</wrench>
        </link>
      </model>
      <model name='testucusu_m'>
        <pose>2086.38 1822.73 0.049201 0 -0 0</pose>
        <scale>1 1 1</scale>
        <link name='link'>
          <pose>2086.38 1822.73 0.049201 0 -0 0</pose>
          <velocity>0 0 0 0 -0 0</velocity>
          <acceleration>0 0 0 0 -0 0</acceleration>
          <wrench>0 0 0 0 -0 0</wrench>
        </link>
      </model>
      <model name='zephyr_with_camera'>
        <pose>1992.27 2199.72 0.034947 2.4e-05 1e-06 -0.006889</pose>
        <scale>1 1 1</scale>
        <link name='ZED_stereocamera::link'>
          <pose>1992.27 2199.38 0.314929 -1e-06 2.4e-05 -1.57769</pose>
          <velocity>0.000269 -4e-06 9.5e-05 3e-06 0.000856 -2.3e-05</velocity>
          <acceleration>0.214873 -0.001464 -0.004014 -2.98646 -1.186 3.12384</acceleration>
          <wrench>0.034165 -0.000233 -0.000638 0 -0 0</wrench>
        </link>
        <link name='cam_link'>
          <pose>1992.27 2199.72 0.034947 2.4e-05 1e-06 -0.006889</pose>
          <velocity>6.9e-05 -2e-06 0.000112 4e-06 0.000856 -2.3e-05</velocity>
          <acceleration>0.055172 -0.00037 0.000134 0.004233 0.685076 -0.018317</acceleration>
          <wrench>0.000552 -4e-06 1e-06 0 -0 0</wrench>
        </link>
        <link name='skid_pad'>
          <pose>1992.27 2199.65 0.014947 1.4e-05 -3e-06 -0.006889</pose>
          <velocity>-6.3e-05 -1e-06 0.000116 -3.8e-05 -0.00254 0</velocity>
          <acceleration>-0.05048 0.000369 0.000333 3.1251 -1.10938 -3.14152</acceleration>
          <wrench>-0.005048 3.7e-05 3.3e-05 0 -0 0</wrench>
        </link>
        <link name='zephyr_delta_wing::flap_left'>
          <pose>1992.73 2199.95 0.241811 -0.003497 -0.001162 -0.006887</pose>
          <velocity>0.000204 -1.4e-05 -0.000157 0.003169 0.00188 -2.5e-05</velocity>
          <acceleration>0.163414 -0.009486 -0.189046 -1.36627 -0.638506 3.12548</acceleration>
          <wrench>0.016341 -0.000949 -0.018905 0 -0 0</wrench>
        </link>
        <link name='zephyr_delta_wing::flap_right'>
          <pose>1991.82 2199.96 0.241812 -0.003507 0.001167 -0.006891</pose>
          <velocity>0.000203 7e-06 0.000316 -0.004766 0.002472 -2.4e-05</velocity>
          <acceleration>0.16258 0.007123 0.189568 0.130206 -1.14874 3.11751</acceleration>
          <wrench>0.016258 0.000712 0.018957 0 -0 0</wrench>
        </link>
        <link name='zephyr_delta_wing::propeller'>
          <pose>1992.27 2199.79 0.242949 3.9e-05 0.640286 -0.006866</pose>
          <velocity>0.000201 -3e-06 0.000112 -2.6e-05 -0.000833 -2.5e-05</velocity>
          <acceleration>0.161027 -0.000979 0.000105 -0.978438 0.015929 -1.28254</acceleration>
          <wrench>0.008051 -4.9e-05 5e-06 0 -0 0</wrench>
        </link>
        <link name='zephyr_delta_wing::wing'>
          <pose>1992.27 2199.72 0.234947 2.4e-05 1e-06 -0.006889</pose>
          <velocity>0.000194 -3e-06 0.000112 4e-06 0.000858 -2.5e-05</velocity>
          <acceleration>0.152766 -0.000925 0.000179 -0.012856 0.682073 -0.020384</acceleration>
          <wrench>0.229148 -0.001387 0.000269 0 -0 0</wrench>
        </link>
        <link name='zephyr_delta_wing::zephyr/imu_link'>
          <pose>1992.27 2199.72 0.234947 2.4e-05 1e-06 -0.006889</pose>
          <velocity>0.000194 -3e-06 0.000112 4e-06 0.000858 -2.5e-05</velocity>
          <acceleration>0.155214 -0.000942 0.000133 -0.000391 0.686586 -0.020348</acceleration>
          <wrench>0.023282 -0.000141 2e-05 0 -0 0</wrench>
        </link>
      </model>
      <light name='sun'>
        <pose>1865.5 2039.39 10 0 -0 0</pose>
      </light>
    </state>
    <model name='ground_plane'>
      <static>1</static>
      <link name='link'>
        <collision name='collision'>
          <geometry>
            <plane>
              <normal>0 0 1</normal>
              <size>50000 50000</size>
            </plane>
          </geometry>
          <surface>
            <friction>
              <ode>
                <mu>1</mu>
                <mu2>1</mu2>
              </ode>
              <torsional>
                <ode/>
              </torsional>
            </friction>
            <contact>
              <ode/>
            </contact>
            <bounce/>
          </surface>
          <max_contacts>10</max_contacts>
        </collision>
        <visual name='runway'>
          <pose>0 0 0.005 0 -0 0</pose>
          <cast_shadows>0</cast_shadows>
          <geometry>
            <plane>
              <normal>0 0 1</normal>
              <size>1829 45</size>
            </plane>
          </geometry>
          <material>
            <script>
              <uri>file://media/materials/scripts/gazebo.material</uri>
              <name>Gazebo/Runway</name>
            </script>
          </material>
        </visual>
        <visual name='grass'>
          <pose>0 0 -0.1 0 -0 0</pose>
          <cast_shadows>0</cast_shadows>
          <geometry>
            <plane>
              <normal>0 0 1</normal>
              <size>10000 10000</size>
            </plane>
          </geometry>
          <material>
            <script>
              <uri>file://media/materials/scripts/gazebo.material</uri>
              <name>Gazebo/Grass</name>
            </script>
          </material>
        </visual>
        <self_collide>0</self_collide>
        <enable_wind>0</enable_wind>
        <kinematic>0</kinematic>
      </link>
    </model>
    <model name='cube_qr_added'>
      <pose>2057.46 1817.02 1 0 -0 0</pose>
      <static>1</static>
      <link name='link'>
        <visual name='visual'>
          <geometry>
            <mesh>
              <scale>2 2 2</scale>
              <uri>model://cube_qr_added/meshes/cube_qr_added.dae</uri>
            </mesh>
          </geometry>
          <material>
            <script>
              <name>Gazebo/White</name>
              <uri>__default__</uri>
            </script>
          </material>
        </visual>
        <self_collide>0</self_collide>
        <enable_wind>0</enable_wind>
        <kinematic>0</kinematic>
      </link>
    </model>
    <model name='square_qr'>
      <pose>2084.87 1821.16 1 0 -0 0</pose>
      <static>1</static>
      <link name='link'>
        <visual name='visual'>
          <geometry>
            <mesh>
              <uri>model://square_qr/meshes/square_qr.dae</uri>
            </mesh>
          </geometry>
          <material>
            <script>
              <name>Gazebo/White</name>
              <uri>__default__</uri>
            </script>
          </material>
        </visual>
        <self_collide>0</self_collide>
        <enable_wind>0</enable_wind>
        <kinematic>0</kinematic>
      </link>
    </model>
    <model name='piramid_qr_added'>
      <pose>2008.94 1723.47 1 0 -0 0</pose>
      <static>1</static>
      <link name='link'>
        <visual name='visual'>
          <geometry>
            <mesh>
              <scale>5 5 5</scale>
              <uri>model://piramid_qr_added/meshes/piramid_qr_added.dae</uri>
            </mesh>
          </geometry>
          <material>
            <script>
              <name>Gazebo/White</name>
              <uri>__default__</uri>
            </script>
          </material>
        </visual>
        <self_collide>0</self_collide>
        <enable_wind>0</enable_wind>
        <kinematic>0</kinematic>
      </link>
    </model>
    <model name='piramid_qr_cutted'>
      <pose>2055.85 1917.85 1 0 -0 0</pose>
      <static>1</static>
      <link name='link'>
        <visual name='visual'>
          <geometry>
            <mesh>
              <scale>3 3 3</scale>
              <uri>model://piramid_qr_cutted/meshes/piramid_qr_cutted.dae</uri>
            </mesh>
          </geometry>
          <material>
            <script>
              <name>Gazebo/White</name>
              <uri>__default__</uri>
            </script>
          </material>
        </visual>
        <self_collide>0</self_collide>
        <enable_wind>0</enable_wind>
        <kinematic>0</kinematic>
      </link>
    </model>
    <model name='teknofest_h'>
      <pose>2058.71 1924.45 1 0 -0 0</pose>
      <static>1</static>
      <link name='link'>
        <visual name='visual'>
          <geometry>
            <mesh>
              <scale>3 3 1e-06</scale>
              <uri>model://QR_12/meshes/teknofest_h.stl</uri>
            </mesh>
          </geometry>
          <material>
            <script>
              <name>Gazebo/Black</name>
              <uri>__default__</uri>
            </script>
          </material>
        </visual>
        <self_collide>0</self_collide>
        <enable_wind>0</enable_wind>
        <kinematic>0</kinematic>
      </link>
    </model>
    <model name='teknofest_h_0'>
      <pose>2063.33 1920.33 1 0 -0 0</pose>
      <static>1</static>
      <link name='link'>
        <visual name='visual'>
          <geometry>
            <mesh>
              <scale>3 3 1e-06</scale>
              <uri>model://QR_12/meshes/teknofest_h.stl</uri>
            </mesh>
          </geometry>
          <material>
            <script>
              <name>Gazebo/Black</name>
              <uri>__default__</uri>
            </script>
          </material>
        </visual>
        <self_collide>0</self_collide>
        <enable_wind>0</enable_wind>
        <kinematic>0</kinematic>
      </link>
    </model>
    <model name='teknofest_h_1'>
      <pose>2057.78 1914.68 1 0 -0 0</pose>
      <static>1</static>
      <link name='link'>
        <visual name='visual'>
          <geometry>
            <mesh>
              <scale>3 3 1e-06</scale>
              <uri>model://QR_12/meshes/teknofest_h.stl</uri>
            </mesh>
          </geometry>
          <material>
            <script>
              <name>Gazebo/Black</name>
              <uri>__default__</uri>
            </script>
          </material>
        </visual>
        <self_collide>0</self_collide>
        <enable_wind>0</enable_wind>
        <kinematic>0</kinematic>
      </link>
    </model>
    <model name='teknofest_h_2'>
      <pose>2053.21 1919.4 1 0 -0 0</pose>
      <static>1</static>
      <link name='link'>
        <visual name='visual'>
          <geometry>
            <mesh>
              <scale>3 3 1e-06</scale>
              <uri>model://QR_12/meshes/teknofest_h.stl</uri>
            </mesh>
          </geometry>
          <material>
            <script>
              <name>Gazebo/Black</name>
              <uri>__default__</uri>
            </script>
          </material>
        </visual>
        <self_collide>0</self_collide>
        <enable_wind>0</enable_wind>
        <kinematic>0</kinematic>
      </link>
    </model>
    <model name='teknofest_h_3'>
      <pose>2063.19 1923.32 1 0 -0 0</pose>
      <static>1</static>
      <link name='link'>
        <visual name='visual'>
          <geometry>
            <mesh>
              <scale>3 3 1e-06</scale>
              <uri>model://QR_12/meshes/teknofest_h.stl</uri>
            </mesh>
          </geometry>
          <material>
            <script>
              <name>Gazebo/Black</name>
              <uri>__default__</uri>
            </script>
          </material>
        </visual>
        <self_collide>0</self_collide>
        <enable_wind>0</enable_wind>
        <kinematic>0</kinematic>
      </link>
    </model>
    <model name='testucusu_m'>
      <pose>2086.38 1822.73 1 0 -0 0</pose>
      <static>1</static>
      <link name='link'>
        <visual name='visual'>
          <geometry>
            <mesh>
              <scale>3 3 1e-06</scale>
              <uri>model://QR_06/meshes/testucusu_m.stl</uri>
            </mesh>
          </geometry>
          <material>
            <script>
              <name>Gazebo/Black</name>
              <uri>__default__</uri>
            </script>
          </material>
        </visual>
        <self_collide>0</self_collide>
        <enable_wind>0</enable_wind>
        <kinematic>0</kinematic>
      </link>
    </model>
    <model name='mustafakemalataturk_m'>
      <pose>2065.61 1819.53 1 0 -0 0</pose>
      <static>1</static>
      <link name='link'>
        <visual name='visual'>
          <geometry>
            <mesh>
              <scale>3 3 1e-06</scale>
              <uri>model://QR_14/meshes/mustafakemalataturk_m.stl</uri>
            </mesh>
          </geometry>
          <material>
            <script>
              <name>Gazebo/Black</name>
              <uri>__default__</uri>
            </script>
          </material>
        </visual>
        <self_collide>0</self_collide>
        <enable_wind>0</enable_wind>
        <kinematic>0</kinematic>
      </link>
    </model>
    <model name='mustafakemalataturk_m_0'>
      <pose>2059.93 1823.49 1 0 -0 0</pose>
      <static>1</static>
      <link name='link'>
        <visual name='visual'>
          <geometry>
            <mesh>
              <scale>3 3 1e-06</scale>
              <uri>model://QR_14/meshes/mustafakemalataturk_m.stl</uri>
            </mesh>
          </geometry>
          <material>
            <script>
              <name>Gazebo/Black</name>
              <uri>__default__</uri>
            </script>
          </material>
        </visual>
        <self_collide>0</self_collide>
        <enable_wind>0</enable_wind>
        <kinematic>0</kinematic>
      </link>
    </model>
    <model name='mustafakemalataturk_m_1'>
      <pose>2054.12 1818.17 1 0 -0 0</pose>
      <static>1</static>
      <link name='link'>
        <visual name='visual'>
          <geometry>
            <mesh>
              <scale>3 3 1e-06</scale>
              <uri>model://QR_14/meshes/mustafakemalataturk_m.stl</uri>
            </mesh>
          </geometry>
          <material>
            <script>
              <name>Gazebo/Black</name>
              <uri>__default__</uri>
            </script>
          </material>
        </visual>
        <self_collide>0</self_collide>
        <enable_wind>0</enable_wind>
        <kinematic>0</kinematic>
      </link>
    </model>
    <model name='mustafakemalataturk_m_2'>
      <pose>2059.16 1812.95 1 0 -0 0</pose>
      <static>1</static>
      <link name='link'>
        <visual name='visual'>
          <geometry>
            <mesh>
              <scale>3 3 1e-06</scale>
              <uri>model://QR_14/meshes/mustafakemalataturk_m.stl</uri>
            </mesh>
          </geometry>
          <material>
            <script>
              <name>Gazebo/Black</name>
              <uri>__default__</uri>
            </script>
          </material>
        </visual>
        <self_collide>0</self_collide>
        <enable_wind>0</enable_wind>
        <kinematic>0</kinematic>
      </link>
    </model>
    <model name='mustafakemalataturk_m_3'>
      <pose>2064.09 1823.31 1 0 -0 0</pose>
      <static>1</static>
      <link name='link'>
        <visual name='visual'>
          <geometry>
            <mesh>
              <scale>3 3 1e-06</scale>
              <uri>model://QR_14/meshes/mustafakemalataturk_m.stl</uri>
            </mesh>
          </geometry>
          <material>
            <script>
              <name>Gazebo/Black</name>
              <uri>__default__</uri>
            </script>
          </material>
        </visual>
        <self_collide>0</self_collide>
        <enable_wind>0</enable_wind>
        <kinematic>0</kinematic>
      </link>
    </model>
    <model name='istikbalgoklerdedir_q'>
      <pose>2012.12 1726.12 1 0 -0 0</pose>
      <static>1</static>
      <link name='link'>
        <visual name='visual'>
          <geometry>
            <mesh>
              <scale>3 3 1e-06</scale>
              <uri>model://QR_17/meshes/istikbalgoklerdedir_q.stl</uri>
            </mesh>
          </geometry>
          <material>
            <script>
              <name>Gazebo/Black</name>
              <uri>__default__</uri>
            </script>
          </material>
        </visual>
        <self_collide>0</self_collide>
        <enable_wind>0</enable_wind>
        <kinematic>0</kinematic>
      </link>
    </model>
    <model name='istikbalgoklerdedir_q_0'>
      <pose>2006.64 1720.06 1 0 -0 0</pose>
      <static>1</static>
      <link name='link'>
        <visual name='visual'>
          <geometry>
            <mesh>
              <scale>3 3 1e-06</scale>
              <uri>model://QR_17/meshes/istikbalgoklerdedir_q.stl</uri>
            </mesh>
          </geometry>
          <material>
            <script>
              <name>Gazebo/Black</name>
              <uri>__default__</uri>
            </script>
          </material>
        </visual>
        <self_collide>0</self_collide>
        <enable_wind>0</enable_wind>
        <kinematic>0</kinematic>
      </link>
    </model>
    <model name='istikbalgoklerdedir_q_1'>
      <pose>2017.61 1720.73 1 0 -0 0</pose>
      <static>1</static>
      <link name='link'>
        <visual name='visual'>
          <geometry>
            <mesh>
              <scale>3 3 1e-06</scale>
              <uri>model://QR_17/meshes/istikbalgoklerdedir_q.stl</uri>
            </mesh>
          </geometry>
          <material>
            <script>
              <name>Gazebo/Black</name>
              <uri>__default__</uri>
            </script>
          </material>
        </visual>
        <self_collide>0</self_collide>
        <enable_wind>0</enable_wind>
        <kinematic>0</kinematic>
      </link>
    </model>
    <model name='istikbalgoklerdedir_q_2'>
      <pose>2011.14 1713.98 1 0 -0 0</pose>
      <static>1</static>
      <link name='link'>
        <visual name='visual'>
          <geometry>
            <mesh>
              <scale>3 3 1e-06</scale>
              <uri>model://QR_17/meshes/istikbalgoklerdedir_q.stl</uri>
            </mesh>
          </geometry>
          <material>
            <script>
              <name>Gazebo/Black</name>
              <uri>__default__</uri>
            </script>
          </material>
        </visual>
        <self_collide>0</self_collide>
        <enable_wind>0</enable_wind>
        <kinematic>0</kinematic>
      </link>
    </model>
    <light name='sun' type='directional'>
      <cast_shadows>1</cast_shadows>
      <pose>1865.5 2039.39 10 0 -0 0</pose>
      <diffuse>0.8 0.8 0.8 1</diffuse>
      <specular>0.2 0.2 0.2 1</specular>
      <attenuation>
        <range>1000</range>
        <constant>0.9</constant>
        <linear>0.01</linear>
        <quadratic>0.001</quadratic>
      </attenuation>
      <direction>-0.5 0.1 -0.9</direction>
      <spot>
        <inner_angle>0</inner_angle>
        <outer_angle>0</outer_angle>
        <falloff>0</falloff>
      </spot>
    </light>
    <model name='zephyr_with_camera'>
      <pose>1992.27 2199.71 0 0 -0 0</pose>
      <frame name='zephyr_delta_wing::__model__' attached_to='zephyr_delta_wing::wing'>
        <pose relative_to='__model__'>0 0 0.2 0 -0 0</pose>
      </frame>
      <link name='zephyr_delta_wing::wing'>
        <inertial>
          <pose>0 -0.12 0 0 -0 0</pose>
          <mass>1.5</mass>
          <inertia>
            <ixx>0.0831371</ixx>
            <ixy>0</ixy>
            <iyy>0.387382</iyy>
            <ixz>0</ixz>
            <iyz>0</iyz>
            <izz>0.469845</izz>
          </inertia>
        </inertial>
        <visual name='visual'>
          <geometry>
            <mesh>
              <uri>model://zephyr_delta_wing/meshes/wing.dae</uri>
              <submesh>
                <name>Wing</name>
                <center>1</center>
              </submesh>
            </mesh>
          </geometry>
        </visual>
        <collision name='body_collision'>
          <geometry>
            <mesh>
              <uri>model://zephyr_delta_wing/meshes/wing.dae</uri>
              <submesh>
                <name>Wing</name>
                <center>1</center>
              </submesh>
            </mesh>
          </geometry>
          <max_contacts>10</max_contacts>
          <surface>
            <contact>
              <ode/>
            </contact>
            <bounce/>
            <friction>
              <torsional>
                <ode/>
              </torsional>
              <ode/>
            </friction>
          </surface>
        </collision>
        <collision name='right_rudder_collision'>
          <pose>-0.76435 0.33918 0.002 -0.03 0 0</pose>
          <geometry>
            <box>
              <size>0.005 0.12993 0.12688</size>
            </box>
          </geometry>
          <max_contacts>10</max_contacts>
          <surface>
            <contact>
              <ode/>
            </contact>
            <bounce/>
            <friction>
              <torsional>
                <ode/>
              </torsional>
              <ode/>
            </friction>
          </surface>
        </collision>
        <collision name='left_rudder_collision'>
          <pose>0.76435 0.33918 0.002 -0.03 0 0</pose>
          <geometry>
            <box>
              <size>0.005 0.12993 0.12688</size>
            </box>
          </geometry>
          <max_contacts>10</max_contacts>
          <surface>
            <contact>
              <ode/>
            </contact>
            <bounce/>
            <friction>
              <torsional>
                <ode/>
              </torsional>
              <ode/>
            </friction>
          </surface>
        </collision>
        <pose relative_to='zephyr_delta_wing::__model__'>0 0 0 0 -0 0</pose>
        <self_collide>0</self_collide>
        <enable_wind>0</enable_wind>
        <kinematic>0</kinematic>
      </link>
      <link name='zephyr_delta_wing::zephyr/imu_link'>
        <inertial>
          <pose>0 0 0 0 -0 0</pose>
          <mass>0.15</mass>
          <inertia>
            <ixx>1e-05</ixx>
            <ixy>0</ixy>
            <ixz>0</ixz>
            <iyy>2e-05</iyy>
            <iyz>0</iyz>
            <izz>2e-05</izz>
          </inertia>
        </inertial>
        <sensor name='imu_sensor' type='imu'>
          <pose>0 0 0 -3.14159 -0 -1.57079</pose>
          <always_on>1</always_on>
          <update_rate>1000</update_rate>
          <imu/>
        </sensor>
        <pose relative_to='zephyr_delta_wing::__model__'>0 0 0 0 -0 0</pose>
        <self_collide>0</self_collide>
        <enable_wind>0</enable_wind>
        <kinematic>0</kinematic>
      </link>
      <joint name='zephyr_delta_wing::zephyr/imu_joint' type='revolute'>
        <child>zephyr_delta_wing::zephyr/imu_link</child>
        <parent>zephyr_delta_wing::wing</parent>
        <axis>
          <xyz expressed_in='zephyr_delta_wing::__model__'>0 0 1</xyz>
          <limit>
            <lower>0</lower>
            <upper>0</upper>
            <effort>0</effort>
            <velocity>0</velocity>
          </limit>
          <dynamics>
            <damping>1</damping>
            <spring_reference>0</spring_reference>
            <spring_stiffness>0</spring_stiffness>
          </dynamics>
        </axis>
        <physics>
          <ode>
            <implicit_spring_damper>1</implicit_spring_damper>
            <limit>
              <cfm>0</cfm>
              <erp>0.2</erp>
            </limit>
          </ode>
        </physics>
      </joint>
      <link name='zephyr_delta_wing::propeller'>
        <pose relative_to='zephyr_delta_wing::__model__'>0 0.07 0.008 0 1.57079 0</pose>
        <inertial>
          <mass>0.05</mass>
          <inertia>
            <ixx>0.000367571</ixx>
            <ixy>0</ixy>
            <iyy>0.00036985</iyy>
            <ixz>0</ixz>
            <iyz>0</iyz>
            <izz>3.187e-06</izz>
          </inertia>
          <pose>0 0 0 0 -0 0</pose>
        </inertial>
        <visual name='visual'>
          <geometry>
            <mesh>
              <uri>model://zephyr_delta_wing/meshes/wing.dae</uri>
              <submesh>
                <name>Propeller</name>
                <center>1</center>
              </submesh>
            </mesh>
          </geometry>
        </visual>
        <collision name='blade1'>
          <pose>0 0 0.074205 0 -0 0.3</pose>
          <geometry>
            <box>
              <size>0.02561 0.00541 0.14841</size>
            </box>
          </geometry>
          <max_contacts>10</max_contacts>
          <surface>
            <contact>
              <ode/>
            </contact>
            <bounce/>
            <friction>
              <torsional>
                <ode/>
              </torsional>
              <ode/>
            </friction>
          </surface>
        </collision>
        <collision name='blade2'>
          <pose>0 0 -0.074205 0 0 -0.3</pose>
          <geometry>
            <box>
              <size>0.02561 0.00541 0.14841</size>
            </box>
          </geometry>
          <max_contacts>10</max_contacts>
          <surface>
            <contact>
              <ode/>
            </contact>
            <bounce/>
            <friction>
              <torsional>
                <ode/>
              </torsional>
              <ode/>
            </friction>
          </surface>
        </collision>
        <self_collide>0</self_collide>
        <enable_wind>0</enable_wind>
        <kinematic>0</kinematic>
      </link>
      <link name='zephyr_delta_wing::flap_left'>
        <pose relative_to='zephyr_delta_wing::__model__'>0.453 0.239 0.007 0 -0 0</pose>
        <inertial>
          <pose>0 0 0 0 -0 0.324457</pose>
          <mass>0.1</mass>
          <inertia>
            <ixx>0.000102319</ixx>
            <ixy>0</ixy>
            <iyy>0.00334417</iyy>
            <ixz>0</ixz>
            <iyz>0</iyz>
            <izz>0.00344607</izz>
          </inertia>
        </inertial>
        <visual name='visual'>
          <geometry>
            <mesh>
              <uri>model://zephyr_delta_wing/meshes/wing.dae</uri>
              <submesh>
                <name>Flap_Left</name>
                <center>1</center>
              </submesh>
            </mesh>
          </geometry>
        </visual>
        <collision name='collision'>
          <pose>-0.01 0.01 0 0 -0 0.324457</pose>
          <geometry>
            <box>
              <size>0.633463 0.110694 0.005</size>
            </box>
          </geometry>
          <max_contacts>10</max_contacts>
          <surface>
            <contact>
              <ode/>
            </contact>
            <bounce/>
            <friction>
              <torsional>
                <ode/>
              </torsional>
              <ode/>
            </friction>
          </surface>
        </collision>
        <self_collide>0</self_collide>
        <enable_wind>0</enable_wind>
        <kinematic>0</kinematic>
      </link>
      <link name='zephyr_delta_wing::flap_right'>
        <pose relative_to='zephyr_delta_wing::__model__'>-0.453 0.239 0.007 0 -0 0</pose>
        <inertial>
          <pose>0 0 0 0 0 -0.324457</pose>
          <mass>0.1</mass>
          <inertia>
            <ixx>0.000102319</ixx>
            <ixy>0</ixy>
            <iyy>0.00334417</iyy>
            <ixz>0</ixz>
            <iyz>0</iyz>
            <izz>0.00344607</izz>
          </inertia>
        </inertial>
        <visual name='visual'>
          <geometry>
            <mesh>
              <uri>model://zephyr_delta_wing/meshes/wing.dae</uri>
              <submesh>
                <name>Flap_Right</name>
                <center>1</center>
              </submesh>
            </mesh>
          </geometry>
        </visual>
        <collision name='collision'>
          <pose>0.01 0.01 0 0 0 -0.324457</pose>
          <geometry>
            <box>
              <size>0.633463 0.110694 0.005</size>
            </box>
          </geometry>
          <max_contacts>10</max_contacts>
          <surface>
            <contact>
              <ode/>
            </contact>
            <bounce/>
            <friction>
              <torsional>
                <ode/>
              </torsional>
              <ode/>
            </friction>
          </surface>
        </collision>
        <self_collide>0</self_collide>
        <enable_wind>0</enable_wind>
        <kinematic>0</kinematic>
      </link>
      <joint name='zephyr_delta_wing::propeller_joint' type='revolute'>
        <parent>zephyr_delta_wing::wing</parent>
        <child>zephyr_delta_wing::propeller</child>
        <axis>
          <xyz>0 -1 0</xyz>
          <dynamics>
            <damping>0.002</damping>
            <spring_reference>0</spring_reference>
            <spring_stiffness>0</spring_stiffness>
          </dynamics>
          <limit>
            <lower>-1e+16</lower>
            <upper>1e+16</upper>
          </limit>
        </axis>
        <physics>
          <ode>
            <implicit_spring_damper>1</implicit_spring_damper>
            <limit>
              <cfm>0</cfm>
              <erp>0.2</erp>
            </limit>
          </ode>
        </physics>
      </joint>
      <joint name='zephyr_delta_wing::flap_left_joint' type='revolute'>
        <parent>zephyr_delta_wing::wing</parent>
        <child>zephyr_delta_wing::flap_left</child>
        <pose>0 -0.04 0 0 -0 0</pose>
        <axis>
          <xyz>1 0.330321 0</xyz>
          <limit>
            <lower>-0.524</lower>
            <upper>0.524</upper>
          </limit>
          <dynamics>
            <damping>0.1</damping>
            <spring_reference>0</spring_reference>
            <spring_stiffness>0</spring_stiffness>
          </dynamics>
        </axis>
        <physics>
          <ode>
            <implicit_spring_damper>1</implicit_spring_damper>
            <limit>
              <cfm>0</cfm>
              <erp>0.2</erp>
            </limit>
          </ode>
        </physics>
      </joint>
      <joint name='zephyr_delta_wing::flap_right_joint' type='revolute'>
        <parent>zephyr_delta_wing::wing</parent>
        <child>zephyr_delta_wing::flap_right</child>
        <pose>0 -0.04 0 0 -0 0</pose>
        <axis>
          <xyz>1 -0.330321 0</xyz>
          <limit>
            <lower>-0.524</lower>
            <upper>0.524</upper>
          </limit>
          <dynamics>
            <damping>0.1</damping>
            <spring_reference>0</spring_reference>
            <spring_stiffness>0</spring_stiffness>
          </dynamics>
        </axis>
        <physics>
          <ode>
            <implicit_spring_damper>1</implicit_spring_damper>
            <limit>
              <cfm>0</cfm>
              <erp>0.2</erp>
            </limit>
          </ode>
        </physics>
      </joint>
      <plugin name='invisible_canard' filename='libLiftDragPlugin.so'>
        <a0>0.13</a0>
        <cla>3.7</cla>
        <cda>0.06417112299</cda>
        <cma>-1.8</cma>
        <alpha_stall>0.3391428111</alpha_stall>
        <cla_stall>-3.85</cla_stall>
        <cda_stall>-0.9233984055</cda_stall>
        <cma_stall>0</cma_stall>
        <cp>0 -0.1 0</cp>
        <area>0.50</area>
        <air_density>1.2041</air_density>
        <forward>0 -1 0</forward>
        <upward>0 0 1</upward>
        <link_name>zephyr_delta_wing::wing</link_name>
      </plugin>
      <plugin name='left_wing' filename='libLiftDragPlugin.so'>
        <a0>0.15</a0>
        <cla>6.8</cla>
        <cda>0.06417112299</cda>
        <cma>-1.8</cma>
        <alpha_stall>0.6391428111</alpha_stall>
        <cla_stall>-3.85</cla_stall>
        <cda_stall>-0.9233984055</cda_stall>
        <cma_stall>0</cma_stall>
        <cp>0.7 0.20 0</cp>
        <area>0.10</area>
        <air_density>1.2041</air_density>
        <forward>0 -1 0</forward>
        <upward>0 0 1</upward>
        <link_name>zephyr_delta_wing::wing</link_name>
        <control_joint_name>zephyr_delta_wing::flap_left_joint</control_joint_name>
        <control_joint_rad_to_cl>-5.0</control_joint_rad_to_cl>
      </plugin>
      <plugin name='right_wing' filename='libLiftDragPlugin.so'>
        <a0>0.15</a0>
        <cla>6.8</cla>
        <cda>0.06417112299</cda>
        <cma>-1.8</cma>
        <alpha_stall>0.6391428111</alpha_stall>
        <cla_stall>-3.85</cla_stall>
        <cda_stall>-0.9233984055</cda_stall>
        <cma_stall>0</cma_stall>
        <cp>-0.7 0.20 0</cp>
        <area>0.10</area>
        <air_density>1.2041</air_density>
        <forward>0 -1 0</forward>
        <upward>0 0 1</upward>
        <link_name>zephyr_delta_wing::wing</link_name>
        <control_joint_name>zephyr_delta_wing::flap_right_joint</control_joint_name>
        <control_joint_rad_to_cl>-5.0</control_joint_rad_to_cl>
      </plugin>
      <plugin name='left_rudder' filename='libLiftDragPlugin.so'>
        <a0>0.0</a0>
        <cla>4.752798721</cla>
        <cda>0.6417112299</cda>
        <cma>-1.8</cma>
        <alpha_stall>0.3391428111</alpha_stall>
        <cla_stall>-3.85</cla_stall>
        <cda_stall>-0.9233984055</cda_stall>
        <cma_stall>0</cma_stall>
        <cp>-0.76 0.30 0.025</cp>
        <area>0.12</area>
        <air_density>1.2041</air_density>
        <forward>0 -1 0</forward>
        <upward>1 0 0</upward>
        <link_name>zephyr_delta_wing::wing</link_name>
      </plugin>
      <plugin name='right_rudder' filename='libLiftDragPlugin.so'>
        <a0>0.0</a0>
        <cla>4.752798721</cla>
        <cda>0.6417112299</cda>
        <cma>-1.8</cma>
        <alpha_stall>0.3391428111</alpha_stall>
        <cla_stall>-3.85</cla_stall>
        <cda_stall>-0.9233984055</cda_stall>
        <cma_stall>0</cma_stall>
        <cp>0.76 0.30 0.025</cp>
        <area>0.12</area>
        <air_density>1.2041</air_density>
        <forward>0 -1 0</forward>
        <upward>1 0 0</upward>
        <link_name>zephyr_delta_wing::wing</link_name>
      </plugin>
      <plugin name='propeller_blade_1' filename='libLiftDragPlugin.so'>
        <a0>0.30</a0>
        <alpha_stall>1.4</alpha_stall>
        <cla>4.2500</cla>
        <cda>0.10</cda>
        <cma>0.00</cma>
        <cla_stall>-0.025</cla_stall>
        <cda_stall>0.0</cda_stall>
        <cma_stall>0.0</cma_stall>
        <area>0.02</area>
        <air_density>1.2041</air_density>
        <cp>0 0 0.074205</cp>
        <forward>-1 0 0</forward>
        <upward>0 -1 0</upward>
        <link_name>zephyr_delta_wing::propeller</link_name>
      </plugin>
      <plugin name='propeller_blade_2' filename='libLiftDragPlugin.so'>
        <a0>0.30</a0>
        <alpha_stall>1.4</alpha_stall>
        <cla>4.2500</cla>
        <cda>0.10</cda>
        <cma>0.00</cma>
        <cla_stall>-0.025</cla_stall>
        <cda_stall>0.0</cda_stall>
        <cma_stall>0.0</cma_stall>
        <area>0.02</area>
        <air_density>1.2041</air_density>
        <cp>0 0 -0.074205</cp>
        <forward>1 0 0</forward>
        <upward>0 -1 0</upward>
        <link_name>zephyr_delta_wing::propeller</link_name>
      </plugin>
      <frame name='ZED_stereocamera::__model__' attached_to='ZED_stereocamera::link'>
        <pose relative_to='__model__'>0 -0.34 0.28 0 -0 -1.5708</pose>
      </frame>
      <link name='ZED_stereocamera::link'>
        <pose relative_to='ZED_stereocamera::__model__'>0 0 0 0 -0 0</pose>
        <inertial>
          <mass>0.159</mass>
          <inertia>
            <ixx>1.2e-05</ixx>
            <iyy>0.000406</iyy>
            <izz>0.000418</izz>
            <ixy>0</ixy>
            <ixz>0</ixz>
            <iyz>0</iyz>
          </inertia>
          <pose>0 0 0 0 -0 0</pose>
        </inertial>
        <collision name='collision'>
          <geometry>
            <box>
              <size>0.1 0.1 0.1</size>
            </box>
          </geometry>
          <max_contacts>10</max_contacts>
          <surface>
            <contact>
              <ode/>
            </contact>
            <bounce/>
            <friction>
              <torsional>
                <ode/>
              </torsional>
              <ode/>
            </friction>
          </surface>
        </collision>
        <visual name='visual'>
          <geometry>
            <mesh>
              <uri>model://ZED_stereocamera/meshes/ZED.stl</uri>
            </mesh>
          </geometry>
          <material>
            <script>
              <name>Gazebo/Grey</name>
              <uri>__default__</uri>
            </script>
          </material>
        </visual>
        <visual name='visual_lens_left'>
          <pose>0 0 0 0 1.57 0</pose>
          <geometry>
            <cylinder>
              <radius>0.007</radius>
              <length>0.03</length>
            </cylinder>
          </geometry>
          <material>
            <script>
              <uri>file://media/materials/scripts/gazebo.material</uri>
              <name>Gazebo/WideLensMap</name>
            </script>
          </material>
        </visual>
        <sensor name='camera' type='camera'>
          <always_on>1</always_on>
          <update_rate>30</update_rate>
          <visualize>1</visualize>
          <plugin name='camera_controller' filename='libgazebo_ros_camera.so'>
            <always_on>1</always_on>
            <update_rate>30</update_rate>
            <cameraName>webcam</cameraName>
            <imageTopicName>image_raw</imageTopicName>
            <cameraInfoTopicName>camera_info</cameraInfoTopicName>
            <frameName>camera_link</frameName>
          </plugin>
          <plugin name='GstCameraPlugin' filename='libgazebo_gst_camera_plugin.so'>
            <robotNamespace/>
            <udpHost>127.0.0.1</udpHost>
            <udpPort>9999</udpPort>
          </plugin>
          <camera name='left'>
            <pose>0 0 0 0 -0 0</pose>
            <horizontal_fov>1.91986</horizontal_fov>
            <image>
              <width>1920</width>
              <height>1080</height>
            </image>
            <clip>
              <near>0.1</near>
              <far>500</far>
            </clip>
          </camera>
        </sensor>
        <self_collide>0</self_collide>
        <enable_wind>0</enable_wind>
        <kinematic>0</kinematic>
      </link>
      <link name='cam_link'>
        <pose>0 0 0 0 -0 0</pose>
        <inertial>
          <mass>0.01</mass>
          <inertia>
            <ixx>0.0001</ixx>
            <iyy>0.0001</iyy>
            <izz>0.0001</izz>
            <ixy>0</ixy>
            <ixz>0</ixz>
            <iyz>0</iyz>
          </inertia>
          <pose>0 0 0 0 -0 0</pose>
        </inertial>
        <self_collide>0</self_collide>
        <enable_wind>0</enable_wind>
        <kinematic>0</kinematic>
      </link>
      <joint name='camera_mount' type='fixed'>
        <child>ZED_stereocamera::link</child>
        <parent>zephyr_delta_wing::wing</parent>
        <axis>
          <xyz>0 0 1</xyz>
          <limit>
            <upper>0</upper>
            <lower>0</lower>
          </limit>
        </axis>
      </joint>
      <joint name='virtual_camera_mount' type='fixed'>
        <child>cam_link</child>
        <parent>zephyr_delta_wing::wing</parent>
        <axis>
          <xyz>0 0 1</xyz>
          <limit>
            <upper>0</upper>
            <lower>0</lower>
          </limit>
        </axis>
      </joint>
      <link name='skid_pad'>
        <pose>0 -0.07 -0.02 0 -0 0</pose>
        <inertial>
          <mass>0.1</mass>
          <inertia>
            <ixx>0.00431371</ixx>
            <ixy>0</ixy>
            <iyy>0.00387382</iyy>
            <ixz>0</ixz>
            <iyz>0</iyz>
            <izz>0.00809845</izz>
          </inertia>
          <pose>0 0 0 0 -0 0</pose>
        </inertial>
        <collision name='skid_pad'>
          <pose>0 0 0 0 -0 0</pose>
          <geometry>
            <box>
              <size>1 0.5 0.05</size>
            </box>
          </geometry>
          <surface>
            <contact>
              <ode>
                <kp>100000</kp>
                <kd>1</kd>
                <min_depth>0.01</min_depth>
                <max_vel>1</max_vel>
              </ode>
            </contact>
            <friction>
              <ode>
                <mu>0.3</mu>
                <fdir1>0 1 0</fdir1>
              </ode>
              <torsional>
                <ode/>
              </torsional>
            </friction>
            <bounce/>
          </surface>
          <max_contacts>10</max_contacts>
        </collision>
        <self_collide>0</self_collide>
        <enable_wind>0</enable_wind>
        <kinematic>0</kinematic>
      </link>
      <joint name='skid_pad_joint' type='fixed'>
        <parent>zephyr_delta_wing::wing</parent>
        <child>skid_pad</child>
        <axis>
          <limit>
            <lower>0</lower>
            <upper>0</upper>
          </limit>
          <xyz expressed_in='__model__'>0 1 0</xyz>
        </axis>
      </joint>
      <plugin name='ardupilot_plugin' filename='libArduPilotPlugin.so'>
        <fdm_addr>127.0.0.1</fdm_addr>
        <fdm_port_in>9012</fdm_port_in>
        <fdm_port_out>9013</fdm_port_out>
        <modelXYZToAirplaneXForwardZDown>0 0 0 3.141593 0 0</modelXYZToAirplaneXForwardZDown>
        <gazeboXYZToNED>0 0 0 3.141593 0 0</gazeboXYZToNED>
        <imuName>zephyr_with_camera::zephyr_delta_wing::zephyr/imu_link::imu_sensor</imuName>
        <connectionTimeoutMaxCount>5</connectionTimeoutMaxCount>
        <control channel='2'>
          <multiplier>838</multiplier>
          <offset>0.2</offset>
          <type>VELOCITY</type>
          <p_gain>0.5</p_gain>
          <i_gain>0</i_gain>
          <d_gain>0</d_gain>
          <i_max>0</i_max>
          <i_min>0</i_min>
          <cmd_max>2.0</cmd_max>
          <cmd_min>0.0</cmd_min>
          <jointName>zephyr_delta_wing::propeller_joint</jointName>
        </control>
        <control channel='0'>
          <multiplier>-1</multiplier>
          <offset>-0.5</offset>
          <type>POSITION</type>
          <p_gain>10.0</p_gain>
          <i_gain>0</i_gain>
          <d_gain>0</d_gain>
          <i_max>0</i_max>
          <i_min>0</i_min>
          <cmd_max>2.0</cmd_max>
          <cmd_min>-2.0</cmd_min>
          <jointName>zephyr_delta_wing::flap_left_joint</jointName>
        </control>
        <control channel='1'>
          <multiplier>-1</multiplier>
          <offset>-0.5</offset>
          <type>POSITION</type>
          <p_gain>10.0</p_gain>
          <i_gain>0</i_gain>
          <d_gain>0</d_gain>
          <i_max>0</i_max>
          <i_min>0</i_min>
          <cmd_max>2.0</cmd_max>
          <cmd_min>-2.0</cmd_min>
          <jointName>zephyr_delta_wing::flap_right_joint</jointName>
        </control>
      </plugin>
      <sensor name='gps_sensor' type='gps'>
        <pose>0 0 0 0 0 0</pose>
        <update_rate>10.0</update_rate>
        <always_on>1</always_on>
        <gps>
          <position_sensing>
            <horizontal>
              <noise type='gaussian_quantized'>
                <mean>0</mean>
                <stddev>1</stddev>
                <bias_mean>3</bias_mean>
                <bias_stddev>1</bias_stddev>
                <precision>0.5</precision>
              </noise>
            </horizontal>
            <vertical>
              <noise type='gaussian_quantized'>
                <mean>0</mean>
                <stddev>1</stddev>
                <bias_mean>3</bias_mean>
                <bias_stddev>1</bias_stddev>
                <precision>1.0</precision>
              </noise>
            </vertical>
          </position_sensing>
          <velocity_sensing>
            <horizontal>
              <noise type='gaussian_quantized'>
                <mean>0</mean>
                <stddev>0.1</stddev>
                <bias_mean>0.1</bias_mean>
                <bias_stddev>0.1</bias_stddev>
                <precision>0.1</precision>
              </noise>
            </horizontal>
            <vertical>
              <noise type='gaussian_quantized'>
                <mean>0</mean>
                <stddev>0.2</stddev>
                <bias_mean>0.2</bias_mean>
                <bias_stddev>0.2</bias_stddev>
                <precision>0.2</precision>
              </noise>
            </vertical>
          </velocity_sensing>
        </gps>
      </sensor>
    </model>
    <model name='cessna_with_camera'>
      <link name='cessna_with_camera/base_link'>
        <inertial>
          <pose>-0.00391 0 0.09273 0 -0 0</pose>
          <mass>4.001</mass>
          <inertia>
            <ixx>0.128638</ixx>
            <ixy>0</ixy>
            <ixz>-2.83339e-05</ixz>
            <iyy>0.18283</iyy>
            <iyz>0</iyz>
            <izz>0.26782</izz>
          </inertia>
        </inertial>
        <sensor name='cessna_with_camera/camera' type='camera'>
          <always_on>1</always_on>
          <update_rate>30</update_rate>
          <visualize>1</visualize>
          <camera>
            <horizontal_fov>1.18647</horizontal_fov>
            <image>
              <format>R8G8B8</format>
              <width>1920</width>
              <height>1080</height>
            </image>
            <clip>
              <near>0.1</near>
              <far>100000</far>
            </clip>
          </camera>
          <plugin name='cessna_with_camera_camera' filename='libgazebo_ros_camera.so'>
            <robotNamespace>cessna_with_camera</robotNamespace>
            <alwaysOn>1</alwaysOn>
            <updateRate>30</updateRate>
            <cameraName>camera</cameraName>
            <imageTopicName>/camera/image_raw</imageTopicName>
            <cameraInfoTopicName>/camera/camera_info</cameraInfoTopicName>
            <frameName>camera</frameName>
            <distortionK1>0.0</distortionK1>
            <distortionK2>0.0</distortionK2>
            <distortionK3>0.0</distortionK3>
            <distortionT1>0.0</distortionT1>
            <distortionT2>0.0</distortionT2>
          </plugin>
          <pose>0.179 0 0.0855 0 -0 0</pose>
        </sensor>
        <self_collide>0</self_collide>
        <enable_wind>0</enable_wind>
        <kinematic>0</kinematic>
        <pose>0 0 0 -0 -0 -0</pose>
        <visual name='cessna_with_camera/base_link_visual'>
          <pose>0 0 0 0 -0 0</pose>
          <geometry>
            <mesh>
              <scale>0.1 0.1 0.1</scale>
              <uri>model://cessna/meshes/body.dae</uri>
            </mesh>
          </geometry>
          <material>
            <script>
              <name>Gazebo</name>
              <uri>file://media/materials/scripts/gazebo.material</uri>
            </script>
            <shader type='pixel'/>
          </material>
          <transparency>0</transparency>
          <cast_shadows>0</cast_shadows>
        </visual>
        <collision name='cessna_with_camera/base_link_collision'>
          <laser_retro>0</laser_retro>
          <max_contacts>10</max_contacts>
          <pose>0 0 0 0 -0 0</pose>
          <geometry>
            <box>
              <size>1 0.5 0.05</size>
            </box>
          </geometry>
          <surface>
            <friction>
              <ode>
                <mu>0.1</mu>
                <mu2>0.1</mu2>
                <fdir1>0 0 0</fdir1>
                <slip1>0</slip1>
                <slip2>0</slip2>
              </ode>
              <torsional>
                <coefficient>1</coefficient>
                <patch_radius>0</patch_radius>
                <surface_radius>0</surface_radius>
                <use_patch_radius>1</use_patch_radius>
                <ode>
                  <slip>0</slip>
                </ode>
              </torsional>
            </friction>
            <bounce>
              <restitution_coefficient>0</restitution_coefficient>
              <threshold>1e+06</threshold>
            </bounce>
            <contact>
              <collide_without_contact>0</collide_without_contact>
              <collide_without_contact_bitmask>1</collide_without_contact_bitmask>
              <collide_bitmask>1</collide_bitmask>
              <ode>
                <soft_cfm>0</soft_cfm>
                <soft_erp>0.2</soft_erp>
                <kp>1e+13</kp>
                <kd>1</kd>
                <max_vel>100</max_vel>
                <min_depth>0.001</min_depth>
              </ode>
              <bullet>
                <split_impulse>1</split_impulse>
                <split_impulse_penetration_threshold>-0.01</split_impulse_penetration_threshold>
                <soft_cfm>0</soft_cfm>
                <soft_erp>0.2</soft_erp>
                <kp>1e+13</kp>
                <kd>1</kd>
              </bullet>
            </contact>
          </surface>
        </collision>
      </link>
      <link name='cessna_with_camera/elevators'>
        <pose>-0.555 -0 0.057 -0 -0 -0</pose>
        <inertial>
          <pose>0 0 0 0 -0 0</pose>
          <mass>0.0001</mass>
          <inertia>
            <ixx>0.0038166</ixx>
            <ixy>0</ixy>
            <ixz>0</ixz>
            <iyy>0.0036</iyy>
            <iyz>0</iyz>
            <izz>0.003816</izz>
          </inertia>
        </inertial>
        <self_collide>0</self_collide>
        <enable_wind>0</enable_wind>
        <kinematic>0</kinematic>
        <visual name='cessna_with_camera/elevators_visual'>
          <pose>0.555 0 -0.057 0 -0 0</pose>
          <geometry>
            <mesh>
              <scale>0.1 0.1 0.1</scale>
              <uri>model://cessna/meshes/elevators.dae</uri>
            </mesh>
          </geometry>
          <material>
            <shader type='pixel'/>
          </material>
          <transparency>0</transparency>
          <cast_shadows>0</cast_shadows>
        </visual>
      </link>
      <link name='cessna_with_camera/imu_link'>
        <pose>0 0 0 -0 -0 -0</pose>
        <inertial>
          <pose>0 0 0 0 -0 0</pose>
          <mass>0.15</mass>
          <inertia>
            <ixx>1e-05</ixx>
            <ixy>0</ixy>
            <ixz>0</ixz>
            <iyy>2e-05</iyy>
            <iyz>0</iyz>
            <izz>3e-05</izz>
          </inertia>
        </inertial>
        <sensor name='imu_sensor' type='imu'>
          <pose>0 0 0 -3.14159 -0 0</pose>
          <always_on>1</always_on>
          <update_rate>1000</update_rate>
          <imu/>
        </sensor>
        <self_collide>0</self_collide>
        <enable_wind>0</enable_wind>
        <kinematic>0</kinematic>
      </link>
      <link name='cessna_with_camera/left_aileron'>
        <pose>-0.145 0.37 0.15 0.05 -0 -0.12</pose>
        <inertial>
          <pose>0 0 0 0 -0 0</pose>
          <mass>0.0001</mass>
          <inertia>
            <ixx>0.0038166</ixx>
            <ixy>0</ixy>
            <ixz>0</ixz>
            <iyy>0.0036</iyy>
            <iyz>0</iyz>
            <izz>0.003816</izz>
          </inertia>
        </inertial>
        <self_collide>0</self_collide>
        <enable_wind>0</enable_wind>
        <kinematic>0</kinematic>
        <visual name='cessna_with_camera/left_aileron_visual'>
          <pose>0.195 -0.36 -0.12 -0.05 -0 0.12</pose>
          <geometry>
            <mesh>
              <scale>0.1 0.1 0.1</scale>
              <uri>model://cessna/meshes/left_aileron.dae</uri>
            </mesh>
          </geometry>
          <material>
            <shader type='pixel'/>
          </material>
          <transparency>0</transparency>
          <cast_shadows>0</cast_shadows>
        </visual>
      </link>
      <link name='cessna_with_camera/propeller'>
        <pose>0.179 -0 0.0855 -0 -0 -0</pose>
        <inertial>
          <pose>0 0 0 0 -0 0</pose>
          <mass>0.025</mass>
          <inertia>
            <ixx>7.5067e-05</ixx>
            <ixy>0</ixy>
            <ixz>0</ixz>
            <iyy>7.515e-05</iyy>
            <iyz>0</iyz>
            <izz>6.8275e-07</izz>
          </inertia>
        </inertial>
        <self_collide>0</self_collide>
        <enable_wind>0</enable_wind>
        <kinematic>0</kinematic>
        <visual name='cessna_with_camera/propeller_visual'>
          <pose>0 0 0 0 -0 0</pose>
          <geometry>
            <mesh>
              <scale>0.1 0.1 0.1</scale>
              <uri>model://cessna/meshes/cessna_prop.dae</uri>
            </mesh>
          </geometry>
          <material>
            <script>
              <name>Gazebo/Blue</name>
              <uri>file://media/materials/scripts/gazebo.material</uri>
            </script>
            <shader type='pixel'/>
          </material>
          <transparency>0</transparency>
          <cast_shadows>0</cast_shadows>
        </visual>
      </link>
      <link name='cessna_with_camera/right_aileron'>
        <pose>-0.145 -0.37 0.15 -0.05 -0 0.12</pose>
        <inertial>
          <pose>0 0 0 0 -0 0</pose>
          <mass>0.0001</mass>
          <inertia>
            <ixx>0.0038166</ixx>
            <ixy>0</ixy>
            <ixz>0</ixz>
            <iyy>0.0036</iyy>
            <iyz>0</iyz>
            <izz>0.003816</izz>
          </inertia>
        </inertial>
        <self_collide>0</self_collide>
        <enable_wind>0</enable_wind>
        <kinematic>0</kinematic>
        <visual name='cessna_with_camera/right_aileron_visual'>
          <pose>0.195 0.36 -0.12 0.05 -0 -0.12</pose>
          <geometry>
            <mesh>
              <scale>0.1 0.1 0.1</scale>
              <uri>model://cessna/meshes/right_aileron.dae</uri>
            </mesh>
          </geometry>
          <material>
            <shader type='pixel'/>
          </material>
          <transparency>0</transparency>
          <cast_shadows>0</cast_shadows>
        </visual>
      </link>
      <link name='cessna_with_camera/rudder'>
        <pose>-0.51 0 0.325 0 -0.35 0</pose>
        <inertial>
          <pose>0 0 0 0 -0 0</pose>
          <mass>0.0001</mass>
          <inertia>
            <ixx>0.0038166</ixx>
            <ixy>0</ixy>
            <ixz>0</ixz>
            <iyy>0.0036</iyy>
            <iyz>0</iyz>
            <izz>0.003816</izz>
          </inertia>
        </inertial>
        <self_collide>0</self_collide>
        <enable_wind>0</enable_wind>
        <kinematic>0</kinematic>
        <visual name='cessna_with_camera/rudder_visual'>
          <pose>0.36 0 -0.475 0 0.35 0</pose>
          <geometry>
            <mesh>
              <scale>0.1 0.1 0.1</scale>
              <uri>model://cessna/meshes/rudder.dae</uri>
            </mesh>
          </geometry>
          <material>
            <shader type='pixel'/>
          </material>
          <transparency>0</transparency>
          <cast_shadows>0</cast_shadows>
        </visual>
      </link>
      <joint name='cessna_with_camera/elevators_joint' type='revolute'>
        <parent>cessna_with_camera/base_link</parent>
        <child>cessna_with_camera/elevators</child>
        <pose>0 0 0 0 -0 0</pose>
        <axis>
          <xyz>0 1 0</xyz>
          <limit>
            <lower>-0.78</lower>
            <upper>0.78</upper>
            <effort>-1</effort>
            <velocity>-1</velocity>
          </limit>
          <dynamics>
            <spring_reference>0</spring_reference>
            <spring_stiffness>0</spring_stiffness>
            <damping>0</damping>
            <friction>0</friction>
          </dynamics>
        </axis>
        <physics>
          <ode>
            <limit>
              <cfm>0</cfm>
              <erp>0.2</erp>
            </limit>
            <suspension>
              <cfm>0</cfm>
              <erp>0.2</erp>
            </suspension>
          </ode>
        </physics>
      </joint>
      <joint name='cessna_with_camera/imu_joint' type='revolute'>
        <parent>cessna_with_camera/base_link</parent>
        <child>cessna_with_camera/imu_link</child>
        <pose>0 0 0 0 -0 0</pose>
        <axis>
          <xyz>1 0 0</xyz>
          <limit>
            <lower>0</lower>
            <upper>0</upper>
            <effort>0</effort>
            <velocity>0</velocity>
          </limit>
          <dynamics>
            <spring_reference>0</spring_reference>
            <spring_stiffness>0</spring_stiffness>
            <damping>1</damping>
            <friction>0</friction>
          </dynamics>
        </axis>
        <physics>
          <ode>
            <limit>
              <cfm>0</cfm>
              <erp>0.2</erp>
            </limit>
            <suspension>
              <cfm>0</cfm>
              <erp>0.2</erp>
            </suspension>
          </ode>
        </physics>
      </joint>
      <joint name='cessna_with_camera/left_aileron_joint' type='revolute'>
        <parent>cessna_with_camera/base_link</parent>
        <child>cessna_with_camera/left_aileron</child>
        <pose>0 0 -0 0 -0 0</pose>
        <axis>
          <xyz>0 1 0</xyz>
          <limit>
            <lower>-0.78</lower>
            <upper>0.78</upper>
            <effort>-1</effort>
            <velocity>-1</velocity>
          </limit>
          <dynamics>
            <spring_reference>0</spring_reference>
            <spring_stiffness>0</spring_stiffness>
            <damping>0</damping>
            <friction>0</friction>
          </dynamics>
        </axis>
        <physics>
          <ode>
            <limit>
              <cfm>0</cfm>
              <erp>0.2</erp>
            </limit>
            <suspension>
              <cfm>0</cfm>
              <erp>0.2</erp>
            </suspension>
          </ode>
        </physics>
      </joint>
      <joint name='cessna_with_camera/propeller_joint' type='revolute'>
        <parent>cessna_with_camera/base_link</parent>
        <child>cessna_with_camera/propeller</child>
        <pose>0 0 0 0 -0 0</pose>
        <axis>
          <xyz>1 0 0</xyz>
          <limit>
            <lower>-1e+16</lower>
            <upper>1e+16</upper>
            <effort>-1</effort>
            <velocity>-1</velocity>
          </limit>
          <dynamics>
            <spring_reference>0</spring_reference>
            <spring_stiffness>0</spring_stiffness>
            <damping>0.001</damping>
            <friction>0</friction>
          </dynamics>
        </axis>
        <physics>
          <ode>
            <limit>
              <cfm>0</cfm>
              <erp>0.2</erp>
            </limit>
            <suspension>
              <cfm>0</cfm>
              <erp>0.2</erp>
            </suspension>
          </ode>
        </physics>
      </joint>
      <joint name='cessna_with_camera/right_aileron_joint' type='revolute'>
        <parent>cessna_with_camera/base_link</parent>
        <child>cessna_with_camera/right_aileron</child>
        <pose>0 -0 -0 0 -0 0</pose>
        <axis>
          <xyz>0 1 0</xyz>
          <limit>
            <lower>-0.78</lower>
            <upper>0.78</upper>
            <effort>-1</effort>
            <velocity>-1</velocity>
          </limit>
          <dynamics>
            <spring_reference>0</spring_reference>
            <spring_stiffness>0</spring_stiffness>
            <damping>0</damping>
            <friction>0</friction>
          </dynamics>
        </axis>
        <physics>
          <ode>
            <limit>
              <cfm>0</cfm>
              <erp>0.2</erp>
            </limit>
            <suspension>
              <cfm>0</cfm>
              <erp>0.2</erp>
            </suspension>
          </ode>
        </physics>
      </joint>
      <joint name='cessna_with_camera/rudder_joint' type='revolute'>
        <parent>cessna_with_camera/base_link</parent>
        <child>cessna_with_camera/rudder</child>
        <pose>-0 0 0 0 -0 0</pose>
        <axis>
          <xyz>0 0 1</xyz>
          <limit>
            <lower>-0.78</lower>
            <upper>0.78</upper>
            <effort>-1</effort>
            <velocity>-1</velocity>
          </limit>
          <dynamics>
            <spring_reference>0</spring_reference>
            <spring_stiffness>0</spring_stiffness>
            <damping>0</damping>
            <friction>0</friction>
          </dynamics>
        </axis>
        <physics>
          <ode>
            <limit>
              <cfm>0</cfm>
              <erp>0.2</erp>
            </limit>
            <suspension>
              <cfm>0</cfm>
              <erp>0.2</erp>
            </suspension>
          </ode>
        </physics>
      </joint>
      <static>0</static>
      <allow_auto_disable>1</allow_auto_disable>
      <plugin name='cessna_with_camera_arduplane_plugin' filename='libArduPilotPlugin.so'>
        <fdm_addr>127.0.0.1</fdm_addr>
        <fdm_port_in>9002</fdm_port_in>
        <fdm_port_out>9003</fdm_port_out>
        <modelXYZToAirplaneXForwardZDown>0 0 0 0 0 0</modelXYZToAirplaneXForwardZDown>
        <gazeboXYZToNED>0 0 0 3.141593 0 0</gazeboXYZToNED>
        <imuName>cessna_with_camera/imu_link::imu_sensor</imuName>
        <connectionTimeoutMaxCount>5</connectionTimeoutMaxCount>
        <control channel='2'>
          <type>VELOCITY</type>
          <offset>0</offset>
          <p_gain>.1</p_gain>
          <i_gain>0</i_gain>
          <d_gain>0</d_gain>
          <i_max>0</i_max>
          <i_min>0</i_min>
          <cmd_max>2.5</cmd_max>
          <cmd_min>0</cmd_min>
          <jointName>cessna_with_camera/propeller_joint</jointName>
          <multiplier>838</multiplier>
          <rotorVelocitySlowdownSim>1</rotorVelocitySlowdownSim>
        </control>
        <control channel='0'>
          <type>POSITION</type>
          <offset>-0.5</offset>
          <p_gain>2.00</p_gain>
          <i_gain>0</i_gain>
          <d_gain>1.50</d_gain>
          <i_max>0</i_max>
          <i_min>0</i_min>
          <cmd_max>1.0</cmd_max>
          <cmd_min>-1.0</cmd_min>
          <multiplier>-1</multiplier>
          <jointName>cessna_with_camera/left_aileron_joint</jointName>
          <controlVelocitySlowdownSim>1</controlVelocitySlowdownSim>
        </control>
        <control channel='0'>
          <type>POSITION</type>
          <offset>-0.5</offset>
          <p_gain>2.00</p_gain>
          <i_gain>0</i_gain>
          <d_gain>1.50</d_gain>
          <i_max>0</i_max>
          <i_min>0</i_min>
          <cmd_max>1.0</cmd_max>
          <cmd_min>-1.0</cmd_min>
          <multiplier>1</multiplier>
          <jointName>cessna_with_camera/right_aileron_joint</jointName>
          <controlVelocitySlowdownSim>1</controlVelocitySlowdownSim>
        </control>
        <control channel='1'>
          <type>POSITION</type>
          <offset>-0.5</offset>
          <p_gain>2.00</p_gain>
          <i_gain>0</i_gain>
          <d_gain>1.50</d_gain>
          <i_max>0</i_max>
          <i_min>0</i_min>
          <cmd_max>1.0</cmd_max>
          <cmd_min>-1.0</cmd_min>
          <multiplier>1</multiplier>
          <jointName>cessna_with_camera/elevators_joint</jointName>
          <controlVelocitySlowdownSim>1</controlVelocitySlowdownSim>
        </control>
        <control channel='3'>
          <type>POSITION</type>
          <offset>-0.5</offset>
          <p_gain>2.00</p_gain>
          <i_gain>0</i_gain>
          <d_gain>1.50</d_gain>
          <i_max>0</i_max>
          <i_min>0</i_min>
          <cmd_max>1.0</cmd_max>
          <cmd_min>-1.0</cmd_min>
          <multiplier>1</multiplier>
          <jointName>cessna_with_camera/rudder_joint</jointName>
          <controlVelocitySlowdownSim>1</controlVelocitySlowdownSim>
        </control>
        <robotNamespace>/cessna1</robotNamespace>
      </plugin>
      <plugin name='elevators_plugin' filename='libLiftDragPlugin.so'>
        <a0>-0.2</a0>
        <cla>4.752798721</cla>
        <cda>0.6417112299</cda>
        <cma>0.0</cma>
        <alpha_stall>0.3391428111</alpha_stall>
        <cla_stall>-3.85</cla_stall>
        <cda_stall>-0.9233984055</cda_stall>
        <cma_stall>0</cma_stall>
        <cp>-0.5 0 0</cp>
        <area>0.01</area>
        <air_density>1.2041</air_density>
        <forward>1 0 0</forward>
        <upward>0 0 1</upward>
        <control_joint_rad_to_cl>-4.0</control_joint_rad_to_cl>
        <forward>1 0 0</forward>
        <link_name>cessna_with_camera/base_link</link_name>
        <control_joint_name>cessna_with_camera/elevators_joint</control_joint_name>
        <robotNamespace>/cessna1</robotNamespace>
      </plugin>
      <plugin name='left_aileron_plugin' filename='libLiftDragPlugin.so'>
        <a0>0.05984281113</a0>
        <cla>4.752798721</cla>
        <cda>0.6417112299</cda>
        <cma>-1.8</cma>
        <alpha_stall>0.3391428111</alpha_stall>
        <cla_stall>-3.85</cla_stall>
        <cda_stall>-0.9233984055</cda_stall>
        <cma_stall>0</cma_stall>
        <cp>-0.1 0.2205 0.15</cp>
        <area>8.08255</area>
        <upward>0 0 1</upward>
        <control_joint_rad_to_cl>-2.0</control_joint_rad_to_cl>
        <forward>1 0 0</forward>
        <link_name>cessna_with_camera/base_link</link_name>
        <control_joint_name>cessna_with_camera/left_aileron_joint</control_joint_name>
        <robotNamespace>/cessna1</robotNamespace>
      </plugin>
      <plugin name='propeller_bottom_blade' filename='libLiftDragPlugin.so'>
        <a0>0.4</a0>
        <cla>4.752798721</cla>
        <cda>0.6417112299</cda>
        <cma>0</cma>
        <alpha_stall>1.5</alpha_stall>
        <cla_stall>-3.85</cla_stall>
        <cda_stall>-0.9233984055</cda_stall>
        <cma_stall>0</cma_stall>
        <cp>-0.37 0 -0.77</cp>
        <area>.0001</area>
        <air_density>1.2041</air_density>
        <forward>0 1 0</forward>
        <upward>1 0 0</upward>
        <link_name>cessna_with_camera/propeller</link_name>
        <robotNamespace>/cessna1</robotNamespace>
      </plugin>
      <plugin name='propeller_top_blade' filename='libLiftDragPlugin.so'>
        <a0>0.4</a0>
        <cla>4.752798721</cla>
        <cda>0.6417112299</cda>
        <cma>0</cma>
        <alpha_stall>1.5</alpha_stall>
        <cla_stall>-3.85</cla_stall>
        <cda_stall>-0.9233984055</cda_stall>
        <cma_stall>0</cma_stall>
        <cp>-0.37 0 0.77</cp>
        <area>.0001</area>
        <air_density>1.2041</air_density>
        <forward>0 -1 0</forward>
        <upward>1 0 0</upward>
        <link_name>cessna_with_camera/propeller</link_name>
        <robotNamespace>/cessna1</robotNamespace>
      </plugin>
      <plugin name='right_aileron_plugin' filename='libLiftDragPlugin.so'>
        <a0>0.05984281113</a0>
        <cla>4.752798721</cla>
        <cda>0.6417112299</cda>
        <cma>-1.8</cma>
        <alpha_stall>0.3391428111</alpha_stall>
        <cla_stall>-3.85</cla_stall>
        <cda_stall>-0.9233984055</cda_stall>
        <cma_stall>0</cma_stall>
        <cp>-0.1 -0.2205 0.15</cp>
        <area>8.08255</area>
        <upward>0 0 1</upward>
        <control_joint_rad_to_cl>-2.0</control_joint_rad_to_cl>
        <forward>1 0 0</forward>
        <link_name>cessna_with_camera/base_link</link_name>
        <control_joint_name>cessna_with_camera/right_aileron_joint</control_joint_name>
        <robotNamespace>/cessna1</robotNamespace>
      </plugin>
      <plugin name='rudder_plugin' filename='libLiftDragPlugin.so'>
        <a0>0.0</a0>
        <cla>4.752798721</cla>
        <cda>0.6417112299</cda>
        <cma>-1.8</cma>
        <alpha_stall>0.3391428111</alpha_stall>
        <cla_stall>-3.85</cla_stall>
        <cda_stall>-0.9233984055</cda_stall>
        <cma_stall>0</cma_stall>
        <cp>-0.6 0 0.155</cp>
        <area>.15329</area>
        <upward>0 1 0</upward>
        <control_joint_rad_to_cl>4.0</control_joint_rad_to_cl>
        <forward>1 0 0</forward>
        <link_name>cessna_with_camera/base_link</link_name>
        <control_joint_name>cessna_with_camera/rudder_joint</control_joint_name>
        <robotNamespace>/cessna1</robotNamespace>
      </plugin>
      <pose>1996.99 2200.86 0 0 -0 0</pose>
    </model>
  </world>
</sdf>
