<?xml version='1.0'?>
<sdf version='1.6'>
  <model name="mini_fixedwing_body">
    <pose>0 0 0.15 0 0 0</pose>
    <link name='fuselage'>
      <inertial>
        <pose>-0.4173 0 0.0175 0 0 0</pose>
        <mass>0.268</mass>
        <inertia>
          <ixx>1.04e-2</ixx>
          <iyy>1.32e-2</iyy>
          <izz>2.33e-2</izz>
        </inertia>
      </inertial>
      <collision name='collision'>
        <pose>0 0 0 0 0 0</pose>
        <geometry>
          <mesh>
            <uri>model://mini_fixedwing_body/meshes/stl/fuselage.stl</uri>
          </mesh>
        </geometry>
        <surface>
          <friction>
            <ode>
              <mu>0.2</mu>
              <mu2>0.2</mu2>
            </ode>
          </friction>
          <contact>
            <ode>
              <max_vel>0.1</max_vel>
              <min_depth>0.001</min_depth>
            </ode>
          </contact>
        </surface>
      </collision>
      <visual name='visual'>
        <pose>0 0 0 0 0 0</pose>
        <geometry>
          <mesh>
            <uri>model://mini_fixedwing_body/meshes/stl/fuselage.stl</uri>
          </mesh>
        </geometry>
        <material>
          <ambient>0.678 0.529 0.384 1</ambient>
          <diffuse>0.678 0.529 0.384 1</diffuse>
          <specular>0.678 0.529 0.384 1</specular>
        </material>
      </visual>
    </link>

    <link name='rudder'>
      <inertial>
        <pose>-0.98 0 0.079</pose>
        <mass>0.003</mass>
        <inertia>
          <ixx>3.88e-6</ixx>
          <iyy>5.04e-6</iyy>
          <izz>1.33e-6</izz>
        </inertia>
      </inertial>
      <visual name='visual'>
        <pose>0 0 0 0 0 0</pose>
        <cast_shadows>0</cast_shadows>
        <geometry>
          <mesh>
            <uri>model://mini_fixedwing_body/meshes/stl/rudder.stl</uri>
          </mesh>
        </geometry>
        <material>
          <script>
            <name>Gazebo/White</name>
          </script>
        </material>
      </visual>
    </link>

    <joint name='rudder_joint' type='revolute'>
      <pose>-0.95 0 0.059</pose>
      <parent>fuselage</parent>
      <child>rudder</child>
      <axis>
        <xyz>0 0 1</xyz>
        <dynamics>
          <damping>0.1</damping>
        </dynamics>
        <limit>
          <lower>-0.5</lower>
          <upper>0.5</upper>
        </limit>
      </axis>
      <physics>
        <ode>
          <implicit_spring_damper>1</implicit_spring_damper>
        </ode>
      </physics>
    </joint>

    <link name='elevator'>
      <inertial>
        <pose>-0.995 0 0.04</pose>
        <mass>0.007</mass>
        <inertia>
          <ixx>7.37e-5</ixx>
          <iyy>1.86e-6</iyy>
          <izz>7.53e-5</izz>
        </inertia>
      </inertial>
      <visual name='visual'>
        <pose>0 0 0 0 0 0</pose>
        <cast_shadows>0</cast_shadows>
        <geometry>
          <mesh>
            <uri>model://mini_fixedwing_body/meshes/stl/elevator.stl</uri>
          </mesh>
        </geometry>
        <material>
          <script>
            <name>Gazebo/White</name>
          </script>
        </material>
      </visual>
    </link>

    <joint name='elevator_joint' type='revolute'>
      <pose>-0.97 0 0.04</pose>
      <parent>fuselage</parent>
      <child>elevator</child>
      <axis>
        <xyz>0 1 0</xyz>
        <dynamics>
          <damping>0.1</damping>
        </dynamics>
        <limit>
          <lower>-0.5</lower>
          <upper>0.5</upper>
        </limit>
      </axis>
      <physics>
        <ode>
          <implicit_spring_damper>1</implicit_spring_damper>
        </ode>
      </physics>
    </joint>

    <link name='aileron_left'>
      <inertial>
        <pose>-0.59 0.32 0.005</pose>
        <mass>0.008</mass>
        <inertia>
          <ixx>8.30e-5</ixx>
          <iyy>3.95e-6</iyy>
          <izz>8.67e-5</izz>
        </inertia>
      </inertial>
      <visual name='visual'>
        <pose>0 0 0 0 0 0</pose>
        <cast_shadows>0</cast_shadows>
        <geometry>
          <mesh>
            <uri>model://mini_fixedwing_body/meshes/stl/aileron_left.stl</uri>
          </mesh>
        </geometry>
        <material>
          <script>
            <name>Gazebo/White</name>
          </script>
        </material>
      </visual>
    </link>

    <joint name='aileron_left_joint' type='revolute'>
      <pose>-0.56 0.32 0.005</pose>
      <parent>fuselage</parent>
      <child>aileron_left</child>
      <axis>
        <xyz>0 -1 0</xyz>
        <dynamics>
          <damping>0.1</damping>
        </dynamics>
        <limit>
          <lower>-0.5</lower>
          <upper>0.5</upper>
        </limit>
      </axis>
      <physics>
        <ode>
          <implicit_spring_damper>1</implicit_spring_damper>
        </ode>
      </physics>
    </joint>

    <link name='aileron_right'>
      <inertial>
        <pose>-0.59 -0.32 0.005</pose>
        <mass>0.008</mass>
        <inertia>
          <ixx>8.3e-5</ixx>
          <iyy>3.95e-6</iyy>
          <izz>8.67e-5</izz>
        </inertia>
      </inertial>
      <visual name='visual'>
        <pose>0 0 0 0 0 0</pose>
        <cast_shadows>0</cast_shadows>
        <geometry>
          <mesh>
            <uri>model://mini_fixedwing_body/meshes/stl/aileron_right.stl</uri>
          </mesh>
        </geometry>
        <material>
          <script>
            <name>Gazebo/White</name>
          </script>
        </material>
      </visual>
    </link>

    <joint name='aileron_right_joint' type='revolute'>
      <pose>-0.56 -0.32 0.005</pose>
      <parent>fuselage</parent>
      <child>aileron_right</child>
      <axis>
        <xyz>0 -1 0</xyz>
        <dynamics>
          <damping>0.1</damping>
        </dynamics>
        <limit>
          <lower>-0.5</lower>
          <upper>0.5</upper>
        </limit>
      </axis>
      <physics>
        <ode>
          <implicit_spring_damper>1</implicit_spring_damper>
        </ode>
      </physics>
    </joint>

    <link name='propeller'>
      <pose>0 0 0 0 -0.1 0</pose>
      <inertial>
        <pose>0 0 0.02 0 0 0</pose>
        <mass>0.001</mass>
        <inertia>
          <ixx>1e-6</ixx>
          <iyy>1e-6</iyy>
          <izz>1e-6</izz>
        </inertia>
      </inertial>
      <visual name='visual'>
        <pose>0 0 0 0 0 0</pose>
        <cast_shadows>0</cast_shadows>
        <geometry>
          <mesh>
            <uri>model://mini_fixedwing_body/meshes/stl/propeller.stl</uri>
          </mesh>
        </geometry>
        <material>
          <script>
            <name>Gazebo/DarkGrey</name>
          </script>
        </material>
      </visual>
    </link>
  </model>

</sdf>

<!-- vim: set et fenc=utf-8 ft=xml ff=unix sts=0 sw=2 ts=2 : -->
